2021-10-06T16:30:09|ERROR|hyperMeasure|hyper Failed to update figure1: Timeout error (-7): '@ GCSMessages._read'. ['Traceback (most recent call last):\n', '  File "C:\\Users\\FastFMT-micro\\anaconda3\\lib\\site-packages\\ScopeFoundry\\measurement.py", line 273, in _on_display_update_timer\n    self.update_display()\n', '  File "C:\\LabPrograms\\Python\\HyperspectralMicroscope\\hyperspectral_measure.py", line 88, in update_display\n    self.stage.read_from_hardware()\n', '  File "C:\\Users\\FastFMT-micro\\anaconda3\\lib\\site-packages\\ScopeFoundry\\hardware.py", line 181, in read_from_hardware\n    lq.read_from_hardware()\n', '  File "C:\\Users\\FastFMT-micro\\anaconda3\\lib\\site-packages\\ScopeFoundry\\logged_quantity.py", line 161, in read_from_hardware\n    val = self.hardware_read_func()\n', '  File "C:\\LabPrograms\\Python\\PI_ScopeFoundry\\PI_GCS_device.py", line 110, in get_velocity\n    vel = self.pi_device.qVEL(self.axis)[self.axis]\n', '  File "C:\\LabPrograms\\Python\\PI_ScopeFoundry\\PIPython\\pipython\\pidevice\\gcs2\\gcs2commands.py", line 2562, in qVEL\n    answer = self._msgs.read(cmdstr)\n', '  File "C:\\LabPrograms\\Python\\PI_ScopeFoundry\\PIPython\\pipython\\pidevice\\gcsmessages.py", line 125, in read\n    answer = self._read(stopon)\n', '  File "C:\\LabPrograms\\Python\\PI_ScopeFoundry\\PIPython\\pipython\\pidevice\\gcsmessages.py", line 180, in _read\n    raise GCSError(gcserror.E_7_COM_TIMEOUT, \'@ GCSMessages._read\')\n', "PI_ScopeFoundry.PIPython.pipython.pidevice.gcserror.GCSError: Timeout error (-7): '@ GCSMessages._read'\n"]
2021-10-06T16:30:09|ERROR|hyperMeasure|hyper Failed to update figure1: Controller sent unexpected response (-1004). ['Traceback (most recent call last):\n', '  File "C:\\Users\\FastFMT-micro\\anaconda3\\lib\\site-packages\\ScopeFoundry\\measurement.py", line 273, in _on_display_update_timer\n    self.update_display()\n', '  File "C:\\LabPrograms\\Python\\HyperspectralMicroscope\\hyperspectral_measure.py", line 88, in update_display\n    self.stage.read_from_hardware()\n', '  File "C:\\Users\\FastFMT-micro\\anaconda3\\lib\\site-packages\\ScopeFoundry\\hardware.py", line 181, in read_from_hardware\n    lq.read_from_hardware()\n', '  File "C:\\Users\\FastFMT-micro\\anaconda3\\lib\\site-packages\\ScopeFoundry\\logged_quantity.py", line 161, in read_from_hardware\n    val = self.hardware_read_func()\n', '  File "C:\\LabPrograms\\Python\\PI_ScopeFoundry\\PI_GCS_device.py", line 68, in get_position\n    position = self.pi_device.qPOS(self.axis)[self.axis]\n', '  File "C:\\LabPrograms\\Python\\PI_ScopeFoundry\\PIPython\\pipython\\pidevice\\gcs2\\gcs2commands.py", line 667, in qPOS\n    answer = self._msgs.read(cmdstr)\n', '  File "C:\\LabPrograms\\Python\\PI_ScopeFoundry\\PIPython\\pipython\\pidevice\\gcsmessages.py", line 143, in read\n    self._checkerror()\n', '  File "C:\\LabPrograms\\Python\\PI_ScopeFoundry\\PIPython\\pipython\\pidevice\\gcsmessages.py", line 302, in _checkerror\n    raise exc  # Raising NoneType while only classes or instances are allowed pylint: disable=E0702\n', 'PI_ScopeFoundry.PIPython.pipython.pidevice.gcserror.GCSError: Controller sent unexpected response (-1004)\n']
2021-10-06T16:30:53|ERROR|hyperMeasure|hyper Failed to update figure1: Controller sent unexpected response (-1004). ['Traceback (most recent call last):\n', '  File "C:\\Users\\FastFMT-micro\\anaconda3\\lib\\site-packages\\ScopeFoundry\\measurement.py", line 273, in _on_display_update_timer\n    self.update_display()\n', '  File "C:\\LabPrograms\\Python\\HyperspectralMicroscope\\hyperspectral_measure.py", line 88, in update_display\n    self.stage.read_from_hardware()\n', '  File "C:\\Users\\FastFMT-micro\\anaconda3\\lib\\site-packages\\ScopeFoundry\\hardware.py", line 181, in read_from_hardware\n    lq.read_from_hardware()\n', '  File "C:\\Users\\FastFMT-micro\\anaconda3\\lib\\site-packages\\ScopeFoundry\\logged_quantity.py", line 161, in read_from_hardware\n    val = self.hardware_read_func()\n', '  File "C:\\LabPrograms\\Python\\PI_ScopeFoundry\\PI_GCS_device.py", line 68, in get_position\n    position = self.pi_device.qPOS(self.axis)[self.axis]\n', '  File "C:\\LabPrograms\\Python\\PI_ScopeFoundry\\PIPython\\pipython\\pidevice\\gcs2\\gcs2commands.py", line 667, in qPOS\n    answer = self._msgs.read(cmdstr)\n', '  File "C:\\LabPrograms\\Python\\PI_ScopeFoundry\\PIPython\\pipython\\pidevice\\gcsmessages.py", line 143, in read\n    self._checkerror()\n', '  File "C:\\LabPrograms\\Python\\PI_ScopeFoundry\\PIPython\\pipython\\pidevice\\gcsmessages.py", line 302, in _checkerror\n    raise exc  # Raising NoneType while only classes or instances are allowed pylint: disable=E0702\n', 'PI_ScopeFoundry.PIPython.pipython.pidevice.gcserror.GCSError: Controller sent unexpected response (-1004)\n']
2021-10-06T16:31:06|ERROR|hyperMeasure|hyper Failed to update figure1: Controller sent unexpected response (-1004). ['Traceback (most recent call last):\n', '  File "C:\\Users\\FastFMT-micro\\anaconda3\\lib\\site-packages\\ScopeFoundry\\measurement.py", line 273, in _on_display_update_timer\n    self.update_display()\n', '  File "C:\\LabPrograms\\Python\\HyperspectralMicroscope\\hyperspectral_measure.py", line 88, in update_display\n    self.stage.read_from_hardware()\n', '  File "C:\\Users\\FastFMT-micro\\anaconda3\\lib\\site-packages\\ScopeFoundry\\hardware.py", line 181, in read_from_hardware\n    lq.read_from_hardware()\n', '  File "C:\\Users\\FastFMT-micro\\anaconda3\\lib\\site-packages\\ScopeFoundry\\logged_quantity.py", line 161, in read_from_hardware\n    val = self.hardware_read_func()\n', '  File "C:\\LabPrograms\\Python\\PI_ScopeFoundry\\PI_GCS_device.py", line 68, in get_position\n    position = self.pi_device.qPOS(self.axis)[self.axis]\n', '  File "C:\\LabPrograms\\Python\\PI_ScopeFoundry\\PIPython\\pipython\\pidevice\\gcs2\\gcs2commands.py", line 667, in qPOS\n    answer = self._msgs.read(cmdstr)\n', '  File "C:\\LabPrograms\\Python\\PI_ScopeFoundry\\PIPython\\pipython\\pidevice\\gcsmessages.py", line 143, in read\n    self._checkerror()\n', '  File "C:\\LabPrograms\\Python\\PI_ScopeFoundry\\PIPython\\pipython\\pidevice\\gcsmessages.py", line 302, in _checkerror\n    raise exc  # Raising NoneType while only classes or instances are allowed pylint: disable=E0702\n', 'PI_ScopeFoundry.PIPython.pipython.pidevice.gcserror.GCSError: Controller sent unexpected response (-1004)\n']
2021-10-06T16:34:49|ERROR|hyperMeasure|hyper Failed to update figure1: Timeout error (-7): '@ GCSMessages._read'. ['Traceback (most recent call last):\n', '  File "C:\\Users\\FastFMT-micro\\anaconda3\\lib\\site-packages\\ScopeFoundry\\measurement.py", line 273, in _on_display_update_timer\n    self.update_display()\n', '  File "C:\\LabPrograms\\Python\\HyperspectralMicroscope\\hyperspectral_measure.py", line 88, in update_display\n    self.stage.read_from_hardware()\n', '  File "C:\\Users\\FastFMT-micro\\anaconda3\\lib\\site-packages\\ScopeFoundry\\hardware.py", line 181, in read_from_hardware\n    lq.read_from_hardware()\n', '  File "C:\\Users\\FastFMT-micro\\anaconda3\\lib\\site-packages\\ScopeFoundry\\logged_quantity.py", line 161, in read_from_hardware\n    val = self.hardware_read_func()\n', '  File "C:\\LabPrograms\\Python\\PI_ScopeFoundry\\PI_GCS_device.py", line 110, in get_velocity\n    vel = self.pi_device.qVEL(self.axis)[self.axis]\n', '  File "C:\\LabPrograms\\Python\\PI_ScopeFoundry\\PIPython\\pipython\\pidevice\\gcs2\\gcs2commands.py", line 2562, in qVEL\n    answer = self._msgs.read(cmdstr)\n', '  File "C:\\LabPrograms\\Python\\PI_ScopeFoundry\\PIPython\\pipython\\pidevice\\gcsmessages.py", line 125, in read\n    answer = self._read(stopon)\n', '  File "C:\\LabPrograms\\Python\\PI_ScopeFoundry\\PIPython\\pipython\\pidevice\\gcsmessages.py", line 180, in _read\n    raise GCSError(gcserror.E_7_COM_TIMEOUT, \'@ GCSMessages._read\')\n', "PI_ScopeFoundry.PIPython.pipython.pidevice.gcserror.GCSError: Timeout error (-7): '@ GCSMessages._read'\n"]
