2021-10-05T18:36:50|CRITICAL|root|Unhandled exception:Traceback (most recent call last):
  File "C:\Users\FastFMT-micro\anaconda3\lib\site-packages\ScopeFoundry\hardware.py", line 208, in enable_connection
    raise err
  File "C:\Users\FastFMT-micro\anaconda3\lib\site-packages\ScopeFoundry\hardware.py", line 204, in enable_connection
    self.connect()
  File "C:\LabPrograms\Python\QImaging_ScopeFoundry\camera_hw.py", line 35, in connect
    self.camera = QImagingDevice(debug=self.debug_mode.val)
  File "C:\LabPrograms\Python\QImaging_ScopeFoundry\camera_device.py", line 18, in __init__
    self.cam = qi.OpenCamera(qi.ListCameras()[0])
IndexError: list index out of range

