2024-07-11T10:57:41|CRITICAL|root|Unhandled exception:Traceback (most recent call last):
  File "C:\Users\FastFMT-micro\anaconda3\lib\site-packages\ScopeFoundry\hardware.py", line 208, in enable_connection
    raise err
  File "C:\Users\FastFMT-micro\anaconda3\lib\site-packages\ScopeFoundry\hardware.py", line 204, in enable_connection
    self.connect()
  File "C:\LabPrograms\Python\PI_ScopeFoundry\PI_GCS_hardware.py", line 40, in connect
    self.motor = PI_GCS_Device(serial = SERIAL, axis = '1')
  File "C:\LabPrograms\Python\PI_ScopeFoundry\PI_GCS_device.py", line 26, in __init__
    self.pi_device.ConnectUSB (serial)
  File "C:\LabPrograms\Python\PI_ScopeFoundry\PIPython\pipython\pidevice\gcs2\gcs2device.py", line 133, in ConnectUSB
    self.dll.ConnectUSB(serialnum)
  File "C:\LabPrograms\Python\PI_ScopeFoundry\PIPython\pipython\pidevice\interfaces\gcsdll.py", line 437, in ConnectUSB
    raise GCSError(self._error)
PI_ScopeFoundry.PIPython.pipython.pidevice.gcserror.GCSError: There is no interface or DLL handle with the given ID (-9)

