2025-02-19T17:43:58|ERROR|hyperMeasure|hyper Failed to update figure1: 'HamamatsuHardware' object has no attribute 'frame_num'. ['Traceback (most recent call last):\n', '  File "C:\\ProgramData\\anaconda3\\envs\\scopefoundry\\lib\\site-packages\\ScopeFoundry\\measurement.py", line 362, in _on_display_update_timer\n    self.update_display()\n', '  File "c:\\data\\python programs\\camera humanitas\\hyperspectralmicroscope\\hyperspectral_measure.py", line 93, in update_display\n    length = self.image_gen.frame_num.val\n', "AttributeError: 'HamamatsuHardware' object has no attribute 'frame_num'\n"]
2025-02-19T17:43:59|ERROR|hyperMeasure|hyper Failed to update figure1: 'HamamatsuHardware' object has no attribute 'frame_num'. ['Traceback (most recent call last):\n', '  File "C:\\ProgramData\\anaconda3\\envs\\scopefoundry\\lib\\site-packages\\ScopeFoundry\\measurement.py", line 362, in _on_display_update_timer\n    self.update_display()\n', '  File "c:\\data\\python programs\\camera humanitas\\hyperspectralmicroscope\\hyperspectral_measure.py", line 93, in update_display\n    length = self.image_gen.frame_num.val\n', "AttributeError: 'HamamatsuHardware' object has no attribute 'frame_num'\n"]
2025-02-19T17:44:07|ERROR|hyperMeasure|hyper Failed to update figure1: 'HamamatsuHardware' object has no attribute 'frame_num'. ['Traceback (most recent call last):\n', '  File "C:\\ProgramData\\anaconda3\\envs\\scopefoundry\\lib\\site-packages\\ScopeFoundry\\measurement.py", line 362, in _on_display_update_timer\n    self.update_display()\n', '  File "c:\\data\\python programs\\camera humanitas\\hyperspectralmicroscope\\hyperspectral_measure.py", line 93, in update_display\n    length = self.image_gen.frame_num.val\n', "AttributeError: 'HamamatsuHardware' object has no attribute 'frame_num'\n"]
2025-02-19T17:44:07|ERROR|hyperMeasure|hyper Failed to update figure1: 'HamamatsuHardware' object has no attribute 'frame_num'. ['Traceback (most recent call last):\n', '  File "C:\\ProgramData\\anaconda3\\envs\\scopefoundry\\lib\\site-packages\\ScopeFoundry\\measurement.py", line 362, in _on_display_update_timer\n    self.update_display()\n', '  File "c:\\data\\python programs\\camera humanitas\\hyperspectralmicroscope\\hyperspectral_measure.py", line 93, in update_display\n    length = self.image_gen.frame_num.val\n', "AttributeError: 'HamamatsuHardware' object has no attribute 'frame_num'\n"]
2025-02-19T17:44:07|ERROR|hyperMeasure|hyper Failed to update figure1: 'HamamatsuHardware' object has no attribute 'frame_num'. ['Traceback (most recent call last):\n', '  File "C:\\ProgramData\\anaconda3\\envs\\scopefoundry\\lib\\site-packages\\ScopeFoundry\\measurement.py", line 362, in _on_display_update_timer\n    self.update_display()\n', '  File "c:\\data\\python programs\\camera humanitas\\hyperspectralmicroscope\\hyperspectral_measure.py", line 93, in update_display\n    length = self.image_gen.frame_num.val\n', "AttributeError: 'HamamatsuHardware' object has no attribute 'frame_num'\n"]
2025-02-19T17:50:43|ERROR|hyperMeasure|hyper Failed to update figure1: 'HamamatsuHardware' object has no attribute 'frame_num'. ['Traceback (most recent call last):\n', '  File "C:\\ProgramData\\anaconda3\\envs\\scopefoundry\\lib\\site-packages\\ScopeFoundry\\measurement.py", line 362, in _on_display_update_timer\n    self.update_display()\n', '  File "c:\\data\\python programs\\camera humanitas\\hyperspectralmicroscope\\hyperspectral_measure.py", line 93, in update_display\n    #length = self.image_gen.frame_num.val\n', "AttributeError: 'HamamatsuHardware' object has no attribute 'frame_num'\n"]
2025-02-19T17:50:43|ERROR|hyperMeasure|hyper Failed to update figure1: 'HamamatsuHardware' object has no attribute 'frame_num'. ['Traceback (most recent call last):\n', '  File "C:\\ProgramData\\anaconda3\\envs\\scopefoundry\\lib\\site-packages\\ScopeFoundry\\measurement.py", line 362, in _on_display_update_timer\n    self.update_display()\n', '  File "c:\\data\\python programs\\camera humanitas\\hyperspectralmicroscope\\hyperspectral_measure.py", line 93, in update_display\n    #length = self.image_gen.frame_num.val\n', "AttributeError: 'HamamatsuHardware' object has no attribute 'frame_num'\n"]
2025-02-19T17:50:44|ERROR|hyperMeasure|hyper Failed to update figure1: 'HamamatsuHardware' object has no attribute 'frame_num'. ['Traceback (most recent call last):\n', '  File "C:\\ProgramData\\anaconda3\\envs\\scopefoundry\\lib\\site-packages\\ScopeFoundry\\measurement.py", line 362, in _on_display_update_timer\n    self.update_display()\n', '  File "c:\\data\\python programs\\camera humanitas\\hyperspectralmicroscope\\hyperspectral_measure.py", line 93, in update_display\n    #length = self.image_gen.frame_num.val\n', "AttributeError: 'HamamatsuHardware' object has no attribute 'frame_num'\n"]
2025-02-19T17:54:51|ERROR|hyperMeasure|hyper Failed to update figure1: 'HamamatsuHardware' object has no attribute 'frame_num'. ['Traceback (most recent call last):\n', '  File "C:\\ProgramData\\anaconda3\\envs\\scopefoundry\\lib\\site-packages\\ScopeFoundry\\measurement.py", line 362, in _on_display_update_timer\n    self.update_display()\n', '  File "c:\\data\\python programs\\camera humanitas\\hyperspectralmicroscope\\hyperspectral_measure.py", line 93, in update_display\n    #length = self.image_gen.frame_num.val\n', "AttributeError: 'HamamatsuHardware' object has no attribute 'frame_num'\n"]
2025-02-19T17:57:52|ERROR|hyperMeasure|hyper Failed to update figure1: 'HamamatsuHardware' object has no attribute 'frame_num'. ['Traceback (most recent call last):\n', '  File "C:\\ProgramData\\anaconda3\\envs\\scopefoundry\\lib\\site-packages\\ScopeFoundry\\measurement.py", line 362, in _on_display_update_timer\n    self.update_display()\n', '  File "c:\\data\\python programs\\camera humanitas\\hyperspectralmicroscope\\hyperspectral_measure.py", line 93, in update_display\n    #length = self.image_gen.frame_num.val\n', "AttributeError: 'HamamatsuHardware' object has no attribute 'frame_num'\n"]
2025-02-19T17:58:13|ERROR|hyperMeasure|hyper Failed to update figure1: 'HamamatsuHardware' object has no attribute 'frame_num'. ['Traceback (most recent call last):\n', '  File "C:\\ProgramData\\anaconda3\\envs\\scopefoundry\\lib\\site-packages\\ScopeFoundry\\measurement.py", line 362, in _on_display_update_timer\n    self.update_display()\n', '  File "c:\\data\\python programs\\camera humanitas\\hyperspectralmicroscope\\hyperspectral_measure.py", line 93, in update_display\n    #length = self.image_gen.frame_num.val\n', "AttributeError: 'HamamatsuHardware' object has no attribute 'frame_num'\n"]
2025-02-19T17:58:23|ERROR|hyperMeasure|hyper Failed to update figure1: 'HamamatsuHardware' object has no attribute 'frame_num'. ['Traceback (most recent call last):\n', '  File "C:\\ProgramData\\anaconda3\\envs\\scopefoundry\\lib\\site-packages\\ScopeFoundry\\measurement.py", line 362, in _on_display_update_timer\n    self.update_display()\n', '  File "c:\\data\\python programs\\camera humanitas\\hyperspectralmicroscope\\hyperspectral_measure.py", line 93, in update_display\n    #length = self.image_gen.frame_num.val\n', "AttributeError: 'HamamatsuHardware' object has no attribute 'frame_num'\n"]
