2021-07-23T12:41:28|ERROR|hyperMeasure|hyper Failed to update figure1: Timeout error (-7): '@ GCSMessages._read'. ['Traceback (most recent call last):\n', '  File "C:\\Users\\FastFMT-micro\\anaconda3\\lib\\site-packages\\ScopeFoundry\\measurement.py", line 273, in _on_display_update_timer\n    self.update_display()\n', '  File "C:\\LabPrograms\\Python\\HyperspectralMicroscope\\hyperspectral_measure.py", line 88, in update_display\n    self.stage.read_from_hardware()\n', '  File "C:\\Users\\FastFMT-micro\\anaconda3\\lib\\site-packages\\ScopeFoundry\\hardware.py", line 181, in read_from_hardware\n    lq.read_from_hardware()\n', '  File "C:\\Users\\FastFMT-micro\\anaconda3\\lib\\site-packages\\ScopeFoundry\\logged_quantity.py", line 161, in read_from_hardware\n    val = self.hardware_read_func()\n', '  File "C:\\LabPrograms\\Python\\PI_ScopeFoundry\\PI_GCS_device.py", line 68, in get_position\n    position = self.pi_device.qPOS(self.axis)[self.axis]\n', '  File "C:\\LabPrograms\\Python\\PI_ScopeFoundry\\PIPython\\pipython\\pidevice\\gcs2\\gcs2commands.py", line 667, in qPOS\n    answer = self._msgs.read(cmdstr)\n', '  File "C:\\LabPrograms\\Python\\PI_ScopeFoundry\\PIPython\\pipython\\pidevice\\gcsmessages.py", line 125, in read\n    answer = self._read(stopon)\n', '  File "C:\\LabPrograms\\Python\\PI_ScopeFoundry\\PIPython\\pipython\\pidevice\\gcsmessages.py", line 180, in _read\n    raise GCSError(gcserror.E_7_COM_TIMEOUT, \'@ GCSMessages._read\')\n', "PI_ScopeFoundry.PIPython.pipython.pidevice.gcserror.GCSError: Timeout error (-7): '@ GCSMessages._read'\n"]
2021-07-23T12:42:12|CRITICAL|root|Unhandled exception:Traceback (most recent call last):
  File "C:\LabPrograms\Python\HyperspectralMicroscope\hyperspectral_measure.py", line 184, in run
    self.measure()
  File "C:\LabPrograms\Python\HyperspectralMicroscope\hyperspectral_measure.py", line 151, in measure
    self.stage.motor.move_absolute(target_pos)
  File "C:\LabPrograms\Python\PI_ScopeFoundry\PI_GCS_device.py", line 52, in move_absolute
    rangemin = self.pi_device.qTMN()[self.axis]
  File "C:\LabPrograms\Python\PI_ScopeFoundry\PIPython\pipython\pidevice\gcs2\gcs2commands.py", line 2538, in qTMN
    answer = self._msgs.read(cmdstr)
  File "C:\LabPrograms\Python\PI_ScopeFoundry\PIPython\pipython\pidevice\gcsmessages.py", line 143, in read
    self._checkerror()
  File "C:\LabPrograms\Python\PI_ScopeFoundry\PIPython\pipython\pidevice\gcsmessages.py", line 302, in _checkerror
    raise exc  # Raising NoneType while only classes or instances are allowed pylint: disable=E0702
PI_ScopeFoundry.PIPython.pipython.pidevice.gcserror.GCSError: Controller sent unexpected response (-1004)

During handling of the above exception, another exception occurred:

Traceback (most recent call last):
  File "C:\Users\FastFMT-micro\anaconda3\lib\site-packages\ScopeFoundry\measurement.py", line 25, in run
    self.measurement._thread_run()
  File "C:\Users\FastFMT-micro\anaconda3\lib\site-packages\ScopeFoundry\measurement.py", line 179, in _thread_run
    self.run()
  File "C:\LabPrograms\Python\HyperspectralMicroscope\hyperspectral_measure.py", line 190, in run
    self.stage.motor.move_absolute(self.starting_pos)
  File "C:\LabPrograms\Python\PI_ScopeFoundry\PI_GCS_device.py", line 52, in move_absolute
    rangemin = self.pi_device.qTMN()[self.axis]
KeyError: '1'

