2025-02-25T16:44:02|ERROR|hyperMeasure|hyper Failed to update figure1: Timeout error (-7): '@ GCSMessages._read'. ['Traceback (most recent call last):\n', '  File "C:\\ProgramData\\anaconda3\\envs\\scopefoundry\\lib\\site-packages\\ScopeFoundry\\measurement.py", line 362, in _on_display_update_timer\n    self.update_display()\n', '  File "c:\\data\\python programs\\camera humanitas\\hyperspectralmicroscope\\hyperspectral_measure.py", line 88, in update_display\n    self.stage.read_from_hardware()\n', '  File "C:\\ProgramData\\anaconda3\\envs\\scopefoundry\\lib\\site-packages\\ScopeFoundry\\hardware.py", line 188, in read_from_hardware\n    lq.read_from_hardware()\n', '  File "C:\\ProgramData\\anaconda3\\envs\\scopefoundry\\lib\\site-packages\\ScopeFoundry\\logged_quantity.py", line 203, in read_from_hardware\n    val = self.hardware_read_func()\n', '  File "c:\\data\\python programs\\camera humanitas\\hyperspectralmicroscope\\PI_ScopeFoundry\\PI_GCS_device.py", line 68, in get_position\n    position = self.pi_device.qPOS(self.axis)[self.axis]\n', '  File "c:\\data\\python programs\\camera humanitas\\hyperspectralmicroscope\\PI_ScopeFoundry\\PIPython\\pipython\\pidevice\\gcs2\\gcs2commands.py", line 667, in qPOS\n    answer = self._msgs.read(cmdstr)\n', '  File "c:\\data\\python programs\\camera humanitas\\hyperspectralmicroscope\\PI_ScopeFoundry\\PIPython\\pipython\\pidevice\\gcsmessages.py", line 125, in read\n    answer = self._read(stopon)\n', '  File "c:\\data\\python programs\\camera humanitas\\hyperspectralmicroscope\\PI_ScopeFoundry\\PIPython\\pipython\\pidevice\\gcsmessages.py", line 180, in _read\n    raise GCSError(gcserror.E_7_COM_TIMEOUT, \'@ GCSMessages._read\')\n', "PI_ScopeFoundry.PIPython.pipython.pidevice.gcserror.GCSError: Timeout error (-7): '@ GCSMessages._read'\n"]
2025-02-25T16:44:02|ERROR|hyperMeasure|hyper Failed to update figure1: Controller sent unexpected response (-1004). ['Traceback (most recent call last):\n', '  File "C:\\ProgramData\\anaconda3\\envs\\scopefoundry\\lib\\site-packages\\ScopeFoundry\\measurement.py", line 362, in _on_display_update_timer\n    self.update_display()\n', '  File "c:\\data\\python programs\\camera humanitas\\hyperspectralmicroscope\\hyperspectral_measure.py", line 88, in update_display\n    self.stage.read_from_hardware()\n', '  File "C:\\ProgramData\\anaconda3\\envs\\scopefoundry\\lib\\site-packages\\ScopeFoundry\\hardware.py", line 188, in read_from_hardware\n    lq.read_from_hardware()\n', '  File "C:\\ProgramData\\anaconda3\\envs\\scopefoundry\\lib\\site-packages\\ScopeFoundry\\logged_quantity.py", line 203, in read_from_hardware\n    val = self.hardware_read_func()\n', '  File "c:\\data\\python programs\\camera humanitas\\hyperspectralmicroscope\\PI_ScopeFoundry\\PI_GCS_device.py", line 68, in get_position\n    position = self.pi_device.qPOS(self.axis)[self.axis]\n', '  File "c:\\data\\python programs\\camera humanitas\\hyperspectralmicroscope\\PI_ScopeFoundry\\PIPython\\pipython\\pidevice\\gcs2\\gcs2commands.py", line 667, in qPOS\n    answer = self._msgs.read(cmdstr)\n', '  File "c:\\data\\python programs\\camera humanitas\\hyperspectralmicroscope\\PI_ScopeFoundry\\PIPython\\pipython\\pidevice\\gcsmessages.py", line 143, in read\n    self._checkerror()\n', '  File "c:\\data\\python programs\\camera humanitas\\hyperspectralmicroscope\\PI_ScopeFoundry\\PIPython\\pipython\\pidevice\\gcsmessages.py", line 302, in _checkerror\n    raise exc  # Raising NoneType while only classes or instances are allowed pylint: disable=E0702\n', 'PI_ScopeFoundry.PIPython.pipython.pidevice.gcserror.GCSError: Controller sent unexpected response (-1004)\n']
2025-02-25T16:44:02|ERROR|hyperMeasure|hyper Failed to update figure1: Controller sent unexpected response (-1004). ['Traceback (most recent call last):\n', '  File "C:\\ProgramData\\anaconda3\\envs\\scopefoundry\\lib\\site-packages\\ScopeFoundry\\measurement.py", line 362, in _on_display_update_timer\n    self.update_display()\n', '  File "c:\\data\\python programs\\camera humanitas\\hyperspectralmicroscope\\hyperspectral_measure.py", line 88, in update_display\n    self.stage.read_from_hardware()\n', '  File "C:\\ProgramData\\anaconda3\\envs\\scopefoundry\\lib\\site-packages\\ScopeFoundry\\hardware.py", line 188, in read_from_hardware\n    lq.read_from_hardware()\n', '  File "C:\\ProgramData\\anaconda3\\envs\\scopefoundry\\lib\\site-packages\\ScopeFoundry\\logged_quantity.py", line 203, in read_from_hardware\n    val = self.hardware_read_func()\n', '  File "c:\\data\\python programs\\camera humanitas\\hyperspectralmicroscope\\PI_ScopeFoundry\\PI_GCS_device.py", line 68, in get_position\n    position = self.pi_device.qPOS(self.axis)[self.axis]\n', '  File "c:\\data\\python programs\\camera humanitas\\hyperspectralmicroscope\\PI_ScopeFoundry\\PIPython\\pipython\\pidevice\\gcs2\\gcs2commands.py", line 667, in qPOS\n    answer = self._msgs.read(cmdstr)\n', '  File "c:\\data\\python programs\\camera humanitas\\hyperspectralmicroscope\\PI_ScopeFoundry\\PIPython\\pipython\\pidevice\\gcsmessages.py", line 143, in read\n    self._checkerror()\n', '  File "c:\\data\\python programs\\camera humanitas\\hyperspectralmicroscope\\PI_ScopeFoundry\\PIPython\\pipython\\pidevice\\gcsmessages.py", line 302, in _checkerror\n    raise exc  # Raising NoneType while only classes or instances are allowed pylint: disable=E0702\n', 'PI_ScopeFoundry.PIPython.pipython.pidevice.gcserror.GCSError: Controller sent unexpected response (-1004)\n']
2025-02-25T16:44:02|ERROR|hyperMeasure|hyper Failed to update figure1: Controller sent unexpected response (-1004). ['Traceback (most recent call last):\n', '  File "C:\\ProgramData\\anaconda3\\envs\\scopefoundry\\lib\\site-packages\\ScopeFoundry\\measurement.py", line 362, in _on_display_update_timer\n    self.update_display()\n', '  File "c:\\data\\python programs\\camera humanitas\\hyperspectralmicroscope\\hyperspectral_measure.py", line 88, in update_display\n    self.stage.read_from_hardware()\n', '  File "C:\\ProgramData\\anaconda3\\envs\\scopefoundry\\lib\\site-packages\\ScopeFoundry\\hardware.py", line 188, in read_from_hardware\n    lq.read_from_hardware()\n', '  File "C:\\ProgramData\\anaconda3\\envs\\scopefoundry\\lib\\site-packages\\ScopeFoundry\\logged_quantity.py", line 203, in read_from_hardware\n    val = self.hardware_read_func()\n', '  File "c:\\data\\python programs\\camera humanitas\\hyperspectralmicroscope\\PI_ScopeFoundry\\PI_GCS_device.py", line 68, in get_position\n    position = self.pi_device.qPOS(self.axis)[self.axis]\n', '  File "c:\\data\\python programs\\camera humanitas\\hyperspectralmicroscope\\PI_ScopeFoundry\\PIPython\\pipython\\pidevice\\gcs2\\gcs2commands.py", line 667, in qPOS\n    answer = self._msgs.read(cmdstr)\n', '  File "c:\\data\\python programs\\camera humanitas\\hyperspectralmicroscope\\PI_ScopeFoundry\\PIPython\\pipython\\pidevice\\gcsmessages.py", line 143, in read\n    self._checkerror()\n', '  File "c:\\data\\python programs\\camera humanitas\\hyperspectralmicroscope\\PI_ScopeFoundry\\PIPython\\pipython\\pidevice\\gcsmessages.py", line 302, in _checkerror\n    raise exc  # Raising NoneType while only classes or instances are allowed pylint: disable=E0702\n', 'PI_ScopeFoundry.PIPython.pipython.pidevice.gcserror.GCSError: Controller sent unexpected response (-1004)\n']
2025-02-25T16:44:02|ERROR|hyperMeasure|hyper Failed to update figure1: Controller sent unexpected response (-1004). ['Traceback (most recent call last):\n', '  File "C:\\ProgramData\\anaconda3\\envs\\scopefoundry\\lib\\site-packages\\ScopeFoundry\\measurement.py", line 362, in _on_display_update_timer\n    self.update_display()\n', '  File "c:\\data\\python programs\\camera humanitas\\hyperspectralmicroscope\\hyperspectral_measure.py", line 88, in update_display\n    self.stage.read_from_hardware()\n', '  File "C:\\ProgramData\\anaconda3\\envs\\scopefoundry\\lib\\site-packages\\ScopeFoundry\\hardware.py", line 188, in read_from_hardware\n    lq.read_from_hardware()\n', '  File "C:\\ProgramData\\anaconda3\\envs\\scopefoundry\\lib\\site-packages\\ScopeFoundry\\logged_quantity.py", line 203, in read_from_hardware\n    val = self.hardware_read_func()\n', '  File "c:\\data\\python programs\\camera humanitas\\hyperspectralmicroscope\\PI_ScopeFoundry\\PI_GCS_device.py", line 68, in get_position\n    position = self.pi_device.qPOS(self.axis)[self.axis]\n', '  File "c:\\data\\python programs\\camera humanitas\\hyperspectralmicroscope\\PI_ScopeFoundry\\PIPython\\pipython\\pidevice\\gcs2\\gcs2commands.py", line 667, in qPOS\n    answer = self._msgs.read(cmdstr)\n', '  File "c:\\data\\python programs\\camera humanitas\\hyperspectralmicroscope\\PI_ScopeFoundry\\PIPython\\pipython\\pidevice\\gcsmessages.py", line 143, in read\n    self._checkerror()\n', '  File "c:\\data\\python programs\\camera humanitas\\hyperspectralmicroscope\\PI_ScopeFoundry\\PIPython\\pipython\\pidevice\\gcsmessages.py", line 302, in _checkerror\n    raise exc  # Raising NoneType while only classes or instances are allowed pylint: disable=E0702\n', 'PI_ScopeFoundry.PIPython.pipython.pidevice.gcserror.GCSError: Controller sent unexpected response (-1004)\n']
2025-02-25T16:44:03|ERROR|hyperMeasure|hyper Failed to update figure1: Controller sent unexpected response (-1004). ['Traceback (most recent call last):\n', '  File "C:\\ProgramData\\anaconda3\\envs\\scopefoundry\\lib\\site-packages\\ScopeFoundry\\measurement.py", line 362, in _on_display_update_timer\n    self.update_display()\n', '  File "c:\\data\\python programs\\camera humanitas\\hyperspectralmicroscope\\hyperspectral_measure.py", line 88, in update_display\n    self.stage.read_from_hardware()\n', '  File "C:\\ProgramData\\anaconda3\\envs\\scopefoundry\\lib\\site-packages\\ScopeFoundry\\hardware.py", line 188, in read_from_hardware\n    lq.read_from_hardware()\n', '  File "C:\\ProgramData\\anaconda3\\envs\\scopefoundry\\lib\\site-packages\\ScopeFoundry\\logged_quantity.py", line 203, in read_from_hardware\n    val = self.hardware_read_func()\n', '  File "c:\\data\\python programs\\camera humanitas\\hyperspectralmicroscope\\PI_ScopeFoundry\\PI_GCS_device.py", line 68, in get_position\n    position = self.pi_device.qPOS(self.axis)[self.axis]\n', '  File "c:\\data\\python programs\\camera humanitas\\hyperspectralmicroscope\\PI_ScopeFoundry\\PIPython\\pipython\\pidevice\\gcs2\\gcs2commands.py", line 667, in qPOS\n    answer = self._msgs.read(cmdstr)\n', '  File "c:\\data\\python programs\\camera humanitas\\hyperspectralmicroscope\\PI_ScopeFoundry\\PIPython\\pipython\\pidevice\\gcsmessages.py", line 143, in read\n    self._checkerror()\n', '  File "c:\\data\\python programs\\camera humanitas\\hyperspectralmicroscope\\PI_ScopeFoundry\\PIPython\\pipython\\pidevice\\gcsmessages.py", line 302, in _checkerror\n    raise exc  # Raising NoneType while only classes or instances are allowed pylint: disable=E0702\n', 'PI_ScopeFoundry.PIPython.pipython.pidevice.gcserror.GCSError: Controller sent unexpected response (-1004)\n']
2025-02-25T16:44:03|ERROR|hyperMeasure|hyper Failed to update figure1: Controller sent unexpected response (-1004). ['Traceback (most recent call last):\n', '  File "C:\\ProgramData\\anaconda3\\envs\\scopefoundry\\lib\\site-packages\\ScopeFoundry\\measurement.py", line 362, in _on_display_update_timer\n    self.update_display()\n', '  File "c:\\data\\python programs\\camera humanitas\\hyperspectralmicroscope\\hyperspectral_measure.py", line 88, in update_display\n    self.stage.read_from_hardware()\n', '  File "C:\\ProgramData\\anaconda3\\envs\\scopefoundry\\lib\\site-packages\\ScopeFoundry\\hardware.py", line 188, in read_from_hardware\n    lq.read_from_hardware()\n', '  File "C:\\ProgramData\\anaconda3\\envs\\scopefoundry\\lib\\site-packages\\ScopeFoundry\\logged_quantity.py", line 203, in read_from_hardware\n    val = self.hardware_read_func()\n', '  File "c:\\data\\python programs\\camera humanitas\\hyperspectralmicroscope\\PI_ScopeFoundry\\PI_GCS_device.py", line 68, in get_position\n    position = self.pi_device.qPOS(self.axis)[self.axis]\n', '  File "c:\\data\\python programs\\camera humanitas\\hyperspectralmicroscope\\PI_ScopeFoundry\\PIPython\\pipython\\pidevice\\gcs2\\gcs2commands.py", line 667, in qPOS\n    answer = self._msgs.read(cmdstr)\n', '  File "c:\\data\\python programs\\camera humanitas\\hyperspectralmicroscope\\PI_ScopeFoundry\\PIPython\\pipython\\pidevice\\gcsmessages.py", line 143, in read\n    self._checkerror()\n', '  File "c:\\data\\python programs\\camera humanitas\\hyperspectralmicroscope\\PI_ScopeFoundry\\PIPython\\pipython\\pidevice\\gcsmessages.py", line 302, in _checkerror\n    raise exc  # Raising NoneType while only classes or instances are allowed pylint: disable=E0702\n', 'PI_ScopeFoundry.PIPython.pipython.pidevice.gcserror.GCSError: Controller sent unexpected response (-1004)\n']
2025-02-25T16:44:03|ERROR|hyperMeasure|hyper Failed to update figure1: Controller sent unexpected response (-1004). ['Traceback (most recent call last):\n', '  File "C:\\ProgramData\\anaconda3\\envs\\scopefoundry\\lib\\site-packages\\ScopeFoundry\\measurement.py", line 362, in _on_display_update_timer\n    self.update_display()\n', '  File "c:\\data\\python programs\\camera humanitas\\hyperspectralmicroscope\\hyperspectral_measure.py", line 88, in update_display\n    self.stage.read_from_hardware()\n', '  File "C:\\ProgramData\\anaconda3\\envs\\scopefoundry\\lib\\site-packages\\ScopeFoundry\\hardware.py", line 188, in read_from_hardware\n    lq.read_from_hardware()\n', '  File "C:\\ProgramData\\anaconda3\\envs\\scopefoundry\\lib\\site-packages\\ScopeFoundry\\logged_quantity.py", line 203, in read_from_hardware\n    val = self.hardware_read_func()\n', '  File "c:\\data\\python programs\\camera humanitas\\hyperspectralmicroscope\\PI_ScopeFoundry\\PI_GCS_device.py", line 68, in get_position\n    position = self.pi_device.qPOS(self.axis)[self.axis]\n', '  File "c:\\data\\python programs\\camera humanitas\\hyperspectralmicroscope\\PI_ScopeFoundry\\PIPython\\pipython\\pidevice\\gcs2\\gcs2commands.py", line 667, in qPOS\n    answer = self._msgs.read(cmdstr)\n', '  File "c:\\data\\python programs\\camera humanitas\\hyperspectralmicroscope\\PI_ScopeFoundry\\PIPython\\pipython\\pidevice\\gcsmessages.py", line 143, in read\n    self._checkerror()\n', '  File "c:\\data\\python programs\\camera humanitas\\hyperspectralmicroscope\\PI_ScopeFoundry\\PIPython\\pipython\\pidevice\\gcsmessages.py", line 302, in _checkerror\n    raise exc  # Raising NoneType while only classes or instances are allowed pylint: disable=E0702\n', 'PI_ScopeFoundry.PIPython.pipython.pidevice.gcserror.GCSError: Controller sent unexpected response (-1004)\n']
2025-02-25T16:44:03|ERROR|hyperMeasure|hyper Failed to update figure1: Controller sent unexpected response (-1004). ['Traceback (most recent call last):\n', '  File "C:\\ProgramData\\anaconda3\\envs\\scopefoundry\\lib\\site-packages\\ScopeFoundry\\measurement.py", line 362, in _on_display_update_timer\n    self.update_display()\n', '  File "c:\\data\\python programs\\camera humanitas\\hyperspectralmicroscope\\hyperspectral_measure.py", line 88, in update_display\n    self.stage.read_from_hardware()\n', '  File "C:\\ProgramData\\anaconda3\\envs\\scopefoundry\\lib\\site-packages\\ScopeFoundry\\hardware.py", line 188, in read_from_hardware\n    lq.read_from_hardware()\n', '  File "C:\\ProgramData\\anaconda3\\envs\\scopefoundry\\lib\\site-packages\\ScopeFoundry\\logged_quantity.py", line 203, in read_from_hardware\n    val = self.hardware_read_func()\n', '  File "c:\\data\\python programs\\camera humanitas\\hyperspectralmicroscope\\PI_ScopeFoundry\\PI_GCS_device.py", line 68, in get_position\n    position = self.pi_device.qPOS(self.axis)[self.axis]\n', '  File "c:\\data\\python programs\\camera humanitas\\hyperspectralmicroscope\\PI_ScopeFoundry\\PIPython\\pipython\\pidevice\\gcs2\\gcs2commands.py", line 667, in qPOS\n    answer = self._msgs.read(cmdstr)\n', '  File "c:\\data\\python programs\\camera humanitas\\hyperspectralmicroscope\\PI_ScopeFoundry\\PIPython\\pipython\\pidevice\\gcsmessages.py", line 143, in read\n    self._checkerror()\n', '  File "c:\\data\\python programs\\camera humanitas\\hyperspectralmicroscope\\PI_ScopeFoundry\\PIPython\\pipython\\pidevice\\gcsmessages.py", line 302, in _checkerror\n    raise exc  # Raising NoneType while only classes or instances are allowed pylint: disable=E0702\n', 'PI_ScopeFoundry.PIPython.pipython.pidevice.gcserror.GCSError: Controller sent unexpected response (-1004)\n']
2025-02-25T16:44:03|ERROR|hyperMeasure|hyper Failed to update figure1: Controller sent unexpected response (-1004). ['Traceback (most recent call last):\n', '  File "C:\\ProgramData\\anaconda3\\envs\\scopefoundry\\lib\\site-packages\\ScopeFoundry\\measurement.py", line 362, in _on_display_update_timer\n    self.update_display()\n', '  File "c:\\data\\python programs\\camera humanitas\\hyperspectralmicroscope\\hyperspectral_measure.py", line 88, in update_display\n    self.stage.read_from_hardware()\n', '  File "C:\\ProgramData\\anaconda3\\envs\\scopefoundry\\lib\\site-packages\\ScopeFoundry\\hardware.py", line 188, in read_from_hardware\n    lq.read_from_hardware()\n', '  File "C:\\ProgramData\\anaconda3\\envs\\scopefoundry\\lib\\site-packages\\ScopeFoundry\\logged_quantity.py", line 203, in read_from_hardware\n    val = self.hardware_read_func()\n', '  File "c:\\data\\python programs\\camera humanitas\\hyperspectralmicroscope\\PI_ScopeFoundry\\PI_GCS_device.py", line 68, in get_position\n    position = self.pi_device.qPOS(self.axis)[self.axis]\n', '  File "c:\\data\\python programs\\camera humanitas\\hyperspectralmicroscope\\PI_ScopeFoundry\\PIPython\\pipython\\pidevice\\gcs2\\gcs2commands.py", line 667, in qPOS\n    answer = self._msgs.read(cmdstr)\n', '  File "c:\\data\\python programs\\camera humanitas\\hyperspectralmicroscope\\PI_ScopeFoundry\\PIPython\\pipython\\pidevice\\gcsmessages.py", line 143, in read\n    self._checkerror()\n', '  File "c:\\data\\python programs\\camera humanitas\\hyperspectralmicroscope\\PI_ScopeFoundry\\PIPython\\pipython\\pidevice\\gcsmessages.py", line 302, in _checkerror\n    raise exc  # Raising NoneType while only classes or instances are allowed pylint: disable=E0702\n', 'PI_ScopeFoundry.PIPython.pipython.pidevice.gcserror.GCSError: Controller sent unexpected response (-1004)\n']
2025-02-25T16:44:03|ERROR|hyperMeasure|hyper Failed to update figure1: Controller sent unexpected response (-1004). ['Traceback (most recent call last):\n', '  File "C:\\ProgramData\\anaconda3\\envs\\scopefoundry\\lib\\site-packages\\ScopeFoundry\\measurement.py", line 362, in _on_display_update_timer\n    self.update_display()\n', '  File "c:\\data\\python programs\\camera humanitas\\hyperspectralmicroscope\\hyperspectral_measure.py", line 88, in update_display\n    self.stage.read_from_hardware()\n', '  File "C:\\ProgramData\\anaconda3\\envs\\scopefoundry\\lib\\site-packages\\ScopeFoundry\\hardware.py", line 188, in read_from_hardware\n    lq.read_from_hardware()\n', '  File "C:\\ProgramData\\anaconda3\\envs\\scopefoundry\\lib\\site-packages\\ScopeFoundry\\logged_quantity.py", line 203, in read_from_hardware\n    val = self.hardware_read_func()\n', '  File "c:\\data\\python programs\\camera humanitas\\hyperspectralmicroscope\\PI_ScopeFoundry\\PI_GCS_device.py", line 68, in get_position\n    position = self.pi_device.qPOS(self.axis)[self.axis]\n', '  File "c:\\data\\python programs\\camera humanitas\\hyperspectralmicroscope\\PI_ScopeFoundry\\PIPython\\pipython\\pidevice\\gcs2\\gcs2commands.py", line 667, in qPOS\n    answer = self._msgs.read(cmdstr)\n', '  File "c:\\data\\python programs\\camera humanitas\\hyperspectralmicroscope\\PI_ScopeFoundry\\PIPython\\pipython\\pidevice\\gcsmessages.py", line 143, in read\n    self._checkerror()\n', '  File "c:\\data\\python programs\\camera humanitas\\hyperspectralmicroscope\\PI_ScopeFoundry\\PIPython\\pipython\\pidevice\\gcsmessages.py", line 302, in _checkerror\n    raise exc  # Raising NoneType while only classes or instances are allowed pylint: disable=E0702\n', 'PI_ScopeFoundry.PIPython.pipython.pidevice.gcserror.GCSError: Controller sent unexpected response (-1004)\n']
2025-02-25T16:44:03|ERROR|hyperMeasure|hyper Failed to update figure1: Controller sent unexpected response (-1004). ['Traceback (most recent call last):\n', '  File "C:\\ProgramData\\anaconda3\\envs\\scopefoundry\\lib\\site-packages\\ScopeFoundry\\measurement.py", line 362, in _on_display_update_timer\n    self.update_display()\n', '  File "c:\\data\\python programs\\camera humanitas\\hyperspectralmicroscope\\hyperspectral_measure.py", line 88, in update_display\n    self.stage.read_from_hardware()\n', '  File "C:\\ProgramData\\anaconda3\\envs\\scopefoundry\\lib\\site-packages\\ScopeFoundry\\hardware.py", line 188, in read_from_hardware\n    lq.read_from_hardware()\n', '  File "C:\\ProgramData\\anaconda3\\envs\\scopefoundry\\lib\\site-packages\\ScopeFoundry\\logged_quantity.py", line 203, in read_from_hardware\n    val = self.hardware_read_func()\n', '  File "c:\\data\\python programs\\camera humanitas\\hyperspectralmicroscope\\PI_ScopeFoundry\\PI_GCS_device.py", line 68, in get_position\n    position = self.pi_device.qPOS(self.axis)[self.axis]\n', '  File "c:\\data\\python programs\\camera humanitas\\hyperspectralmicroscope\\PI_ScopeFoundry\\PIPython\\pipython\\pidevice\\gcs2\\gcs2commands.py", line 667, in qPOS\n    answer = self._msgs.read(cmdstr)\n', '  File "c:\\data\\python programs\\camera humanitas\\hyperspectralmicroscope\\PI_ScopeFoundry\\PIPython\\pipython\\pidevice\\gcsmessages.py", line 143, in read\n    self._checkerror()\n', '  File "c:\\data\\python programs\\camera humanitas\\hyperspectralmicroscope\\PI_ScopeFoundry\\PIPython\\pipython\\pidevice\\gcsmessages.py", line 302, in _checkerror\n    raise exc  # Raising NoneType while only classes or instances are allowed pylint: disable=E0702\n', 'PI_ScopeFoundry.PIPython.pipython.pidevice.gcserror.GCSError: Controller sent unexpected response (-1004)\n']
2025-02-25T16:44:03|ERROR|hyperMeasure|hyper Failed to update figure1: Controller sent unexpected response (-1004). ['Traceback (most recent call last):\n', '  File "C:\\ProgramData\\anaconda3\\envs\\scopefoundry\\lib\\site-packages\\ScopeFoundry\\measurement.py", line 362, in _on_display_update_timer\n    self.update_display()\n', '  File "c:\\data\\python programs\\camera humanitas\\hyperspectralmicroscope\\hyperspectral_measure.py", line 88, in update_display\n    self.stage.read_from_hardware()\n', '  File "C:\\ProgramData\\anaconda3\\envs\\scopefoundry\\lib\\site-packages\\ScopeFoundry\\hardware.py", line 188, in read_from_hardware\n    lq.read_from_hardware()\n', '  File "C:\\ProgramData\\anaconda3\\envs\\scopefoundry\\lib\\site-packages\\ScopeFoundry\\logged_quantity.py", line 203, in read_from_hardware\n    val = self.hardware_read_func()\n', '  File "c:\\data\\python programs\\camera humanitas\\hyperspectralmicroscope\\PI_ScopeFoundry\\PI_GCS_device.py", line 68, in get_position\n    position = self.pi_device.qPOS(self.axis)[self.axis]\n', '  File "c:\\data\\python programs\\camera humanitas\\hyperspectralmicroscope\\PI_ScopeFoundry\\PIPython\\pipython\\pidevice\\gcs2\\gcs2commands.py", line 667, in qPOS\n    answer = self._msgs.read(cmdstr)\n', '  File "c:\\data\\python programs\\camera humanitas\\hyperspectralmicroscope\\PI_ScopeFoundry\\PIPython\\pipython\\pidevice\\gcsmessages.py", line 143, in read\n    self._checkerror()\n', '  File "c:\\data\\python programs\\camera humanitas\\hyperspectralmicroscope\\PI_ScopeFoundry\\PIPython\\pipython\\pidevice\\gcsmessages.py", line 302, in _checkerror\n    raise exc  # Raising NoneType while only classes or instances are allowed pylint: disable=E0702\n', 'PI_ScopeFoundry.PIPython.pipython.pidevice.gcserror.GCSError: Controller sent unexpected response (-1004)\n']
2025-02-25T16:44:03|ERROR|hyperMeasure|hyper Failed to update figure1: Controller sent unexpected response (-1004). ['Traceback (most recent call last):\n', '  File "C:\\ProgramData\\anaconda3\\envs\\scopefoundry\\lib\\site-packages\\ScopeFoundry\\measurement.py", line 362, in _on_display_update_timer\n    self.update_display()\n', '  File "c:\\data\\python programs\\camera humanitas\\hyperspectralmicroscope\\hyperspectral_measure.py", line 88, in update_display\n    self.stage.read_from_hardware()\n', '  File "C:\\ProgramData\\anaconda3\\envs\\scopefoundry\\lib\\site-packages\\ScopeFoundry\\hardware.py", line 188, in read_from_hardware\n    lq.read_from_hardware()\n', '  File "C:\\ProgramData\\anaconda3\\envs\\scopefoundry\\lib\\site-packages\\ScopeFoundry\\logged_quantity.py", line 203, in read_from_hardware\n    val = self.hardware_read_func()\n', '  File "c:\\data\\python programs\\camera humanitas\\hyperspectralmicroscope\\PI_ScopeFoundry\\PI_GCS_device.py", line 68, in get_position\n    position = self.pi_device.qPOS(self.axis)[self.axis]\n', '  File "c:\\data\\python programs\\camera humanitas\\hyperspectralmicroscope\\PI_ScopeFoundry\\PIPython\\pipython\\pidevice\\gcs2\\gcs2commands.py", line 667, in qPOS\n    answer = self._msgs.read(cmdstr)\n', '  File "c:\\data\\python programs\\camera humanitas\\hyperspectralmicroscope\\PI_ScopeFoundry\\PIPython\\pipython\\pidevice\\gcsmessages.py", line 143, in read\n    self._checkerror()\n', '  File "c:\\data\\python programs\\camera humanitas\\hyperspectralmicroscope\\PI_ScopeFoundry\\PIPython\\pipython\\pidevice\\gcsmessages.py", line 302, in _checkerror\n    raise exc  # Raising NoneType while only classes or instances are allowed pylint: disable=E0702\n', 'PI_ScopeFoundry.PIPython.pipython.pidevice.gcserror.GCSError: Controller sent unexpected response (-1004)\n']
2025-02-25T16:44:04|ERROR|hyperMeasure|hyper Failed to update figure1: Controller sent unexpected response (-1004). ['Traceback (most recent call last):\n', '  File "C:\\ProgramData\\anaconda3\\envs\\scopefoundry\\lib\\site-packages\\ScopeFoundry\\measurement.py", line 362, in _on_display_update_timer\n    self.update_display()\n', '  File "c:\\data\\python programs\\camera humanitas\\hyperspectralmicroscope\\hyperspectral_measure.py", line 88, in update_display\n    self.stage.read_from_hardware()\n', '  File "C:\\ProgramData\\anaconda3\\envs\\scopefoundry\\lib\\site-packages\\ScopeFoundry\\hardware.py", line 188, in read_from_hardware\n    lq.read_from_hardware()\n', '  File "C:\\ProgramData\\anaconda3\\envs\\scopefoundry\\lib\\site-packages\\ScopeFoundry\\logged_quantity.py", line 203, in read_from_hardware\n    val = self.hardware_read_func()\n', '  File "c:\\data\\python programs\\camera humanitas\\hyperspectralmicroscope\\PI_ScopeFoundry\\PI_GCS_device.py", line 68, in get_position\n    position = self.pi_device.qPOS(self.axis)[self.axis]\n', '  File "c:\\data\\python programs\\camera humanitas\\hyperspectralmicroscope\\PI_ScopeFoundry\\PIPython\\pipython\\pidevice\\gcs2\\gcs2commands.py", line 667, in qPOS\n    answer = self._msgs.read(cmdstr)\n', '  File "c:\\data\\python programs\\camera humanitas\\hyperspectralmicroscope\\PI_ScopeFoundry\\PIPython\\pipython\\pidevice\\gcsmessages.py", line 143, in read\n    self._checkerror()\n', '  File "c:\\data\\python programs\\camera humanitas\\hyperspectralmicroscope\\PI_ScopeFoundry\\PIPython\\pipython\\pidevice\\gcsmessages.py", line 302, in _checkerror\n    raise exc  # Raising NoneType while only classes or instances are allowed pylint: disable=E0702\n', 'PI_ScopeFoundry.PIPython.pipython.pidevice.gcserror.GCSError: Controller sent unexpected response (-1004)\n']
2025-02-25T16:44:04|ERROR|hyperMeasure|hyper Failed to update figure1: Controller sent unexpected response (-1004). ['Traceback (most recent call last):\n', '  File "C:\\ProgramData\\anaconda3\\envs\\scopefoundry\\lib\\site-packages\\ScopeFoundry\\measurement.py", line 362, in _on_display_update_timer\n    self.update_display()\n', '  File "c:\\data\\python programs\\camera humanitas\\hyperspectralmicroscope\\hyperspectral_measure.py", line 88, in update_display\n    self.stage.read_from_hardware()\n', '  File "C:\\ProgramData\\anaconda3\\envs\\scopefoundry\\lib\\site-packages\\ScopeFoundry\\hardware.py", line 188, in read_from_hardware\n    lq.read_from_hardware()\n', '  File "C:\\ProgramData\\anaconda3\\envs\\scopefoundry\\lib\\site-packages\\ScopeFoundry\\logged_quantity.py", line 203, in read_from_hardware\n    val = self.hardware_read_func()\n', '  File "c:\\data\\python programs\\camera humanitas\\hyperspectralmicroscope\\PI_ScopeFoundry\\PI_GCS_device.py", line 68, in get_position\n    position = self.pi_device.qPOS(self.axis)[self.axis]\n', '  File "c:\\data\\python programs\\camera humanitas\\hyperspectralmicroscope\\PI_ScopeFoundry\\PIPython\\pipython\\pidevice\\gcs2\\gcs2commands.py", line 667, in qPOS\n    answer = self._msgs.read(cmdstr)\n', '  File "c:\\data\\python programs\\camera humanitas\\hyperspectralmicroscope\\PI_ScopeFoundry\\PIPython\\pipython\\pidevice\\gcsmessages.py", line 143, in read\n    self._checkerror()\n', '  File "c:\\data\\python programs\\camera humanitas\\hyperspectralmicroscope\\PI_ScopeFoundry\\PIPython\\pipython\\pidevice\\gcsmessages.py", line 302, in _checkerror\n    raise exc  # Raising NoneType while only classes or instances are allowed pylint: disable=E0702\n', 'PI_ScopeFoundry.PIPython.pipython.pidevice.gcserror.GCSError: Controller sent unexpected response (-1004)\n']
2025-02-25T16:44:04|ERROR|hyperMeasure|hyper Failed to update figure1: Controller sent unexpected response (-1004). ['Traceback (most recent call last):\n', '  File "C:\\ProgramData\\anaconda3\\envs\\scopefoundry\\lib\\site-packages\\ScopeFoundry\\measurement.py", line 362, in _on_display_update_timer\n    self.update_display()\n', '  File "c:\\data\\python programs\\camera humanitas\\hyperspectralmicroscope\\hyperspectral_measure.py", line 88, in update_display\n    self.stage.read_from_hardware()\n', '  File "C:\\ProgramData\\anaconda3\\envs\\scopefoundry\\lib\\site-packages\\ScopeFoundry\\hardware.py", line 188, in read_from_hardware\n    lq.read_from_hardware()\n', '  File "C:\\ProgramData\\anaconda3\\envs\\scopefoundry\\lib\\site-packages\\ScopeFoundry\\logged_quantity.py", line 203, in read_from_hardware\n    val = self.hardware_read_func()\n', '  File "c:\\data\\python programs\\camera humanitas\\hyperspectralmicroscope\\PI_ScopeFoundry\\PI_GCS_device.py", line 68, in get_position\n    position = self.pi_device.qPOS(self.axis)[self.axis]\n', '  File "c:\\data\\python programs\\camera humanitas\\hyperspectralmicroscope\\PI_ScopeFoundry\\PIPython\\pipython\\pidevice\\gcs2\\gcs2commands.py", line 667, in qPOS\n    answer = self._msgs.read(cmdstr)\n', '  File "c:\\data\\python programs\\camera humanitas\\hyperspectralmicroscope\\PI_ScopeFoundry\\PIPython\\pipython\\pidevice\\gcsmessages.py", line 143, in read\n    self._checkerror()\n', '  File "c:\\data\\python programs\\camera humanitas\\hyperspectralmicroscope\\PI_ScopeFoundry\\PIPython\\pipython\\pidevice\\gcsmessages.py", line 302, in _checkerror\n    raise exc  # Raising NoneType while only classes or instances are allowed pylint: disable=E0702\n', 'PI_ScopeFoundry.PIPython.pipython.pidevice.gcserror.GCSError: Controller sent unexpected response (-1004)\n']
2025-02-25T16:44:04|ERROR|hyperMeasure|hyper Failed to update figure1: Controller sent unexpected response (-1004). ['Traceback (most recent call last):\n', '  File "C:\\ProgramData\\anaconda3\\envs\\scopefoundry\\lib\\site-packages\\ScopeFoundry\\measurement.py", line 362, in _on_display_update_timer\n    self.update_display()\n', '  File "c:\\data\\python programs\\camera humanitas\\hyperspectralmicroscope\\hyperspectral_measure.py", line 88, in update_display\n    self.stage.read_from_hardware()\n', '  File "C:\\ProgramData\\anaconda3\\envs\\scopefoundry\\lib\\site-packages\\ScopeFoundry\\hardware.py", line 188, in read_from_hardware\n    lq.read_from_hardware()\n', '  File "C:\\ProgramData\\anaconda3\\envs\\scopefoundry\\lib\\site-packages\\ScopeFoundry\\logged_quantity.py", line 203, in read_from_hardware\n    val = self.hardware_read_func()\n', '  File "c:\\data\\python programs\\camera humanitas\\hyperspectralmicroscope\\PI_ScopeFoundry\\PI_GCS_device.py", line 68, in get_position\n    position = self.pi_device.qPOS(self.axis)[self.axis]\n', '  File "c:\\data\\python programs\\camera humanitas\\hyperspectralmicroscope\\PI_ScopeFoundry\\PIPython\\pipython\\pidevice\\gcs2\\gcs2commands.py", line 667, in qPOS\n    answer = self._msgs.read(cmdstr)\n', '  File "c:\\data\\python programs\\camera humanitas\\hyperspectralmicroscope\\PI_ScopeFoundry\\PIPython\\pipython\\pidevice\\gcsmessages.py", line 143, in read\n    self._checkerror()\n', '  File "c:\\data\\python programs\\camera humanitas\\hyperspectralmicroscope\\PI_ScopeFoundry\\PIPython\\pipython\\pidevice\\gcsmessages.py", line 302, in _checkerror\n    raise exc  # Raising NoneType while only classes or instances are allowed pylint: disable=E0702\n', 'PI_ScopeFoundry.PIPython.pipython.pidevice.gcserror.GCSError: Controller sent unexpected response (-1004)\n']
2025-02-25T16:44:04|ERROR|hyperMeasure|hyper Failed to update figure1: Controller sent unexpected response (-1004). ['Traceback (most recent call last):\n', '  File "C:\\ProgramData\\anaconda3\\envs\\scopefoundry\\lib\\site-packages\\ScopeFoundry\\measurement.py", line 362, in _on_display_update_timer\n    self.update_display()\n', '  File "c:\\data\\python programs\\camera humanitas\\hyperspectralmicroscope\\hyperspectral_measure.py", line 88, in update_display\n    self.stage.read_from_hardware()\n', '  File "C:\\ProgramData\\anaconda3\\envs\\scopefoundry\\lib\\site-packages\\ScopeFoundry\\hardware.py", line 188, in read_from_hardware\n    lq.read_from_hardware()\n', '  File "C:\\ProgramData\\anaconda3\\envs\\scopefoundry\\lib\\site-packages\\ScopeFoundry\\logged_quantity.py", line 203, in read_from_hardware\n    val = self.hardware_read_func()\n', '  File "c:\\data\\python programs\\camera humanitas\\hyperspectralmicroscope\\PI_ScopeFoundry\\PI_GCS_device.py", line 68, in get_position\n    position = self.pi_device.qPOS(self.axis)[self.axis]\n', '  File "c:\\data\\python programs\\camera humanitas\\hyperspectralmicroscope\\PI_ScopeFoundry\\PIPython\\pipython\\pidevice\\gcs2\\gcs2commands.py", line 667, in qPOS\n    answer = self._msgs.read(cmdstr)\n', '  File "c:\\data\\python programs\\camera humanitas\\hyperspectralmicroscope\\PI_ScopeFoundry\\PIPython\\pipython\\pidevice\\gcsmessages.py", line 143, in read\n    self._checkerror()\n', '  File "c:\\data\\python programs\\camera humanitas\\hyperspectralmicroscope\\PI_ScopeFoundry\\PIPython\\pipython\\pidevice\\gcsmessages.py", line 302, in _checkerror\n    raise exc  # Raising NoneType while only classes or instances are allowed pylint: disable=E0702\n', 'PI_ScopeFoundry.PIPython.pipython.pidevice.gcserror.GCSError: Controller sent unexpected response (-1004)\n']
2025-02-25T16:44:04|ERROR|hyperMeasure|hyper Failed to update figure1: Controller sent unexpected response (-1004). ['Traceback (most recent call last):\n', '  File "C:\\ProgramData\\anaconda3\\envs\\scopefoundry\\lib\\site-packages\\ScopeFoundry\\measurement.py", line 362, in _on_display_update_timer\n    self.update_display()\n', '  File "c:\\data\\python programs\\camera humanitas\\hyperspectralmicroscope\\hyperspectral_measure.py", line 88, in update_display\n    self.stage.read_from_hardware()\n', '  File "C:\\ProgramData\\anaconda3\\envs\\scopefoundry\\lib\\site-packages\\ScopeFoundry\\hardware.py", line 188, in read_from_hardware\n    lq.read_from_hardware()\n', '  File "C:\\ProgramData\\anaconda3\\envs\\scopefoundry\\lib\\site-packages\\ScopeFoundry\\logged_quantity.py", line 203, in read_from_hardware\n    val = self.hardware_read_func()\n', '  File "c:\\data\\python programs\\camera humanitas\\hyperspectralmicroscope\\PI_ScopeFoundry\\PI_GCS_device.py", line 68, in get_position\n    position = self.pi_device.qPOS(self.axis)[self.axis]\n', '  File "c:\\data\\python programs\\camera humanitas\\hyperspectralmicroscope\\PI_ScopeFoundry\\PIPython\\pipython\\pidevice\\gcs2\\gcs2commands.py", line 667, in qPOS\n    answer = self._msgs.read(cmdstr)\n', '  File "c:\\data\\python programs\\camera humanitas\\hyperspectralmicroscope\\PI_ScopeFoundry\\PIPython\\pipython\\pidevice\\gcsmessages.py", line 143, in read\n    self._checkerror()\n', '  File "c:\\data\\python programs\\camera humanitas\\hyperspectralmicroscope\\PI_ScopeFoundry\\PIPython\\pipython\\pidevice\\gcsmessages.py", line 302, in _checkerror\n    raise exc  # Raising NoneType while only classes or instances are allowed pylint: disable=E0702\n', 'PI_ScopeFoundry.PIPython.pipython.pidevice.gcserror.GCSError: Controller sent unexpected response (-1004)\n']
2025-02-25T16:44:04|ERROR|hyperMeasure|hyper Failed to update figure1: Controller sent unexpected response (-1004). ['Traceback (most recent call last):\n', '  File "C:\\ProgramData\\anaconda3\\envs\\scopefoundry\\lib\\site-packages\\ScopeFoundry\\measurement.py", line 362, in _on_display_update_timer\n    self.update_display()\n', '  File "c:\\data\\python programs\\camera humanitas\\hyperspectralmicroscope\\hyperspectral_measure.py", line 88, in update_display\n    self.stage.read_from_hardware()\n', '  File "C:\\ProgramData\\anaconda3\\envs\\scopefoundry\\lib\\site-packages\\ScopeFoundry\\hardware.py", line 188, in read_from_hardware\n    lq.read_from_hardware()\n', '  File "C:\\ProgramData\\anaconda3\\envs\\scopefoundry\\lib\\site-packages\\ScopeFoundry\\logged_quantity.py", line 203, in read_from_hardware\n    val = self.hardware_read_func()\n', '  File "c:\\data\\python programs\\camera humanitas\\hyperspectralmicroscope\\PI_ScopeFoundry\\PI_GCS_device.py", line 68, in get_position\n    position = self.pi_device.qPOS(self.axis)[self.axis]\n', '  File "c:\\data\\python programs\\camera humanitas\\hyperspectralmicroscope\\PI_ScopeFoundry\\PIPython\\pipython\\pidevice\\gcs2\\gcs2commands.py", line 667, in qPOS\n    answer = self._msgs.read(cmdstr)\n', '  File "c:\\data\\python programs\\camera humanitas\\hyperspectralmicroscope\\PI_ScopeFoundry\\PIPython\\pipython\\pidevice\\gcsmessages.py", line 143, in read\n    self._checkerror()\n', '  File "c:\\data\\python programs\\camera humanitas\\hyperspectralmicroscope\\PI_ScopeFoundry\\PIPython\\pipython\\pidevice\\gcsmessages.py", line 302, in _checkerror\n    raise exc  # Raising NoneType while only classes or instances are allowed pylint: disable=E0702\n', 'PI_ScopeFoundry.PIPython.pipython.pidevice.gcserror.GCSError: Controller sent unexpected response (-1004)\n']
2025-02-25T16:44:04|ERROR|hyperMeasure|hyper Failed to update figure1: Controller sent unexpected response (-1004). ['Traceback (most recent call last):\n', '  File "C:\\ProgramData\\anaconda3\\envs\\scopefoundry\\lib\\site-packages\\ScopeFoundry\\measurement.py", line 362, in _on_display_update_timer\n    self.update_display()\n', '  File "c:\\data\\python programs\\camera humanitas\\hyperspectralmicroscope\\hyperspectral_measure.py", line 88, in update_display\n    self.stage.read_from_hardware()\n', '  File "C:\\ProgramData\\anaconda3\\envs\\scopefoundry\\lib\\site-packages\\ScopeFoundry\\hardware.py", line 188, in read_from_hardware\n    lq.read_from_hardware()\n', '  File "C:\\ProgramData\\anaconda3\\envs\\scopefoundry\\lib\\site-packages\\ScopeFoundry\\logged_quantity.py", line 203, in read_from_hardware\n    val = self.hardware_read_func()\n', '  File "c:\\data\\python programs\\camera humanitas\\hyperspectralmicroscope\\PI_ScopeFoundry\\PI_GCS_device.py", line 68, in get_position\n    position = self.pi_device.qPOS(self.axis)[self.axis]\n', '  File "c:\\data\\python programs\\camera humanitas\\hyperspectralmicroscope\\PI_ScopeFoundry\\PIPython\\pipython\\pidevice\\gcs2\\gcs2commands.py", line 667, in qPOS\n    answer = self._msgs.read(cmdstr)\n', '  File "c:\\data\\python programs\\camera humanitas\\hyperspectralmicroscope\\PI_ScopeFoundry\\PIPython\\pipython\\pidevice\\gcsmessages.py", line 143, in read\n    self._checkerror()\n', '  File "c:\\data\\python programs\\camera humanitas\\hyperspectralmicroscope\\PI_ScopeFoundry\\PIPython\\pipython\\pidevice\\gcsmessages.py", line 302, in _checkerror\n    raise exc  # Raising NoneType while only classes or instances are allowed pylint: disable=E0702\n', 'PI_ScopeFoundry.PIPython.pipython.pidevice.gcserror.GCSError: Controller sent unexpected response (-1004)\n']
2025-02-25T16:44:04|ERROR|hyperMeasure|hyper Failed to update figure1: Controller sent unexpected response (-1004). ['Traceback (most recent call last):\n', '  File "C:\\ProgramData\\anaconda3\\envs\\scopefoundry\\lib\\site-packages\\ScopeFoundry\\measurement.py", line 362, in _on_display_update_timer\n    self.update_display()\n', '  File "c:\\data\\python programs\\camera humanitas\\hyperspectralmicroscope\\hyperspectral_measure.py", line 88, in update_display\n    self.stage.read_from_hardware()\n', '  File "C:\\ProgramData\\anaconda3\\envs\\scopefoundry\\lib\\site-packages\\ScopeFoundry\\hardware.py", line 188, in read_from_hardware\n    lq.read_from_hardware()\n', '  File "C:\\ProgramData\\anaconda3\\envs\\scopefoundry\\lib\\site-packages\\ScopeFoundry\\logged_quantity.py", line 203, in read_from_hardware\n    val = self.hardware_read_func()\n', '  File "c:\\data\\python programs\\camera humanitas\\hyperspectralmicroscope\\PI_ScopeFoundry\\PI_GCS_device.py", line 68, in get_position\n    position = self.pi_device.qPOS(self.axis)[self.axis]\n', '  File "c:\\data\\python programs\\camera humanitas\\hyperspectralmicroscope\\PI_ScopeFoundry\\PIPython\\pipython\\pidevice\\gcs2\\gcs2commands.py", line 667, in qPOS\n    answer = self._msgs.read(cmdstr)\n', '  File "c:\\data\\python programs\\camera humanitas\\hyperspectralmicroscope\\PI_ScopeFoundry\\PIPython\\pipython\\pidevice\\gcsmessages.py", line 143, in read\n    self._checkerror()\n', '  File "c:\\data\\python programs\\camera humanitas\\hyperspectralmicroscope\\PI_ScopeFoundry\\PIPython\\pipython\\pidevice\\gcsmessages.py", line 302, in _checkerror\n    raise exc  # Raising NoneType while only classes or instances are allowed pylint: disable=E0702\n', 'PI_ScopeFoundry.PIPython.pipython.pidevice.gcserror.GCSError: Controller sent unexpected response (-1004)\n']
2025-02-25T16:44:04|ERROR|hyperMeasure|hyper Failed to update figure1: Controller sent unexpected response (-1004). ['Traceback (most recent call last):\n', '  File "C:\\ProgramData\\anaconda3\\envs\\scopefoundry\\lib\\site-packages\\ScopeFoundry\\measurement.py", line 362, in _on_display_update_timer\n    self.update_display()\n', '  File "c:\\data\\python programs\\camera humanitas\\hyperspectralmicroscope\\hyperspectral_measure.py", line 88, in update_display\n    self.stage.read_from_hardware()\n', '  File "C:\\ProgramData\\anaconda3\\envs\\scopefoundry\\lib\\site-packages\\ScopeFoundry\\hardware.py", line 188, in read_from_hardware\n    lq.read_from_hardware()\n', '  File "C:\\ProgramData\\anaconda3\\envs\\scopefoundry\\lib\\site-packages\\ScopeFoundry\\logged_quantity.py", line 203, in read_from_hardware\n    val = self.hardware_read_func()\n', '  File "c:\\data\\python programs\\camera humanitas\\hyperspectralmicroscope\\PI_ScopeFoundry\\PI_GCS_device.py", line 68, in get_position\n    position = self.pi_device.qPOS(self.axis)[self.axis]\n', '  File "c:\\data\\python programs\\camera humanitas\\hyperspectralmicroscope\\PI_ScopeFoundry\\PIPython\\pipython\\pidevice\\gcs2\\gcs2commands.py", line 667, in qPOS\n    answer = self._msgs.read(cmdstr)\n', '  File "c:\\data\\python programs\\camera humanitas\\hyperspectralmicroscope\\PI_ScopeFoundry\\PIPython\\pipython\\pidevice\\gcsmessages.py", line 143, in read\n    self._checkerror()\n', '  File "c:\\data\\python programs\\camera humanitas\\hyperspectralmicroscope\\PI_ScopeFoundry\\PIPython\\pipython\\pidevice\\gcsmessages.py", line 302, in _checkerror\n    raise exc  # Raising NoneType while only classes or instances are allowed pylint: disable=E0702\n', 'PI_ScopeFoundry.PIPython.pipython.pidevice.gcserror.GCSError: Controller sent unexpected response (-1004)\n']
2025-02-25T16:44:05|ERROR|hyperMeasure|hyper Failed to update figure1: Controller sent unexpected response (-1004). ['Traceback (most recent call last):\n', '  File "C:\\ProgramData\\anaconda3\\envs\\scopefoundry\\lib\\site-packages\\ScopeFoundry\\measurement.py", line 362, in _on_display_update_timer\n    self.update_display()\n', '  File "c:\\data\\python programs\\camera humanitas\\hyperspectralmicroscope\\hyperspectral_measure.py", line 88, in update_display\n    self.stage.read_from_hardware()\n', '  File "C:\\ProgramData\\anaconda3\\envs\\scopefoundry\\lib\\site-packages\\ScopeFoundry\\hardware.py", line 188, in read_from_hardware\n    lq.read_from_hardware()\n', '  File "C:\\ProgramData\\anaconda3\\envs\\scopefoundry\\lib\\site-packages\\ScopeFoundry\\logged_quantity.py", line 203, in read_from_hardware\n    val = self.hardware_read_func()\n', '  File "c:\\data\\python programs\\camera humanitas\\hyperspectralmicroscope\\PI_ScopeFoundry\\PI_GCS_device.py", line 68, in get_position\n    position = self.pi_device.qPOS(self.axis)[self.axis]\n', '  File "c:\\data\\python programs\\camera humanitas\\hyperspectralmicroscope\\PI_ScopeFoundry\\PIPython\\pipython\\pidevice\\gcs2\\gcs2commands.py", line 667, in qPOS\n    answer = self._msgs.read(cmdstr)\n', '  File "c:\\data\\python programs\\camera humanitas\\hyperspectralmicroscope\\PI_ScopeFoundry\\PIPython\\pipython\\pidevice\\gcsmessages.py", line 143, in read\n    self._checkerror()\n', '  File "c:\\data\\python programs\\camera humanitas\\hyperspectralmicroscope\\PI_ScopeFoundry\\PIPython\\pipython\\pidevice\\gcsmessages.py", line 302, in _checkerror\n    raise exc  # Raising NoneType while only classes or instances are allowed pylint: disable=E0702\n', 'PI_ScopeFoundry.PIPython.pipython.pidevice.gcserror.GCSError: Controller sent unexpected response (-1004)\n']
2025-02-25T16:44:05|ERROR|hyperMeasure|hyper Failed to update figure1: Controller sent unexpected response (-1004). ['Traceback (most recent call last):\n', '  File "C:\\ProgramData\\anaconda3\\envs\\scopefoundry\\lib\\site-packages\\ScopeFoundry\\measurement.py", line 362, in _on_display_update_timer\n    self.update_display()\n', '  File "c:\\data\\python programs\\camera humanitas\\hyperspectralmicroscope\\hyperspectral_measure.py", line 88, in update_display\n    self.stage.read_from_hardware()\n', '  File "C:\\ProgramData\\anaconda3\\envs\\scopefoundry\\lib\\site-packages\\ScopeFoundry\\hardware.py", line 188, in read_from_hardware\n    lq.read_from_hardware()\n', '  File "C:\\ProgramData\\anaconda3\\envs\\scopefoundry\\lib\\site-packages\\ScopeFoundry\\logged_quantity.py", line 203, in read_from_hardware\n    val = self.hardware_read_func()\n', '  File "c:\\data\\python programs\\camera humanitas\\hyperspectralmicroscope\\PI_ScopeFoundry\\PI_GCS_device.py", line 68, in get_position\n    position = self.pi_device.qPOS(self.axis)[self.axis]\n', '  File "c:\\data\\python programs\\camera humanitas\\hyperspectralmicroscope\\PI_ScopeFoundry\\PIPython\\pipython\\pidevice\\gcs2\\gcs2commands.py", line 667, in qPOS\n    answer = self._msgs.read(cmdstr)\n', '  File "c:\\data\\python programs\\camera humanitas\\hyperspectralmicroscope\\PI_ScopeFoundry\\PIPython\\pipython\\pidevice\\gcsmessages.py", line 143, in read\n    self._checkerror()\n', '  File "c:\\data\\python programs\\camera humanitas\\hyperspectralmicroscope\\PI_ScopeFoundry\\PIPython\\pipython\\pidevice\\gcsmessages.py", line 302, in _checkerror\n    raise exc  # Raising NoneType while only classes or instances are allowed pylint: disable=E0702\n', 'PI_ScopeFoundry.PIPython.pipython.pidevice.gcserror.GCSError: Controller sent unexpected response (-1004)\n']
2025-02-25T16:44:05|ERROR|hyperMeasure|hyper Failed to update figure1: Controller sent unexpected response (-1004). ['Traceback (most recent call last):\n', '  File "C:\\ProgramData\\anaconda3\\envs\\scopefoundry\\lib\\site-packages\\ScopeFoundry\\measurement.py", line 362, in _on_display_update_timer\n    self.update_display()\n', '  File "c:\\data\\python programs\\camera humanitas\\hyperspectralmicroscope\\hyperspectral_measure.py", line 88, in update_display\n    self.stage.read_from_hardware()\n', '  File "C:\\ProgramData\\anaconda3\\envs\\scopefoundry\\lib\\site-packages\\ScopeFoundry\\hardware.py", line 188, in read_from_hardware\n    lq.read_from_hardware()\n', '  File "C:\\ProgramData\\anaconda3\\envs\\scopefoundry\\lib\\site-packages\\ScopeFoundry\\logged_quantity.py", line 203, in read_from_hardware\n    val = self.hardware_read_func()\n', '  File "c:\\data\\python programs\\camera humanitas\\hyperspectralmicroscope\\PI_ScopeFoundry\\PI_GCS_device.py", line 68, in get_position\n    position = self.pi_device.qPOS(self.axis)[self.axis]\n', '  File "c:\\data\\python programs\\camera humanitas\\hyperspectralmicroscope\\PI_ScopeFoundry\\PIPython\\pipython\\pidevice\\gcs2\\gcs2commands.py", line 667, in qPOS\n    answer = self._msgs.read(cmdstr)\n', '  File "c:\\data\\python programs\\camera humanitas\\hyperspectralmicroscope\\PI_ScopeFoundry\\PIPython\\pipython\\pidevice\\gcsmessages.py", line 143, in read\n    self._checkerror()\n', '  File "c:\\data\\python programs\\camera humanitas\\hyperspectralmicroscope\\PI_ScopeFoundry\\PIPython\\pipython\\pidevice\\gcsmessages.py", line 302, in _checkerror\n    raise exc  # Raising NoneType while only classes or instances are allowed pylint: disable=E0702\n', 'PI_ScopeFoundry.PIPython.pipython.pidevice.gcserror.GCSError: Controller sent unexpected response (-1004)\n']
2025-02-25T16:44:05|ERROR|hyperMeasure|hyper Failed to update figure1: Controller sent unexpected response (-1004). ['Traceback (most recent call last):\n', '  File "C:\\ProgramData\\anaconda3\\envs\\scopefoundry\\lib\\site-packages\\ScopeFoundry\\measurement.py", line 362, in _on_display_update_timer\n    self.update_display()\n', '  File "c:\\data\\python programs\\camera humanitas\\hyperspectralmicroscope\\hyperspectral_measure.py", line 88, in update_display\n    self.stage.read_from_hardware()\n', '  File "C:\\ProgramData\\anaconda3\\envs\\scopefoundry\\lib\\site-packages\\ScopeFoundry\\hardware.py", line 188, in read_from_hardware\n    lq.read_from_hardware()\n', '  File "C:\\ProgramData\\anaconda3\\envs\\scopefoundry\\lib\\site-packages\\ScopeFoundry\\logged_quantity.py", line 203, in read_from_hardware\n    val = self.hardware_read_func()\n', '  File "c:\\data\\python programs\\camera humanitas\\hyperspectralmicroscope\\PI_ScopeFoundry\\PI_GCS_device.py", line 68, in get_position\n    position = self.pi_device.qPOS(self.axis)[self.axis]\n', '  File "c:\\data\\python programs\\camera humanitas\\hyperspectralmicroscope\\PI_ScopeFoundry\\PIPython\\pipython\\pidevice\\gcs2\\gcs2commands.py", line 667, in qPOS\n    answer = self._msgs.read(cmdstr)\n', '  File "c:\\data\\python programs\\camera humanitas\\hyperspectralmicroscope\\PI_ScopeFoundry\\PIPython\\pipython\\pidevice\\gcsmessages.py", line 143, in read\n    self._checkerror()\n', '  File "c:\\data\\python programs\\camera humanitas\\hyperspectralmicroscope\\PI_ScopeFoundry\\PIPython\\pipython\\pidevice\\gcsmessages.py", line 302, in _checkerror\n    raise exc  # Raising NoneType while only classes or instances are allowed pylint: disable=E0702\n', 'PI_ScopeFoundry.PIPython.pipython.pidevice.gcserror.GCSError: Controller sent unexpected response (-1004)\n']
2025-02-25T16:44:05|ERROR|hyperMeasure|hyper Failed to update figure1: Controller sent unexpected response (-1004). ['Traceback (most recent call last):\n', '  File "C:\\ProgramData\\anaconda3\\envs\\scopefoundry\\lib\\site-packages\\ScopeFoundry\\measurement.py", line 362, in _on_display_update_timer\n    self.update_display()\n', '  File "c:\\data\\python programs\\camera humanitas\\hyperspectralmicroscope\\hyperspectral_measure.py", line 88, in update_display\n    self.stage.read_from_hardware()\n', '  File "C:\\ProgramData\\anaconda3\\envs\\scopefoundry\\lib\\site-packages\\ScopeFoundry\\hardware.py", line 188, in read_from_hardware\n    lq.read_from_hardware()\n', '  File "C:\\ProgramData\\anaconda3\\envs\\scopefoundry\\lib\\site-packages\\ScopeFoundry\\logged_quantity.py", line 203, in read_from_hardware\n    val = self.hardware_read_func()\n', '  File "c:\\data\\python programs\\camera humanitas\\hyperspectralmicroscope\\PI_ScopeFoundry\\PI_GCS_device.py", line 68, in get_position\n    position = self.pi_device.qPOS(self.axis)[self.axis]\n', '  File "c:\\data\\python programs\\camera humanitas\\hyperspectralmicroscope\\PI_ScopeFoundry\\PIPython\\pipython\\pidevice\\gcs2\\gcs2commands.py", line 667, in qPOS\n    answer = self._msgs.read(cmdstr)\n', '  File "c:\\data\\python programs\\camera humanitas\\hyperspectralmicroscope\\PI_ScopeFoundry\\PIPython\\pipython\\pidevice\\gcsmessages.py", line 143, in read\n    self._checkerror()\n', '  File "c:\\data\\python programs\\camera humanitas\\hyperspectralmicroscope\\PI_ScopeFoundry\\PIPython\\pipython\\pidevice\\gcsmessages.py", line 302, in _checkerror\n    raise exc  # Raising NoneType while only classes or instances are allowed pylint: disable=E0702\n', 'PI_ScopeFoundry.PIPython.pipython.pidevice.gcserror.GCSError: Controller sent unexpected response (-1004)\n']
2025-02-25T16:44:05|ERROR|hyperMeasure|hyper Failed to update figure1: Controller sent unexpected response (-1004). ['Traceback (most recent call last):\n', '  File "C:\\ProgramData\\anaconda3\\envs\\scopefoundry\\lib\\site-packages\\ScopeFoundry\\measurement.py", line 362, in _on_display_update_timer\n    self.update_display()\n', '  File "c:\\data\\python programs\\camera humanitas\\hyperspectralmicroscope\\hyperspectral_measure.py", line 88, in update_display\n    self.stage.read_from_hardware()\n', '  File "C:\\ProgramData\\anaconda3\\envs\\scopefoundry\\lib\\site-packages\\ScopeFoundry\\hardware.py", line 188, in read_from_hardware\n    lq.read_from_hardware()\n', '  File "C:\\ProgramData\\anaconda3\\envs\\scopefoundry\\lib\\site-packages\\ScopeFoundry\\logged_quantity.py", line 203, in read_from_hardware\n    val = self.hardware_read_func()\n', '  File "c:\\data\\python programs\\camera humanitas\\hyperspectralmicroscope\\PI_ScopeFoundry\\PI_GCS_device.py", line 68, in get_position\n    position = self.pi_device.qPOS(self.axis)[self.axis]\n', '  File "c:\\data\\python programs\\camera humanitas\\hyperspectralmicroscope\\PI_ScopeFoundry\\PIPython\\pipython\\pidevice\\gcs2\\gcs2commands.py", line 667, in qPOS\n    answer = self._msgs.read(cmdstr)\n', '  File "c:\\data\\python programs\\camera humanitas\\hyperspectralmicroscope\\PI_ScopeFoundry\\PIPython\\pipython\\pidevice\\gcsmessages.py", line 143, in read\n    self._checkerror()\n', '  File "c:\\data\\python programs\\camera humanitas\\hyperspectralmicroscope\\PI_ScopeFoundry\\PIPython\\pipython\\pidevice\\gcsmessages.py", line 302, in _checkerror\n    raise exc  # Raising NoneType while only classes or instances are allowed pylint: disable=E0702\n', 'PI_ScopeFoundry.PIPython.pipython.pidevice.gcserror.GCSError: Controller sent unexpected response (-1004)\n']
2025-02-25T16:44:05|ERROR|hyperMeasure|hyper Failed to update figure1: Controller sent unexpected response (-1004). ['Traceback (most recent call last):\n', '  File "C:\\ProgramData\\anaconda3\\envs\\scopefoundry\\lib\\site-packages\\ScopeFoundry\\measurement.py", line 362, in _on_display_update_timer\n    self.update_display()\n', '  File "c:\\data\\python programs\\camera humanitas\\hyperspectralmicroscope\\hyperspectral_measure.py", line 88, in update_display\n    self.stage.read_from_hardware()\n', '  File "C:\\ProgramData\\anaconda3\\envs\\scopefoundry\\lib\\site-packages\\ScopeFoundry\\hardware.py", line 188, in read_from_hardware\n    lq.read_from_hardware()\n', '  File "C:\\ProgramData\\anaconda3\\envs\\scopefoundry\\lib\\site-packages\\ScopeFoundry\\logged_quantity.py", line 203, in read_from_hardware\n    val = self.hardware_read_func()\n', '  File "c:\\data\\python programs\\camera humanitas\\hyperspectralmicroscope\\PI_ScopeFoundry\\PI_GCS_device.py", line 68, in get_position\n    position = self.pi_device.qPOS(self.axis)[self.axis]\n', '  File "c:\\data\\python programs\\camera humanitas\\hyperspectralmicroscope\\PI_ScopeFoundry\\PIPython\\pipython\\pidevice\\gcs2\\gcs2commands.py", line 667, in qPOS\n    answer = self._msgs.read(cmdstr)\n', '  File "c:\\data\\python programs\\camera humanitas\\hyperspectralmicroscope\\PI_ScopeFoundry\\PIPython\\pipython\\pidevice\\gcsmessages.py", line 143, in read\n    self._checkerror()\n', '  File "c:\\data\\python programs\\camera humanitas\\hyperspectralmicroscope\\PI_ScopeFoundry\\PIPython\\pipython\\pidevice\\gcsmessages.py", line 302, in _checkerror\n    raise exc  # Raising NoneType while only classes or instances are allowed pylint: disable=E0702\n', 'PI_ScopeFoundry.PIPython.pipython.pidevice.gcserror.GCSError: Controller sent unexpected response (-1004)\n']
2025-02-25T16:44:06|ERROR|hyperMeasure|hyper Failed to update figure1: Controller sent unexpected response (-1004). ['Traceback (most recent call last):\n', '  File "C:\\ProgramData\\anaconda3\\envs\\scopefoundry\\lib\\site-packages\\ScopeFoundry\\measurement.py", line 362, in _on_display_update_timer\n    self.update_display()\n', '  File "c:\\data\\python programs\\camera humanitas\\hyperspectralmicroscope\\hyperspectral_measure.py", line 88, in update_display\n    self.stage.read_from_hardware()\n', '  File "C:\\ProgramData\\anaconda3\\envs\\scopefoundry\\lib\\site-packages\\ScopeFoundry\\hardware.py", line 188, in read_from_hardware\n    lq.read_from_hardware()\n', '  File "C:\\ProgramData\\anaconda3\\envs\\scopefoundry\\lib\\site-packages\\ScopeFoundry\\logged_quantity.py", line 203, in read_from_hardware\n    val = self.hardware_read_func()\n', '  File "c:\\data\\python programs\\camera humanitas\\hyperspectralmicroscope\\PI_ScopeFoundry\\PI_GCS_device.py", line 68, in get_position\n    position = self.pi_device.qPOS(self.axis)[self.axis]\n', '  File "c:\\data\\python programs\\camera humanitas\\hyperspectralmicroscope\\PI_ScopeFoundry\\PIPython\\pipython\\pidevice\\gcs2\\gcs2commands.py", line 667, in qPOS\n    answer = self._msgs.read(cmdstr)\n', '  File "c:\\data\\python programs\\camera humanitas\\hyperspectralmicroscope\\PI_ScopeFoundry\\PIPython\\pipython\\pidevice\\gcsmessages.py", line 143, in read\n    self._checkerror()\n', '  File "c:\\data\\python programs\\camera humanitas\\hyperspectralmicroscope\\PI_ScopeFoundry\\PIPython\\pipython\\pidevice\\gcsmessages.py", line 302, in _checkerror\n    raise exc  # Raising NoneType while only classes or instances are allowed pylint: disable=E0702\n', 'PI_ScopeFoundry.PIPython.pipython.pidevice.gcserror.GCSError: Controller sent unexpected response (-1004)\n']
2025-02-25T16:44:06|ERROR|hyperMeasure|hyper Failed to update figure1: Controller sent unexpected response (-1004). ['Traceback (most recent call last):\n', '  File "C:\\ProgramData\\anaconda3\\envs\\scopefoundry\\lib\\site-packages\\ScopeFoundry\\measurement.py", line 362, in _on_display_update_timer\n    self.update_display()\n', '  File "c:\\data\\python programs\\camera humanitas\\hyperspectralmicroscope\\hyperspectral_measure.py", line 88, in update_display\n    self.stage.read_from_hardware()\n', '  File "C:\\ProgramData\\anaconda3\\envs\\scopefoundry\\lib\\site-packages\\ScopeFoundry\\hardware.py", line 188, in read_from_hardware\n    lq.read_from_hardware()\n', '  File "C:\\ProgramData\\anaconda3\\envs\\scopefoundry\\lib\\site-packages\\ScopeFoundry\\logged_quantity.py", line 203, in read_from_hardware\n    val = self.hardware_read_func()\n', '  File "c:\\data\\python programs\\camera humanitas\\hyperspectralmicroscope\\PI_ScopeFoundry\\PI_GCS_device.py", line 68, in get_position\n    position = self.pi_device.qPOS(self.axis)[self.axis]\n', '  File "c:\\data\\python programs\\camera humanitas\\hyperspectralmicroscope\\PI_ScopeFoundry\\PIPython\\pipython\\pidevice\\gcs2\\gcs2commands.py", line 667, in qPOS\n    answer = self._msgs.read(cmdstr)\n', '  File "c:\\data\\python programs\\camera humanitas\\hyperspectralmicroscope\\PI_ScopeFoundry\\PIPython\\pipython\\pidevice\\gcsmessages.py", line 143, in read\n    self._checkerror()\n', '  File "c:\\data\\python programs\\camera humanitas\\hyperspectralmicroscope\\PI_ScopeFoundry\\PIPython\\pipython\\pidevice\\gcsmessages.py", line 302, in _checkerror\n    raise exc  # Raising NoneType while only classes or instances are allowed pylint: disable=E0702\n', 'PI_ScopeFoundry.PIPython.pipython.pidevice.gcserror.GCSError: Controller sent unexpected response (-1004)\n']
2025-02-25T16:44:06|ERROR|hyperMeasure|hyper Failed to update figure1: Controller sent unexpected response (-1004). ['Traceback (most recent call last):\n', '  File "C:\\ProgramData\\anaconda3\\envs\\scopefoundry\\lib\\site-packages\\ScopeFoundry\\measurement.py", line 362, in _on_display_update_timer\n    self.update_display()\n', '  File "c:\\data\\python programs\\camera humanitas\\hyperspectralmicroscope\\hyperspectral_measure.py", line 88, in update_display\n    self.stage.read_from_hardware()\n', '  File "C:\\ProgramData\\anaconda3\\envs\\scopefoundry\\lib\\site-packages\\ScopeFoundry\\hardware.py", line 188, in read_from_hardware\n    lq.read_from_hardware()\n', '  File "C:\\ProgramData\\anaconda3\\envs\\scopefoundry\\lib\\site-packages\\ScopeFoundry\\logged_quantity.py", line 203, in read_from_hardware\n    val = self.hardware_read_func()\n', '  File "c:\\data\\python programs\\camera humanitas\\hyperspectralmicroscope\\PI_ScopeFoundry\\PI_GCS_device.py", line 68, in get_position\n    position = self.pi_device.qPOS(self.axis)[self.axis]\n', '  File "c:\\data\\python programs\\camera humanitas\\hyperspectralmicroscope\\PI_ScopeFoundry\\PIPython\\pipython\\pidevice\\gcs2\\gcs2commands.py", line 667, in qPOS\n    answer = self._msgs.read(cmdstr)\n', '  File "c:\\data\\python programs\\camera humanitas\\hyperspectralmicroscope\\PI_ScopeFoundry\\PIPython\\pipython\\pidevice\\gcsmessages.py", line 143, in read\n    self._checkerror()\n', '  File "c:\\data\\python programs\\camera humanitas\\hyperspectralmicroscope\\PI_ScopeFoundry\\PIPython\\pipython\\pidevice\\gcsmessages.py", line 302, in _checkerror\n    raise exc  # Raising NoneType while only classes or instances are allowed pylint: disable=E0702\n', 'PI_ScopeFoundry.PIPython.pipython.pidevice.gcserror.GCSError: Controller sent unexpected response (-1004)\n']
2025-02-25T16:44:06|ERROR|hyperMeasure|hyper Failed to update figure1: Controller sent unexpected response (-1004). ['Traceback (most recent call last):\n', '  File "C:\\ProgramData\\anaconda3\\envs\\scopefoundry\\lib\\site-packages\\ScopeFoundry\\measurement.py", line 362, in _on_display_update_timer\n    self.update_display()\n', '  File "c:\\data\\python programs\\camera humanitas\\hyperspectralmicroscope\\hyperspectral_measure.py", line 88, in update_display\n    self.stage.read_from_hardware()\n', '  File "C:\\ProgramData\\anaconda3\\envs\\scopefoundry\\lib\\site-packages\\ScopeFoundry\\hardware.py", line 188, in read_from_hardware\n    lq.read_from_hardware()\n', '  File "C:\\ProgramData\\anaconda3\\envs\\scopefoundry\\lib\\site-packages\\ScopeFoundry\\logged_quantity.py", line 203, in read_from_hardware\n    val = self.hardware_read_func()\n', '  File "c:\\data\\python programs\\camera humanitas\\hyperspectralmicroscope\\PI_ScopeFoundry\\PI_GCS_device.py", line 68, in get_position\n    position = self.pi_device.qPOS(self.axis)[self.axis]\n', '  File "c:\\data\\python programs\\camera humanitas\\hyperspectralmicroscope\\PI_ScopeFoundry\\PIPython\\pipython\\pidevice\\gcs2\\gcs2commands.py", line 667, in qPOS\n    answer = self._msgs.read(cmdstr)\n', '  File "c:\\data\\python programs\\camera humanitas\\hyperspectralmicroscope\\PI_ScopeFoundry\\PIPython\\pipython\\pidevice\\gcsmessages.py", line 143, in read\n    self._checkerror()\n', '  File "c:\\data\\python programs\\camera humanitas\\hyperspectralmicroscope\\PI_ScopeFoundry\\PIPython\\pipython\\pidevice\\gcsmessages.py", line 302, in _checkerror\n    raise exc  # Raising NoneType while only classes or instances are allowed pylint: disable=E0702\n', 'PI_ScopeFoundry.PIPython.pipython.pidevice.gcserror.GCSError: Controller sent unexpected response (-1004)\n']
2025-02-25T16:44:06|ERROR|hyperMeasure|hyper Failed to update figure1: Controller sent unexpected response (-1004). ['Traceback (most recent call last):\n', '  File "C:\\ProgramData\\anaconda3\\envs\\scopefoundry\\lib\\site-packages\\ScopeFoundry\\measurement.py", line 362, in _on_display_update_timer\n    self.update_display()\n', '  File "c:\\data\\python programs\\camera humanitas\\hyperspectralmicroscope\\hyperspectral_measure.py", line 88, in update_display\n    self.stage.read_from_hardware()\n', '  File "C:\\ProgramData\\anaconda3\\envs\\scopefoundry\\lib\\site-packages\\ScopeFoundry\\hardware.py", line 188, in read_from_hardware\n    lq.read_from_hardware()\n', '  File "C:\\ProgramData\\anaconda3\\envs\\scopefoundry\\lib\\site-packages\\ScopeFoundry\\logged_quantity.py", line 203, in read_from_hardware\n    val = self.hardware_read_func()\n', '  File "c:\\data\\python programs\\camera humanitas\\hyperspectralmicroscope\\PI_ScopeFoundry\\PI_GCS_device.py", line 68, in get_position\n    position = self.pi_device.qPOS(self.axis)[self.axis]\n', '  File "c:\\data\\python programs\\camera humanitas\\hyperspectralmicroscope\\PI_ScopeFoundry\\PIPython\\pipython\\pidevice\\gcs2\\gcs2commands.py", line 667, in qPOS\n    answer = self._msgs.read(cmdstr)\n', '  File "c:\\data\\python programs\\camera humanitas\\hyperspectralmicroscope\\PI_ScopeFoundry\\PIPython\\pipython\\pidevice\\gcsmessages.py", line 143, in read\n    self._checkerror()\n', '  File "c:\\data\\python programs\\camera humanitas\\hyperspectralmicroscope\\PI_ScopeFoundry\\PIPython\\pipython\\pidevice\\gcsmessages.py", line 302, in _checkerror\n    raise exc  # Raising NoneType while only classes or instances are allowed pylint: disable=E0702\n', 'PI_ScopeFoundry.PIPython.pipython.pidevice.gcserror.GCSError: Controller sent unexpected response (-1004)\n']
2025-02-25T16:44:07|ERROR|hyperMeasure|hyper Failed to update figure1: Controller sent unexpected response (-1004). ['Traceback (most recent call last):\n', '  File "C:\\ProgramData\\anaconda3\\envs\\scopefoundry\\lib\\site-packages\\ScopeFoundry\\measurement.py", line 362, in _on_display_update_timer\n    self.update_display()\n', '  File "c:\\data\\python programs\\camera humanitas\\hyperspectralmicroscope\\hyperspectral_measure.py", line 88, in update_display\n    self.stage.read_from_hardware()\n', '  File "C:\\ProgramData\\anaconda3\\envs\\scopefoundry\\lib\\site-packages\\ScopeFoundry\\hardware.py", line 188, in read_from_hardware\n    lq.read_from_hardware()\n', '  File "C:\\ProgramData\\anaconda3\\envs\\scopefoundry\\lib\\site-packages\\ScopeFoundry\\logged_quantity.py", line 203, in read_from_hardware\n    val = self.hardware_read_func()\n', '  File "c:\\data\\python programs\\camera humanitas\\hyperspectralmicroscope\\PI_ScopeFoundry\\PI_GCS_device.py", line 68, in get_position\n    position = self.pi_device.qPOS(self.axis)[self.axis]\n', '  File "c:\\data\\python programs\\camera humanitas\\hyperspectralmicroscope\\PI_ScopeFoundry\\PIPython\\pipython\\pidevice\\gcs2\\gcs2commands.py", line 667, in qPOS\n    answer = self._msgs.read(cmdstr)\n', '  File "c:\\data\\python programs\\camera humanitas\\hyperspectralmicroscope\\PI_ScopeFoundry\\PIPython\\pipython\\pidevice\\gcsmessages.py", line 143, in read\n    self._checkerror()\n', '  File "c:\\data\\python programs\\camera humanitas\\hyperspectralmicroscope\\PI_ScopeFoundry\\PIPython\\pipython\\pidevice\\gcsmessages.py", line 302, in _checkerror\n    raise exc  # Raising NoneType while only classes or instances are allowed pylint: disable=E0702\n', 'PI_ScopeFoundry.PIPython.pipython.pidevice.gcserror.GCSError: Controller sent unexpected response (-1004)\n']
2025-02-25T16:44:07|ERROR|hyperMeasure|hyper Failed to update figure1: Controller sent unexpected response (-1004). ['Traceback (most recent call last):\n', '  File "C:\\ProgramData\\anaconda3\\envs\\scopefoundry\\lib\\site-packages\\ScopeFoundry\\measurement.py", line 362, in _on_display_update_timer\n    self.update_display()\n', '  File "c:\\data\\python programs\\camera humanitas\\hyperspectralmicroscope\\hyperspectral_measure.py", line 88, in update_display\n    self.stage.read_from_hardware()\n', '  File "C:\\ProgramData\\anaconda3\\envs\\scopefoundry\\lib\\site-packages\\ScopeFoundry\\hardware.py", line 188, in read_from_hardware\n    lq.read_from_hardware()\n', '  File "C:\\ProgramData\\anaconda3\\envs\\scopefoundry\\lib\\site-packages\\ScopeFoundry\\logged_quantity.py", line 203, in read_from_hardware\n    val = self.hardware_read_func()\n', '  File "c:\\data\\python programs\\camera humanitas\\hyperspectralmicroscope\\PI_ScopeFoundry\\PI_GCS_device.py", line 68, in get_position\n    position = self.pi_device.qPOS(self.axis)[self.axis]\n', '  File "c:\\data\\python programs\\camera humanitas\\hyperspectralmicroscope\\PI_ScopeFoundry\\PIPython\\pipython\\pidevice\\gcs2\\gcs2commands.py", line 667, in qPOS\n    answer = self._msgs.read(cmdstr)\n', '  File "c:\\data\\python programs\\camera humanitas\\hyperspectralmicroscope\\PI_ScopeFoundry\\PIPython\\pipython\\pidevice\\gcsmessages.py", line 143, in read\n    self._checkerror()\n', '  File "c:\\data\\python programs\\camera humanitas\\hyperspectralmicroscope\\PI_ScopeFoundry\\PIPython\\pipython\\pidevice\\gcsmessages.py", line 302, in _checkerror\n    raise exc  # Raising NoneType while only classes or instances are allowed pylint: disable=E0702\n', 'PI_ScopeFoundry.PIPython.pipython.pidevice.gcserror.GCSError: Controller sent unexpected response (-1004)\n']
2025-02-25T16:44:07|ERROR|hyperMeasure|hyper Failed to update figure1: Controller sent unexpected response (-1004). ['Traceback (most recent call last):\n', '  File "C:\\ProgramData\\anaconda3\\envs\\scopefoundry\\lib\\site-packages\\ScopeFoundry\\measurement.py", line 362, in _on_display_update_timer\n    self.update_display()\n', '  File "c:\\data\\python programs\\camera humanitas\\hyperspectralmicroscope\\hyperspectral_measure.py", line 88, in update_display\n    self.stage.read_from_hardware()\n', '  File "C:\\ProgramData\\anaconda3\\envs\\scopefoundry\\lib\\site-packages\\ScopeFoundry\\hardware.py", line 188, in read_from_hardware\n    lq.read_from_hardware()\n', '  File "C:\\ProgramData\\anaconda3\\envs\\scopefoundry\\lib\\site-packages\\ScopeFoundry\\logged_quantity.py", line 203, in read_from_hardware\n    val = self.hardware_read_func()\n', '  File "c:\\data\\python programs\\camera humanitas\\hyperspectralmicroscope\\PI_ScopeFoundry\\PI_GCS_device.py", line 68, in get_position\n    position = self.pi_device.qPOS(self.axis)[self.axis]\n', '  File "c:\\data\\python programs\\camera humanitas\\hyperspectralmicroscope\\PI_ScopeFoundry\\PIPython\\pipython\\pidevice\\gcs2\\gcs2commands.py", line 667, in qPOS\n    answer = self._msgs.read(cmdstr)\n', '  File "c:\\data\\python programs\\camera humanitas\\hyperspectralmicroscope\\PI_ScopeFoundry\\PIPython\\pipython\\pidevice\\gcsmessages.py", line 143, in read\n    self._checkerror()\n', '  File "c:\\data\\python programs\\camera humanitas\\hyperspectralmicroscope\\PI_ScopeFoundry\\PIPython\\pipython\\pidevice\\gcsmessages.py", line 302, in _checkerror\n    raise exc  # Raising NoneType while only classes or instances are allowed pylint: disable=E0702\n', 'PI_ScopeFoundry.PIPython.pipython.pidevice.gcserror.GCSError: Controller sent unexpected response (-1004)\n']
2025-02-25T16:44:07|ERROR|hyperMeasure|hyper Failed to update figure1: Controller sent unexpected response (-1004). ['Traceback (most recent call last):\n', '  File "C:\\ProgramData\\anaconda3\\envs\\scopefoundry\\lib\\site-packages\\ScopeFoundry\\measurement.py", line 362, in _on_display_update_timer\n    self.update_display()\n', '  File "c:\\data\\python programs\\camera humanitas\\hyperspectralmicroscope\\hyperspectral_measure.py", line 88, in update_display\n    self.stage.read_from_hardware()\n', '  File "C:\\ProgramData\\anaconda3\\envs\\scopefoundry\\lib\\site-packages\\ScopeFoundry\\hardware.py", line 188, in read_from_hardware\n    lq.read_from_hardware()\n', '  File "C:\\ProgramData\\anaconda3\\envs\\scopefoundry\\lib\\site-packages\\ScopeFoundry\\logged_quantity.py", line 203, in read_from_hardware\n    val = self.hardware_read_func()\n', '  File "c:\\data\\python programs\\camera humanitas\\hyperspectralmicroscope\\PI_ScopeFoundry\\PI_GCS_device.py", line 68, in get_position\n    position = self.pi_device.qPOS(self.axis)[self.axis]\n', '  File "c:\\data\\python programs\\camera humanitas\\hyperspectralmicroscope\\PI_ScopeFoundry\\PIPython\\pipython\\pidevice\\gcs2\\gcs2commands.py", line 667, in qPOS\n    answer = self._msgs.read(cmdstr)\n', '  File "c:\\data\\python programs\\camera humanitas\\hyperspectralmicroscope\\PI_ScopeFoundry\\PIPython\\pipython\\pidevice\\gcsmessages.py", line 143, in read\n    self._checkerror()\n', '  File "c:\\data\\python programs\\camera humanitas\\hyperspectralmicroscope\\PI_ScopeFoundry\\PIPython\\pipython\\pidevice\\gcsmessages.py", line 302, in _checkerror\n    raise exc  # Raising NoneType while only classes or instances are allowed pylint: disable=E0702\n', 'PI_ScopeFoundry.PIPython.pipython.pidevice.gcserror.GCSError: Controller sent unexpected response (-1004)\n']
2025-02-25T16:44:07|ERROR|hyperMeasure|hyper Failed to update figure1: Controller sent unexpected response (-1004). ['Traceback (most recent call last):\n', '  File "C:\\ProgramData\\anaconda3\\envs\\scopefoundry\\lib\\site-packages\\ScopeFoundry\\measurement.py", line 362, in _on_display_update_timer\n    self.update_display()\n', '  File "c:\\data\\python programs\\camera humanitas\\hyperspectralmicroscope\\hyperspectral_measure.py", line 88, in update_display\n    self.stage.read_from_hardware()\n', '  File "C:\\ProgramData\\anaconda3\\envs\\scopefoundry\\lib\\site-packages\\ScopeFoundry\\hardware.py", line 188, in read_from_hardware\n    lq.read_from_hardware()\n', '  File "C:\\ProgramData\\anaconda3\\envs\\scopefoundry\\lib\\site-packages\\ScopeFoundry\\logged_quantity.py", line 203, in read_from_hardware\n    val = self.hardware_read_func()\n', '  File "c:\\data\\python programs\\camera humanitas\\hyperspectralmicroscope\\PI_ScopeFoundry\\PI_GCS_device.py", line 68, in get_position\n    position = self.pi_device.qPOS(self.axis)[self.axis]\n', '  File "c:\\data\\python programs\\camera humanitas\\hyperspectralmicroscope\\PI_ScopeFoundry\\PIPython\\pipython\\pidevice\\gcs2\\gcs2commands.py", line 667, in qPOS\n    answer = self._msgs.read(cmdstr)\n', '  File "c:\\data\\python programs\\camera humanitas\\hyperspectralmicroscope\\PI_ScopeFoundry\\PIPython\\pipython\\pidevice\\gcsmessages.py", line 143, in read\n    self._checkerror()\n', '  File "c:\\data\\python programs\\camera humanitas\\hyperspectralmicroscope\\PI_ScopeFoundry\\PIPython\\pipython\\pidevice\\gcsmessages.py", line 302, in _checkerror\n    raise exc  # Raising NoneType while only classes or instances are allowed pylint: disable=E0702\n', 'PI_ScopeFoundry.PIPython.pipython.pidevice.gcserror.GCSError: Controller sent unexpected response (-1004)\n']
2025-02-25T16:44:08|ERROR|hyperMeasure|hyper Failed to update figure1: Controller sent unexpected response (-1004). ['Traceback (most recent call last):\n', '  File "C:\\ProgramData\\anaconda3\\envs\\scopefoundry\\lib\\site-packages\\ScopeFoundry\\measurement.py", line 362, in _on_display_update_timer\n    self.update_display()\n', '  File "c:\\data\\python programs\\camera humanitas\\hyperspectralmicroscope\\hyperspectral_measure.py", line 88, in update_display\n    self.stage.read_from_hardware()\n', '  File "C:\\ProgramData\\anaconda3\\envs\\scopefoundry\\lib\\site-packages\\ScopeFoundry\\hardware.py", line 188, in read_from_hardware\n    lq.read_from_hardware()\n', '  File "C:\\ProgramData\\anaconda3\\envs\\scopefoundry\\lib\\site-packages\\ScopeFoundry\\logged_quantity.py", line 203, in read_from_hardware\n    val = self.hardware_read_func()\n', '  File "c:\\data\\python programs\\camera humanitas\\hyperspectralmicroscope\\PI_ScopeFoundry\\PI_GCS_device.py", line 68, in get_position\n    position = self.pi_device.qPOS(self.axis)[self.axis]\n', '  File "c:\\data\\python programs\\camera humanitas\\hyperspectralmicroscope\\PI_ScopeFoundry\\PIPython\\pipython\\pidevice\\gcs2\\gcs2commands.py", line 667, in qPOS\n    answer = self._msgs.read(cmdstr)\n', '  File "c:\\data\\python programs\\camera humanitas\\hyperspectralmicroscope\\PI_ScopeFoundry\\PIPython\\pipython\\pidevice\\gcsmessages.py", line 143, in read\n    self._checkerror()\n', '  File "c:\\data\\python programs\\camera humanitas\\hyperspectralmicroscope\\PI_ScopeFoundry\\PIPython\\pipython\\pidevice\\gcsmessages.py", line 302, in _checkerror\n    raise exc  # Raising NoneType while only classes or instances are allowed pylint: disable=E0702\n', 'PI_ScopeFoundry.PIPython.pipython.pidevice.gcserror.GCSError: Controller sent unexpected response (-1004)\n']
2025-02-25T16:44:08|ERROR|hyperMeasure|hyper Failed to update figure1: Controller sent unexpected response (-1004). ['Traceback (most recent call last):\n', '  File "C:\\ProgramData\\anaconda3\\envs\\scopefoundry\\lib\\site-packages\\ScopeFoundry\\measurement.py", line 362, in _on_display_update_timer\n    self.update_display()\n', '  File "c:\\data\\python programs\\camera humanitas\\hyperspectralmicroscope\\hyperspectral_measure.py", line 88, in update_display\n    self.stage.read_from_hardware()\n', '  File "C:\\ProgramData\\anaconda3\\envs\\scopefoundry\\lib\\site-packages\\ScopeFoundry\\hardware.py", line 188, in read_from_hardware\n    lq.read_from_hardware()\n', '  File "C:\\ProgramData\\anaconda3\\envs\\scopefoundry\\lib\\site-packages\\ScopeFoundry\\logged_quantity.py", line 203, in read_from_hardware\n    val = self.hardware_read_func()\n', '  File "c:\\data\\python programs\\camera humanitas\\hyperspectralmicroscope\\PI_ScopeFoundry\\PI_GCS_device.py", line 68, in get_position\n    position = self.pi_device.qPOS(self.axis)[self.axis]\n', '  File "c:\\data\\python programs\\camera humanitas\\hyperspectralmicroscope\\PI_ScopeFoundry\\PIPython\\pipython\\pidevice\\gcs2\\gcs2commands.py", line 667, in qPOS\n    answer = self._msgs.read(cmdstr)\n', '  File "c:\\data\\python programs\\camera humanitas\\hyperspectralmicroscope\\PI_ScopeFoundry\\PIPython\\pipython\\pidevice\\gcsmessages.py", line 143, in read\n    self._checkerror()\n', '  File "c:\\data\\python programs\\camera humanitas\\hyperspectralmicroscope\\PI_ScopeFoundry\\PIPython\\pipython\\pidevice\\gcsmessages.py", line 302, in _checkerror\n    raise exc  # Raising NoneType while only classes or instances are allowed pylint: disable=E0702\n', 'PI_ScopeFoundry.PIPython.pipython.pidevice.gcserror.GCSError: Controller sent unexpected response (-1004)\n']
2025-02-25T16:44:08|ERROR|hyperMeasure|hyper Failed to update figure1: Controller sent unexpected response (-1004). ['Traceback (most recent call last):\n', '  File "C:\\ProgramData\\anaconda3\\envs\\scopefoundry\\lib\\site-packages\\ScopeFoundry\\measurement.py", line 362, in _on_display_update_timer\n    self.update_display()\n', '  File "c:\\data\\python programs\\camera humanitas\\hyperspectralmicroscope\\hyperspectral_measure.py", line 88, in update_display\n    self.stage.read_from_hardware()\n', '  File "C:\\ProgramData\\anaconda3\\envs\\scopefoundry\\lib\\site-packages\\ScopeFoundry\\hardware.py", line 188, in read_from_hardware\n    lq.read_from_hardware()\n', '  File "C:\\ProgramData\\anaconda3\\envs\\scopefoundry\\lib\\site-packages\\ScopeFoundry\\logged_quantity.py", line 203, in read_from_hardware\n    val = self.hardware_read_func()\n', '  File "c:\\data\\python programs\\camera humanitas\\hyperspectralmicroscope\\PI_ScopeFoundry\\PI_GCS_device.py", line 68, in get_position\n    position = self.pi_device.qPOS(self.axis)[self.axis]\n', '  File "c:\\data\\python programs\\camera humanitas\\hyperspectralmicroscope\\PI_ScopeFoundry\\PIPython\\pipython\\pidevice\\gcs2\\gcs2commands.py", line 667, in qPOS\n    answer = self._msgs.read(cmdstr)\n', '  File "c:\\data\\python programs\\camera humanitas\\hyperspectralmicroscope\\PI_ScopeFoundry\\PIPython\\pipython\\pidevice\\gcsmessages.py", line 143, in read\n    self._checkerror()\n', '  File "c:\\data\\python programs\\camera humanitas\\hyperspectralmicroscope\\PI_ScopeFoundry\\PIPython\\pipython\\pidevice\\gcsmessages.py", line 302, in _checkerror\n    raise exc  # Raising NoneType while only classes or instances are allowed pylint: disable=E0702\n', 'PI_ScopeFoundry.PIPython.pipython.pidevice.gcserror.GCSError: Controller sent unexpected response (-1004)\n']
2025-02-25T16:44:08|ERROR|hyperMeasure|hyper Failed to update figure1: Controller sent unexpected response (-1004). ['Traceback (most recent call last):\n', '  File "C:\\ProgramData\\anaconda3\\envs\\scopefoundry\\lib\\site-packages\\ScopeFoundry\\measurement.py", line 362, in _on_display_update_timer\n    self.update_display()\n', '  File "c:\\data\\python programs\\camera humanitas\\hyperspectralmicroscope\\hyperspectral_measure.py", line 88, in update_display\n    self.stage.read_from_hardware()\n', '  File "C:\\ProgramData\\anaconda3\\envs\\scopefoundry\\lib\\site-packages\\ScopeFoundry\\hardware.py", line 188, in read_from_hardware\n    lq.read_from_hardware()\n', '  File "C:\\ProgramData\\anaconda3\\envs\\scopefoundry\\lib\\site-packages\\ScopeFoundry\\logged_quantity.py", line 203, in read_from_hardware\n    val = self.hardware_read_func()\n', '  File "c:\\data\\python programs\\camera humanitas\\hyperspectralmicroscope\\PI_ScopeFoundry\\PI_GCS_device.py", line 68, in get_position\n    position = self.pi_device.qPOS(self.axis)[self.axis]\n', '  File "c:\\data\\python programs\\camera humanitas\\hyperspectralmicroscope\\PI_ScopeFoundry\\PIPython\\pipython\\pidevice\\gcs2\\gcs2commands.py", line 667, in qPOS\n    answer = self._msgs.read(cmdstr)\n', '  File "c:\\data\\python programs\\camera humanitas\\hyperspectralmicroscope\\PI_ScopeFoundry\\PIPython\\pipython\\pidevice\\gcsmessages.py", line 143, in read\n    self._checkerror()\n', '  File "c:\\data\\python programs\\camera humanitas\\hyperspectralmicroscope\\PI_ScopeFoundry\\PIPython\\pipython\\pidevice\\gcsmessages.py", line 302, in _checkerror\n    raise exc  # Raising NoneType while only classes or instances are allowed pylint: disable=E0702\n', 'PI_ScopeFoundry.PIPython.pipython.pidevice.gcserror.GCSError: Controller sent unexpected response (-1004)\n']
2025-02-25T16:44:08|ERROR|hyperMeasure|hyper Failed to update figure1: Controller sent unexpected response (-1004). ['Traceback (most recent call last):\n', '  File "C:\\ProgramData\\anaconda3\\envs\\scopefoundry\\lib\\site-packages\\ScopeFoundry\\measurement.py", line 362, in _on_display_update_timer\n    self.update_display()\n', '  File "c:\\data\\python programs\\camera humanitas\\hyperspectralmicroscope\\hyperspectral_measure.py", line 88, in update_display\n    self.stage.read_from_hardware()\n', '  File "C:\\ProgramData\\anaconda3\\envs\\scopefoundry\\lib\\site-packages\\ScopeFoundry\\hardware.py", line 188, in read_from_hardware\n    lq.read_from_hardware()\n', '  File "C:\\ProgramData\\anaconda3\\envs\\scopefoundry\\lib\\site-packages\\ScopeFoundry\\logged_quantity.py", line 203, in read_from_hardware\n    val = self.hardware_read_func()\n', '  File "c:\\data\\python programs\\camera humanitas\\hyperspectralmicroscope\\PI_ScopeFoundry\\PI_GCS_device.py", line 68, in get_position\n    position = self.pi_device.qPOS(self.axis)[self.axis]\n', '  File "c:\\data\\python programs\\camera humanitas\\hyperspectralmicroscope\\PI_ScopeFoundry\\PIPython\\pipython\\pidevice\\gcs2\\gcs2commands.py", line 667, in qPOS\n    answer = self._msgs.read(cmdstr)\n', '  File "c:\\data\\python programs\\camera humanitas\\hyperspectralmicroscope\\PI_ScopeFoundry\\PIPython\\pipython\\pidevice\\gcsmessages.py", line 143, in read\n    self._checkerror()\n', '  File "c:\\data\\python programs\\camera humanitas\\hyperspectralmicroscope\\PI_ScopeFoundry\\PIPython\\pipython\\pidevice\\gcsmessages.py", line 302, in _checkerror\n    raise exc  # Raising NoneType while only classes or instances are allowed pylint: disable=E0702\n', 'PI_ScopeFoundry.PIPython.pipython.pidevice.gcserror.GCSError: Controller sent unexpected response (-1004)\n']
2025-02-25T16:44:08|ERROR|hyperMeasure|hyper Failed to update figure1: Controller sent unexpected response (-1004). ['Traceback (most recent call last):\n', '  File "C:\\ProgramData\\anaconda3\\envs\\scopefoundry\\lib\\site-packages\\ScopeFoundry\\measurement.py", line 362, in _on_display_update_timer\n    self.update_display()\n', '  File "c:\\data\\python programs\\camera humanitas\\hyperspectralmicroscope\\hyperspectral_measure.py", line 88, in update_display\n    self.stage.read_from_hardware()\n', '  File "C:\\ProgramData\\anaconda3\\envs\\scopefoundry\\lib\\site-packages\\ScopeFoundry\\hardware.py", line 188, in read_from_hardware\n    lq.read_from_hardware()\n', '  File "C:\\ProgramData\\anaconda3\\envs\\scopefoundry\\lib\\site-packages\\ScopeFoundry\\logged_quantity.py", line 203, in read_from_hardware\n    val = self.hardware_read_func()\n', '  File "c:\\data\\python programs\\camera humanitas\\hyperspectralmicroscope\\PI_ScopeFoundry\\PI_GCS_device.py", line 68, in get_position\n    position = self.pi_device.qPOS(self.axis)[self.axis]\n', '  File "c:\\data\\python programs\\camera humanitas\\hyperspectralmicroscope\\PI_ScopeFoundry\\PIPython\\pipython\\pidevice\\gcs2\\gcs2commands.py", line 667, in qPOS\n    answer = self._msgs.read(cmdstr)\n', '  File "c:\\data\\python programs\\camera humanitas\\hyperspectralmicroscope\\PI_ScopeFoundry\\PIPython\\pipython\\pidevice\\gcsmessages.py", line 143, in read\n    self._checkerror()\n', '  File "c:\\data\\python programs\\camera humanitas\\hyperspectralmicroscope\\PI_ScopeFoundry\\PIPython\\pipython\\pidevice\\gcsmessages.py", line 302, in _checkerror\n    raise exc  # Raising NoneType while only classes or instances are allowed pylint: disable=E0702\n', 'PI_ScopeFoundry.PIPython.pipython.pidevice.gcserror.GCSError: Controller sent unexpected response (-1004)\n']
2025-02-25T16:44:09|ERROR|hyperMeasure|hyper Failed to update figure1: Controller sent unexpected response (-1004). ['Traceback (most recent call last):\n', '  File "C:\\ProgramData\\anaconda3\\envs\\scopefoundry\\lib\\site-packages\\ScopeFoundry\\measurement.py", line 362, in _on_display_update_timer\n    self.update_display()\n', '  File "c:\\data\\python programs\\camera humanitas\\hyperspectralmicroscope\\hyperspectral_measure.py", line 88, in update_display\n    self.stage.read_from_hardware()\n', '  File "C:\\ProgramData\\anaconda3\\envs\\scopefoundry\\lib\\site-packages\\ScopeFoundry\\hardware.py", line 188, in read_from_hardware\n    lq.read_from_hardware()\n', '  File "C:\\ProgramData\\anaconda3\\envs\\scopefoundry\\lib\\site-packages\\ScopeFoundry\\logged_quantity.py", line 203, in read_from_hardware\n    val = self.hardware_read_func()\n', '  File "c:\\data\\python programs\\camera humanitas\\hyperspectralmicroscope\\PI_ScopeFoundry\\PI_GCS_device.py", line 68, in get_position\n    position = self.pi_device.qPOS(self.axis)[self.axis]\n', '  File "c:\\data\\python programs\\camera humanitas\\hyperspectralmicroscope\\PI_ScopeFoundry\\PIPython\\pipython\\pidevice\\gcs2\\gcs2commands.py", line 667, in qPOS\n    answer = self._msgs.read(cmdstr)\n', '  File "c:\\data\\python programs\\camera humanitas\\hyperspectralmicroscope\\PI_ScopeFoundry\\PIPython\\pipython\\pidevice\\gcsmessages.py", line 143, in read\n    self._checkerror()\n', '  File "c:\\data\\python programs\\camera humanitas\\hyperspectralmicroscope\\PI_ScopeFoundry\\PIPython\\pipython\\pidevice\\gcsmessages.py", line 302, in _checkerror\n    raise exc  # Raising NoneType while only classes or instances are allowed pylint: disable=E0702\n', 'PI_ScopeFoundry.PIPython.pipython.pidevice.gcserror.GCSError: Controller sent unexpected response (-1004)\n']
2025-02-25T16:44:09|ERROR|hyperMeasure|hyper Failed to update figure1: Controller sent unexpected response (-1004). ['Traceback (most recent call last):\n', '  File "C:\\ProgramData\\anaconda3\\envs\\scopefoundry\\lib\\site-packages\\ScopeFoundry\\measurement.py", line 362, in _on_display_update_timer\n    self.update_display()\n', '  File "c:\\data\\python programs\\camera humanitas\\hyperspectralmicroscope\\hyperspectral_measure.py", line 88, in update_display\n    self.stage.read_from_hardware()\n', '  File "C:\\ProgramData\\anaconda3\\envs\\scopefoundry\\lib\\site-packages\\ScopeFoundry\\hardware.py", line 188, in read_from_hardware\n    lq.read_from_hardware()\n', '  File "C:\\ProgramData\\anaconda3\\envs\\scopefoundry\\lib\\site-packages\\ScopeFoundry\\logged_quantity.py", line 203, in read_from_hardware\n    val = self.hardware_read_func()\n', '  File "c:\\data\\python programs\\camera humanitas\\hyperspectralmicroscope\\PI_ScopeFoundry\\PI_GCS_device.py", line 68, in get_position\n    position = self.pi_device.qPOS(self.axis)[self.axis]\n', '  File "c:\\data\\python programs\\camera humanitas\\hyperspectralmicroscope\\PI_ScopeFoundry\\PIPython\\pipython\\pidevice\\gcs2\\gcs2commands.py", line 667, in qPOS\n    answer = self._msgs.read(cmdstr)\n', '  File "c:\\data\\python programs\\camera humanitas\\hyperspectralmicroscope\\PI_ScopeFoundry\\PIPython\\pipython\\pidevice\\gcsmessages.py", line 143, in read\n    self._checkerror()\n', '  File "c:\\data\\python programs\\camera humanitas\\hyperspectralmicroscope\\PI_ScopeFoundry\\PIPython\\pipython\\pidevice\\gcsmessages.py", line 302, in _checkerror\n    raise exc  # Raising NoneType while only classes or instances are allowed pylint: disable=E0702\n', 'PI_ScopeFoundry.PIPython.pipython.pidevice.gcserror.GCSError: Controller sent unexpected response (-1004)\n']
2025-02-25T16:44:09|ERROR|hyperMeasure|hyper Failed to update figure1: Controller sent unexpected response (-1004). ['Traceback (most recent call last):\n', '  File "C:\\ProgramData\\anaconda3\\envs\\scopefoundry\\lib\\site-packages\\ScopeFoundry\\measurement.py", line 362, in _on_display_update_timer\n    self.update_display()\n', '  File "c:\\data\\python programs\\camera humanitas\\hyperspectralmicroscope\\hyperspectral_measure.py", line 88, in update_display\n    self.stage.read_from_hardware()\n', '  File "C:\\ProgramData\\anaconda3\\envs\\scopefoundry\\lib\\site-packages\\ScopeFoundry\\hardware.py", line 188, in read_from_hardware\n    lq.read_from_hardware()\n', '  File "C:\\ProgramData\\anaconda3\\envs\\scopefoundry\\lib\\site-packages\\ScopeFoundry\\logged_quantity.py", line 203, in read_from_hardware\n    val = self.hardware_read_func()\n', '  File "c:\\data\\python programs\\camera humanitas\\hyperspectralmicroscope\\PI_ScopeFoundry\\PI_GCS_device.py", line 68, in get_position\n    position = self.pi_device.qPOS(self.axis)[self.axis]\n', '  File "c:\\data\\python programs\\camera humanitas\\hyperspectralmicroscope\\PI_ScopeFoundry\\PIPython\\pipython\\pidevice\\gcs2\\gcs2commands.py", line 667, in qPOS\n    answer = self._msgs.read(cmdstr)\n', '  File "c:\\data\\python programs\\camera humanitas\\hyperspectralmicroscope\\PI_ScopeFoundry\\PIPython\\pipython\\pidevice\\gcsmessages.py", line 143, in read\n    self._checkerror()\n', '  File "c:\\data\\python programs\\camera humanitas\\hyperspectralmicroscope\\PI_ScopeFoundry\\PIPython\\pipython\\pidevice\\gcsmessages.py", line 302, in _checkerror\n    raise exc  # Raising NoneType while only classes or instances are allowed pylint: disable=E0702\n', 'PI_ScopeFoundry.PIPython.pipython.pidevice.gcserror.GCSError: Controller sent unexpected response (-1004)\n']
2025-02-25T16:44:09|ERROR|hyperMeasure|hyper Failed to update figure1: Controller sent unexpected response (-1004). ['Traceback (most recent call last):\n', '  File "C:\\ProgramData\\anaconda3\\envs\\scopefoundry\\lib\\site-packages\\ScopeFoundry\\measurement.py", line 362, in _on_display_update_timer\n    self.update_display()\n', '  File "c:\\data\\python programs\\camera humanitas\\hyperspectralmicroscope\\hyperspectral_measure.py", line 88, in update_display\n    self.stage.read_from_hardware()\n', '  File "C:\\ProgramData\\anaconda3\\envs\\scopefoundry\\lib\\site-packages\\ScopeFoundry\\hardware.py", line 188, in read_from_hardware\n    lq.read_from_hardware()\n', '  File "C:\\ProgramData\\anaconda3\\envs\\scopefoundry\\lib\\site-packages\\ScopeFoundry\\logged_quantity.py", line 203, in read_from_hardware\n    val = self.hardware_read_func()\n', '  File "c:\\data\\python programs\\camera humanitas\\hyperspectralmicroscope\\PI_ScopeFoundry\\PI_GCS_device.py", line 68, in get_position\n    position = self.pi_device.qPOS(self.axis)[self.axis]\n', '  File "c:\\data\\python programs\\camera humanitas\\hyperspectralmicroscope\\PI_ScopeFoundry\\PIPython\\pipython\\pidevice\\gcs2\\gcs2commands.py", line 667, in qPOS\n    answer = self._msgs.read(cmdstr)\n', '  File "c:\\data\\python programs\\camera humanitas\\hyperspectralmicroscope\\PI_ScopeFoundry\\PIPython\\pipython\\pidevice\\gcsmessages.py", line 143, in read\n    self._checkerror()\n', '  File "c:\\data\\python programs\\camera humanitas\\hyperspectralmicroscope\\PI_ScopeFoundry\\PIPython\\pipython\\pidevice\\gcsmessages.py", line 302, in _checkerror\n    raise exc  # Raising NoneType while only classes or instances are allowed pylint: disable=E0702\n', 'PI_ScopeFoundry.PIPython.pipython.pidevice.gcserror.GCSError: Controller sent unexpected response (-1004)\n']
2025-02-25T16:44:09|ERROR|hyperMeasure|hyper Failed to update figure1: Controller sent unexpected response (-1004). ['Traceback (most recent call last):\n', '  File "C:\\ProgramData\\anaconda3\\envs\\scopefoundry\\lib\\site-packages\\ScopeFoundry\\measurement.py", line 362, in _on_display_update_timer\n    self.update_display()\n', '  File "c:\\data\\python programs\\camera humanitas\\hyperspectralmicroscope\\hyperspectral_measure.py", line 88, in update_display\n    self.stage.read_from_hardware()\n', '  File "C:\\ProgramData\\anaconda3\\envs\\scopefoundry\\lib\\site-packages\\ScopeFoundry\\hardware.py", line 188, in read_from_hardware\n    lq.read_from_hardware()\n', '  File "C:\\ProgramData\\anaconda3\\envs\\scopefoundry\\lib\\site-packages\\ScopeFoundry\\logged_quantity.py", line 203, in read_from_hardware\n    val = self.hardware_read_func()\n', '  File "c:\\data\\python programs\\camera humanitas\\hyperspectralmicroscope\\PI_ScopeFoundry\\PI_GCS_device.py", line 68, in get_position\n    position = self.pi_device.qPOS(self.axis)[self.axis]\n', '  File "c:\\data\\python programs\\camera humanitas\\hyperspectralmicroscope\\PI_ScopeFoundry\\PIPython\\pipython\\pidevice\\gcs2\\gcs2commands.py", line 667, in qPOS\n    answer = self._msgs.read(cmdstr)\n', '  File "c:\\data\\python programs\\camera humanitas\\hyperspectralmicroscope\\PI_ScopeFoundry\\PIPython\\pipython\\pidevice\\gcsmessages.py", line 143, in read\n    self._checkerror()\n', '  File "c:\\data\\python programs\\camera humanitas\\hyperspectralmicroscope\\PI_ScopeFoundry\\PIPython\\pipython\\pidevice\\gcsmessages.py", line 302, in _checkerror\n    raise exc  # Raising NoneType while only classes or instances are allowed pylint: disable=E0702\n', 'PI_ScopeFoundry.PIPython.pipython.pidevice.gcserror.GCSError: Controller sent unexpected response (-1004)\n']
2025-02-25T16:44:10|ERROR|hyperMeasure|hyper Failed to update figure1: Controller sent unexpected response (-1004). ['Traceback (most recent call last):\n', '  File "C:\\ProgramData\\anaconda3\\envs\\scopefoundry\\lib\\site-packages\\ScopeFoundry\\measurement.py", line 362, in _on_display_update_timer\n    self.update_display()\n', '  File "c:\\data\\python programs\\camera humanitas\\hyperspectralmicroscope\\hyperspectral_measure.py", line 88, in update_display\n    self.stage.read_from_hardware()\n', '  File "C:\\ProgramData\\anaconda3\\envs\\scopefoundry\\lib\\site-packages\\ScopeFoundry\\hardware.py", line 188, in read_from_hardware\n    lq.read_from_hardware()\n', '  File "C:\\ProgramData\\anaconda3\\envs\\scopefoundry\\lib\\site-packages\\ScopeFoundry\\logged_quantity.py", line 203, in read_from_hardware\n    val = self.hardware_read_func()\n', '  File "c:\\data\\python programs\\camera humanitas\\hyperspectralmicroscope\\PI_ScopeFoundry\\PI_GCS_device.py", line 68, in get_position\n    position = self.pi_device.qPOS(self.axis)[self.axis]\n', '  File "c:\\data\\python programs\\camera humanitas\\hyperspectralmicroscope\\PI_ScopeFoundry\\PIPython\\pipython\\pidevice\\gcs2\\gcs2commands.py", line 667, in qPOS\n    answer = self._msgs.read(cmdstr)\n', '  File "c:\\data\\python programs\\camera humanitas\\hyperspectralmicroscope\\PI_ScopeFoundry\\PIPython\\pipython\\pidevice\\gcsmessages.py", line 143, in read\n    self._checkerror()\n', '  File "c:\\data\\python programs\\camera humanitas\\hyperspectralmicroscope\\PI_ScopeFoundry\\PIPython\\pipython\\pidevice\\gcsmessages.py", line 302, in _checkerror\n    raise exc  # Raising NoneType while only classes or instances are allowed pylint: disable=E0702\n', 'PI_ScopeFoundry.PIPython.pipython.pidevice.gcserror.GCSError: Controller sent unexpected response (-1004)\n']
2025-02-25T16:44:10|ERROR|hyperMeasure|hyper Failed to update figure1: Controller sent unexpected response (-1004). ['Traceback (most recent call last):\n', '  File "C:\\ProgramData\\anaconda3\\envs\\scopefoundry\\lib\\site-packages\\ScopeFoundry\\measurement.py", line 362, in _on_display_update_timer\n    self.update_display()\n', '  File "c:\\data\\python programs\\camera humanitas\\hyperspectralmicroscope\\hyperspectral_measure.py", line 88, in update_display\n    self.stage.read_from_hardware()\n', '  File "C:\\ProgramData\\anaconda3\\envs\\scopefoundry\\lib\\site-packages\\ScopeFoundry\\hardware.py", line 188, in read_from_hardware\n    lq.read_from_hardware()\n', '  File "C:\\ProgramData\\anaconda3\\envs\\scopefoundry\\lib\\site-packages\\ScopeFoundry\\logged_quantity.py", line 203, in read_from_hardware\n    val = self.hardware_read_func()\n', '  File "c:\\data\\python programs\\camera humanitas\\hyperspectralmicroscope\\PI_ScopeFoundry\\PI_GCS_device.py", line 68, in get_position\n    position = self.pi_device.qPOS(self.axis)[self.axis]\n', '  File "c:\\data\\python programs\\camera humanitas\\hyperspectralmicroscope\\PI_ScopeFoundry\\PIPython\\pipython\\pidevice\\gcs2\\gcs2commands.py", line 667, in qPOS\n    answer = self._msgs.read(cmdstr)\n', '  File "c:\\data\\python programs\\camera humanitas\\hyperspectralmicroscope\\PI_ScopeFoundry\\PIPython\\pipython\\pidevice\\gcsmessages.py", line 143, in read\n    self._checkerror()\n', '  File "c:\\data\\python programs\\camera humanitas\\hyperspectralmicroscope\\PI_ScopeFoundry\\PIPython\\pipython\\pidevice\\gcsmessages.py", line 302, in _checkerror\n    raise exc  # Raising NoneType while only classes or instances are allowed pylint: disable=E0702\n', 'PI_ScopeFoundry.PIPython.pipython.pidevice.gcserror.GCSError: Controller sent unexpected response (-1004)\n']
2025-02-25T16:44:10|ERROR|hyperMeasure|hyper Failed to update figure1: Controller sent unexpected response (-1004). ['Traceback (most recent call last):\n', '  File "C:\\ProgramData\\anaconda3\\envs\\scopefoundry\\lib\\site-packages\\ScopeFoundry\\measurement.py", line 362, in _on_display_update_timer\n    self.update_display()\n', '  File "c:\\data\\python programs\\camera humanitas\\hyperspectralmicroscope\\hyperspectral_measure.py", line 88, in update_display\n    self.stage.read_from_hardware()\n', '  File "C:\\ProgramData\\anaconda3\\envs\\scopefoundry\\lib\\site-packages\\ScopeFoundry\\hardware.py", line 188, in read_from_hardware\n    lq.read_from_hardware()\n', '  File "C:\\ProgramData\\anaconda3\\envs\\scopefoundry\\lib\\site-packages\\ScopeFoundry\\logged_quantity.py", line 203, in read_from_hardware\n    val = self.hardware_read_func()\n', '  File "c:\\data\\python programs\\camera humanitas\\hyperspectralmicroscope\\PI_ScopeFoundry\\PI_GCS_device.py", line 68, in get_position\n    position = self.pi_device.qPOS(self.axis)[self.axis]\n', '  File "c:\\data\\python programs\\camera humanitas\\hyperspectralmicroscope\\PI_ScopeFoundry\\PIPython\\pipython\\pidevice\\gcs2\\gcs2commands.py", line 667, in qPOS\n    answer = self._msgs.read(cmdstr)\n', '  File "c:\\data\\python programs\\camera humanitas\\hyperspectralmicroscope\\PI_ScopeFoundry\\PIPython\\pipython\\pidevice\\gcsmessages.py", line 143, in read\n    self._checkerror()\n', '  File "c:\\data\\python programs\\camera humanitas\\hyperspectralmicroscope\\PI_ScopeFoundry\\PIPython\\pipython\\pidevice\\gcsmessages.py", line 302, in _checkerror\n    raise exc  # Raising NoneType while only classes or instances are allowed pylint: disable=E0702\n', 'PI_ScopeFoundry.PIPython.pipython.pidevice.gcserror.GCSError: Controller sent unexpected response (-1004)\n']
2025-02-25T16:44:10|ERROR|hyperMeasure|hyper Failed to update figure1: Controller sent unexpected response (-1004). ['Traceback (most recent call last):\n', '  File "C:\\ProgramData\\anaconda3\\envs\\scopefoundry\\lib\\site-packages\\ScopeFoundry\\measurement.py", line 362, in _on_display_update_timer\n    self.update_display()\n', '  File "c:\\data\\python programs\\camera humanitas\\hyperspectralmicroscope\\hyperspectral_measure.py", line 88, in update_display\n    self.stage.read_from_hardware()\n', '  File "C:\\ProgramData\\anaconda3\\envs\\scopefoundry\\lib\\site-packages\\ScopeFoundry\\hardware.py", line 188, in read_from_hardware\n    lq.read_from_hardware()\n', '  File "C:\\ProgramData\\anaconda3\\envs\\scopefoundry\\lib\\site-packages\\ScopeFoundry\\logged_quantity.py", line 203, in read_from_hardware\n    val = self.hardware_read_func()\n', '  File "c:\\data\\python programs\\camera humanitas\\hyperspectralmicroscope\\PI_ScopeFoundry\\PI_GCS_device.py", line 68, in get_position\n    position = self.pi_device.qPOS(self.axis)[self.axis]\n', '  File "c:\\data\\python programs\\camera humanitas\\hyperspectralmicroscope\\PI_ScopeFoundry\\PIPython\\pipython\\pidevice\\gcs2\\gcs2commands.py", line 667, in qPOS\n    answer = self._msgs.read(cmdstr)\n', '  File "c:\\data\\python programs\\camera humanitas\\hyperspectralmicroscope\\PI_ScopeFoundry\\PIPython\\pipython\\pidevice\\gcsmessages.py", line 143, in read\n    self._checkerror()\n', '  File "c:\\data\\python programs\\camera humanitas\\hyperspectralmicroscope\\PI_ScopeFoundry\\PIPython\\pipython\\pidevice\\gcsmessages.py", line 302, in _checkerror\n    raise exc  # Raising NoneType while only classes or instances are allowed pylint: disable=E0702\n', 'PI_ScopeFoundry.PIPython.pipython.pidevice.gcserror.GCSError: Controller sent unexpected response (-1004)\n']
2025-02-25T16:44:10|ERROR|hyperMeasure|hyper Failed to update figure1: Controller sent unexpected response (-1004). ['Traceback (most recent call last):\n', '  File "C:\\ProgramData\\anaconda3\\envs\\scopefoundry\\lib\\site-packages\\ScopeFoundry\\measurement.py", line 362, in _on_display_update_timer\n    self.update_display()\n', '  File "c:\\data\\python programs\\camera humanitas\\hyperspectralmicroscope\\hyperspectral_measure.py", line 88, in update_display\n    self.stage.read_from_hardware()\n', '  File "C:\\ProgramData\\anaconda3\\envs\\scopefoundry\\lib\\site-packages\\ScopeFoundry\\hardware.py", line 188, in read_from_hardware\n    lq.read_from_hardware()\n', '  File "C:\\ProgramData\\anaconda3\\envs\\scopefoundry\\lib\\site-packages\\ScopeFoundry\\logged_quantity.py", line 203, in read_from_hardware\n    val = self.hardware_read_func()\n', '  File "c:\\data\\python programs\\camera humanitas\\hyperspectralmicroscope\\PI_ScopeFoundry\\PI_GCS_device.py", line 68, in get_position\n    position = self.pi_device.qPOS(self.axis)[self.axis]\n', '  File "c:\\data\\python programs\\camera humanitas\\hyperspectralmicroscope\\PI_ScopeFoundry\\PIPython\\pipython\\pidevice\\gcs2\\gcs2commands.py", line 667, in qPOS\n    answer = self._msgs.read(cmdstr)\n', '  File "c:\\data\\python programs\\camera humanitas\\hyperspectralmicroscope\\PI_ScopeFoundry\\PIPython\\pipython\\pidevice\\gcsmessages.py", line 143, in read\n    self._checkerror()\n', '  File "c:\\data\\python programs\\camera humanitas\\hyperspectralmicroscope\\PI_ScopeFoundry\\PIPython\\pipython\\pidevice\\gcsmessages.py", line 302, in _checkerror\n    raise exc  # Raising NoneType while only classes or instances are allowed pylint: disable=E0702\n', 'PI_ScopeFoundry.PIPython.pipython.pidevice.gcserror.GCSError: Controller sent unexpected response (-1004)\n']
2025-02-25T16:44:10|ERROR|hyperMeasure|hyper Failed to update figure1: Controller sent unexpected response (-1004). ['Traceback (most recent call last):\n', '  File "C:\\ProgramData\\anaconda3\\envs\\scopefoundry\\lib\\site-packages\\ScopeFoundry\\measurement.py", line 362, in _on_display_update_timer\n    self.update_display()\n', '  File "c:\\data\\python programs\\camera humanitas\\hyperspectralmicroscope\\hyperspectral_measure.py", line 88, in update_display\n    self.stage.read_from_hardware()\n', '  File "C:\\ProgramData\\anaconda3\\envs\\scopefoundry\\lib\\site-packages\\ScopeFoundry\\hardware.py", line 188, in read_from_hardware\n    lq.read_from_hardware()\n', '  File "C:\\ProgramData\\anaconda3\\envs\\scopefoundry\\lib\\site-packages\\ScopeFoundry\\logged_quantity.py", line 203, in read_from_hardware\n    val = self.hardware_read_func()\n', '  File "c:\\data\\python programs\\camera humanitas\\hyperspectralmicroscope\\PI_ScopeFoundry\\PI_GCS_device.py", line 68, in get_position\n    position = self.pi_device.qPOS(self.axis)[self.axis]\n', '  File "c:\\data\\python programs\\camera humanitas\\hyperspectralmicroscope\\PI_ScopeFoundry\\PIPython\\pipython\\pidevice\\gcs2\\gcs2commands.py", line 667, in qPOS\n    answer = self._msgs.read(cmdstr)\n', '  File "c:\\data\\python programs\\camera humanitas\\hyperspectralmicroscope\\PI_ScopeFoundry\\PIPython\\pipython\\pidevice\\gcsmessages.py", line 143, in read\n    self._checkerror()\n', '  File "c:\\data\\python programs\\camera humanitas\\hyperspectralmicroscope\\PI_ScopeFoundry\\PIPython\\pipython\\pidevice\\gcsmessages.py", line 302, in _checkerror\n    raise exc  # Raising NoneType while only classes or instances are allowed pylint: disable=E0702\n', 'PI_ScopeFoundry.PIPython.pipython.pidevice.gcserror.GCSError: Controller sent unexpected response (-1004)\n']
2025-02-25T16:44:11|ERROR|hyperMeasure|hyper Failed to update figure1: Controller sent unexpected response (-1004). ['Traceback (most recent call last):\n', '  File "C:\\ProgramData\\anaconda3\\envs\\scopefoundry\\lib\\site-packages\\ScopeFoundry\\measurement.py", line 362, in _on_display_update_timer\n    self.update_display()\n', '  File "c:\\data\\python programs\\camera humanitas\\hyperspectralmicroscope\\hyperspectral_measure.py", line 88, in update_display\n    self.stage.read_from_hardware()\n', '  File "C:\\ProgramData\\anaconda3\\envs\\scopefoundry\\lib\\site-packages\\ScopeFoundry\\hardware.py", line 188, in read_from_hardware\n    lq.read_from_hardware()\n', '  File "C:\\ProgramData\\anaconda3\\envs\\scopefoundry\\lib\\site-packages\\ScopeFoundry\\logged_quantity.py", line 203, in read_from_hardware\n    val = self.hardware_read_func()\n', '  File "c:\\data\\python programs\\camera humanitas\\hyperspectralmicroscope\\PI_ScopeFoundry\\PI_GCS_device.py", line 68, in get_position\n    position = self.pi_device.qPOS(self.axis)[self.axis]\n', '  File "c:\\data\\python programs\\camera humanitas\\hyperspectralmicroscope\\PI_ScopeFoundry\\PIPython\\pipython\\pidevice\\gcs2\\gcs2commands.py", line 667, in qPOS\n    answer = self._msgs.read(cmdstr)\n', '  File "c:\\data\\python programs\\camera humanitas\\hyperspectralmicroscope\\PI_ScopeFoundry\\PIPython\\pipython\\pidevice\\gcsmessages.py", line 143, in read\n    self._checkerror()\n', '  File "c:\\data\\python programs\\camera humanitas\\hyperspectralmicroscope\\PI_ScopeFoundry\\PIPython\\pipython\\pidevice\\gcsmessages.py", line 302, in _checkerror\n    raise exc  # Raising NoneType while only classes or instances are allowed pylint: disable=E0702\n', 'PI_ScopeFoundry.PIPython.pipython.pidevice.gcserror.GCSError: Controller sent unexpected response (-1004)\n']
2025-02-25T16:44:11|ERROR|hyperMeasure|hyper Failed to update figure1: Controller sent unexpected response (-1004). ['Traceback (most recent call last):\n', '  File "C:\\ProgramData\\anaconda3\\envs\\scopefoundry\\lib\\site-packages\\ScopeFoundry\\measurement.py", line 362, in _on_display_update_timer\n    self.update_display()\n', '  File "c:\\data\\python programs\\camera humanitas\\hyperspectralmicroscope\\hyperspectral_measure.py", line 88, in update_display\n    self.stage.read_from_hardware()\n', '  File "C:\\ProgramData\\anaconda3\\envs\\scopefoundry\\lib\\site-packages\\ScopeFoundry\\hardware.py", line 188, in read_from_hardware\n    lq.read_from_hardware()\n', '  File "C:\\ProgramData\\anaconda3\\envs\\scopefoundry\\lib\\site-packages\\ScopeFoundry\\logged_quantity.py", line 203, in read_from_hardware\n    val = self.hardware_read_func()\n', '  File "c:\\data\\python programs\\camera humanitas\\hyperspectralmicroscope\\PI_ScopeFoundry\\PI_GCS_device.py", line 68, in get_position\n    position = self.pi_device.qPOS(self.axis)[self.axis]\n', '  File "c:\\data\\python programs\\camera humanitas\\hyperspectralmicroscope\\PI_ScopeFoundry\\PIPython\\pipython\\pidevice\\gcs2\\gcs2commands.py", line 667, in qPOS\n    answer = self._msgs.read(cmdstr)\n', '  File "c:\\data\\python programs\\camera humanitas\\hyperspectralmicroscope\\PI_ScopeFoundry\\PIPython\\pipython\\pidevice\\gcsmessages.py", line 143, in read\n    self._checkerror()\n', '  File "c:\\data\\python programs\\camera humanitas\\hyperspectralmicroscope\\PI_ScopeFoundry\\PIPython\\pipython\\pidevice\\gcsmessages.py", line 302, in _checkerror\n    raise exc  # Raising NoneType while only classes or instances are allowed pylint: disable=E0702\n', 'PI_ScopeFoundry.PIPython.pipython.pidevice.gcserror.GCSError: Controller sent unexpected response (-1004)\n']
2025-02-25T16:44:11|ERROR|hyperMeasure|hyper Failed to update figure1: Controller sent unexpected response (-1004). ['Traceback (most recent call last):\n', '  File "C:\\ProgramData\\anaconda3\\envs\\scopefoundry\\lib\\site-packages\\ScopeFoundry\\measurement.py", line 362, in _on_display_update_timer\n    self.update_display()\n', '  File "c:\\data\\python programs\\camera humanitas\\hyperspectralmicroscope\\hyperspectral_measure.py", line 88, in update_display\n    self.stage.read_from_hardware()\n', '  File "C:\\ProgramData\\anaconda3\\envs\\scopefoundry\\lib\\site-packages\\ScopeFoundry\\hardware.py", line 188, in read_from_hardware\n    lq.read_from_hardware()\n', '  File "C:\\ProgramData\\anaconda3\\envs\\scopefoundry\\lib\\site-packages\\ScopeFoundry\\logged_quantity.py", line 203, in read_from_hardware\n    val = self.hardware_read_func()\n', '  File "c:\\data\\python programs\\camera humanitas\\hyperspectralmicroscope\\PI_ScopeFoundry\\PI_GCS_device.py", line 68, in get_position\n    position = self.pi_device.qPOS(self.axis)[self.axis]\n', '  File "c:\\data\\python programs\\camera humanitas\\hyperspectralmicroscope\\PI_ScopeFoundry\\PIPython\\pipython\\pidevice\\gcs2\\gcs2commands.py", line 667, in qPOS\n    answer = self._msgs.read(cmdstr)\n', '  File "c:\\data\\python programs\\camera humanitas\\hyperspectralmicroscope\\PI_ScopeFoundry\\PIPython\\pipython\\pidevice\\gcsmessages.py", line 143, in read\n    self._checkerror()\n', '  File "c:\\data\\python programs\\camera humanitas\\hyperspectralmicroscope\\PI_ScopeFoundry\\PIPython\\pipython\\pidevice\\gcsmessages.py", line 302, in _checkerror\n    raise exc  # Raising NoneType while only classes or instances are allowed pylint: disable=E0702\n', 'PI_ScopeFoundry.PIPython.pipython.pidevice.gcserror.GCSError: Controller sent unexpected response (-1004)\n']
2025-02-25T16:44:11|ERROR|hyperMeasure|hyper Failed to update figure1: Controller sent unexpected response (-1004). ['Traceback (most recent call last):\n', '  File "C:\\ProgramData\\anaconda3\\envs\\scopefoundry\\lib\\site-packages\\ScopeFoundry\\measurement.py", line 362, in _on_display_update_timer\n    self.update_display()\n', '  File "c:\\data\\python programs\\camera humanitas\\hyperspectralmicroscope\\hyperspectral_measure.py", line 88, in update_display\n    self.stage.read_from_hardware()\n', '  File "C:\\ProgramData\\anaconda3\\envs\\scopefoundry\\lib\\site-packages\\ScopeFoundry\\hardware.py", line 188, in read_from_hardware\n    lq.read_from_hardware()\n', '  File "C:\\ProgramData\\anaconda3\\envs\\scopefoundry\\lib\\site-packages\\ScopeFoundry\\logged_quantity.py", line 203, in read_from_hardware\n    val = self.hardware_read_func()\n', '  File "c:\\data\\python programs\\camera humanitas\\hyperspectralmicroscope\\PI_ScopeFoundry\\PI_GCS_device.py", line 68, in get_position\n    position = self.pi_device.qPOS(self.axis)[self.axis]\n', '  File "c:\\data\\python programs\\camera humanitas\\hyperspectralmicroscope\\PI_ScopeFoundry\\PIPython\\pipython\\pidevice\\gcs2\\gcs2commands.py", line 667, in qPOS\n    answer = self._msgs.read(cmdstr)\n', '  File "c:\\data\\python programs\\camera humanitas\\hyperspectralmicroscope\\PI_ScopeFoundry\\PIPython\\pipython\\pidevice\\gcsmessages.py", line 143, in read\n    self._checkerror()\n', '  File "c:\\data\\python programs\\camera humanitas\\hyperspectralmicroscope\\PI_ScopeFoundry\\PIPython\\pipython\\pidevice\\gcsmessages.py", line 302, in _checkerror\n    raise exc  # Raising NoneType while only classes or instances are allowed pylint: disable=E0702\n', 'PI_ScopeFoundry.PIPython.pipython.pidevice.gcserror.GCSError: Controller sent unexpected response (-1004)\n']
2025-02-25T16:44:11|ERROR|hyperMeasure|hyper Failed to update figure1: Controller sent unexpected response (-1004). ['Traceback (most recent call last):\n', '  File "C:\\ProgramData\\anaconda3\\envs\\scopefoundry\\lib\\site-packages\\ScopeFoundry\\measurement.py", line 362, in _on_display_update_timer\n    self.update_display()\n', '  File "c:\\data\\python programs\\camera humanitas\\hyperspectralmicroscope\\hyperspectral_measure.py", line 88, in update_display\n    self.stage.read_from_hardware()\n', '  File "C:\\ProgramData\\anaconda3\\envs\\scopefoundry\\lib\\site-packages\\ScopeFoundry\\hardware.py", line 188, in read_from_hardware\n    lq.read_from_hardware()\n', '  File "C:\\ProgramData\\anaconda3\\envs\\scopefoundry\\lib\\site-packages\\ScopeFoundry\\logged_quantity.py", line 203, in read_from_hardware\n    val = self.hardware_read_func()\n', '  File "c:\\data\\python programs\\camera humanitas\\hyperspectralmicroscope\\PI_ScopeFoundry\\PI_GCS_device.py", line 68, in get_position\n    position = self.pi_device.qPOS(self.axis)[self.axis]\n', '  File "c:\\data\\python programs\\camera humanitas\\hyperspectralmicroscope\\PI_ScopeFoundry\\PIPython\\pipython\\pidevice\\gcs2\\gcs2commands.py", line 667, in qPOS\n    answer = self._msgs.read(cmdstr)\n', '  File "c:\\data\\python programs\\camera humanitas\\hyperspectralmicroscope\\PI_ScopeFoundry\\PIPython\\pipython\\pidevice\\gcsmessages.py", line 143, in read\n    self._checkerror()\n', '  File "c:\\data\\python programs\\camera humanitas\\hyperspectralmicroscope\\PI_ScopeFoundry\\PIPython\\pipython\\pidevice\\gcsmessages.py", line 302, in _checkerror\n    raise exc  # Raising NoneType while only classes or instances are allowed pylint: disable=E0702\n', 'PI_ScopeFoundry.PIPython.pipython.pidevice.gcserror.GCSError: Controller sent unexpected response (-1004)\n']
2025-02-25T16:44:11|ERROR|hyperMeasure|hyper Failed to update figure1: Controller sent unexpected response (-1004). ['Traceback (most recent call last):\n', '  File "C:\\ProgramData\\anaconda3\\envs\\scopefoundry\\lib\\site-packages\\ScopeFoundry\\measurement.py", line 362, in _on_display_update_timer\n    self.update_display()\n', '  File "c:\\data\\python programs\\camera humanitas\\hyperspectralmicroscope\\hyperspectral_measure.py", line 88, in update_display\n    self.stage.read_from_hardware()\n', '  File "C:\\ProgramData\\anaconda3\\envs\\scopefoundry\\lib\\site-packages\\ScopeFoundry\\hardware.py", line 188, in read_from_hardware\n    lq.read_from_hardware()\n', '  File "C:\\ProgramData\\anaconda3\\envs\\scopefoundry\\lib\\site-packages\\ScopeFoundry\\logged_quantity.py", line 203, in read_from_hardware\n    val = self.hardware_read_func()\n', '  File "c:\\data\\python programs\\camera humanitas\\hyperspectralmicroscope\\PI_ScopeFoundry\\PI_GCS_device.py", line 68, in get_position\n    position = self.pi_device.qPOS(self.axis)[self.axis]\n', '  File "c:\\data\\python programs\\camera humanitas\\hyperspectralmicroscope\\PI_ScopeFoundry\\PIPython\\pipython\\pidevice\\gcs2\\gcs2commands.py", line 667, in qPOS\n    answer = self._msgs.read(cmdstr)\n', '  File "c:\\data\\python programs\\camera humanitas\\hyperspectralmicroscope\\PI_ScopeFoundry\\PIPython\\pipython\\pidevice\\gcsmessages.py", line 143, in read\n    self._checkerror()\n', '  File "c:\\data\\python programs\\camera humanitas\\hyperspectralmicroscope\\PI_ScopeFoundry\\PIPython\\pipython\\pidevice\\gcsmessages.py", line 302, in _checkerror\n    raise exc  # Raising NoneType while only classes or instances are allowed pylint: disable=E0702\n', 'PI_ScopeFoundry.PIPython.pipython.pidevice.gcserror.GCSError: Controller sent unexpected response (-1004)\n']
2025-02-25T16:44:12|ERROR|hyperMeasure|hyper Failed to update figure1: Controller sent unexpected response (-1004). ['Traceback (most recent call last):\n', '  File "C:\\ProgramData\\anaconda3\\envs\\scopefoundry\\lib\\site-packages\\ScopeFoundry\\measurement.py", line 362, in _on_display_update_timer\n    self.update_display()\n', '  File "c:\\data\\python programs\\camera humanitas\\hyperspectralmicroscope\\hyperspectral_measure.py", line 88, in update_display\n    self.stage.read_from_hardware()\n', '  File "C:\\ProgramData\\anaconda3\\envs\\scopefoundry\\lib\\site-packages\\ScopeFoundry\\hardware.py", line 188, in read_from_hardware\n    lq.read_from_hardware()\n', '  File "C:\\ProgramData\\anaconda3\\envs\\scopefoundry\\lib\\site-packages\\ScopeFoundry\\logged_quantity.py", line 203, in read_from_hardware\n    val = self.hardware_read_func()\n', '  File "c:\\data\\python programs\\camera humanitas\\hyperspectralmicroscope\\PI_ScopeFoundry\\PI_GCS_device.py", line 68, in get_position\n    position = self.pi_device.qPOS(self.axis)[self.axis]\n', '  File "c:\\data\\python programs\\camera humanitas\\hyperspectralmicroscope\\PI_ScopeFoundry\\PIPython\\pipython\\pidevice\\gcs2\\gcs2commands.py", line 667, in qPOS\n    answer = self._msgs.read(cmdstr)\n', '  File "c:\\data\\python programs\\camera humanitas\\hyperspectralmicroscope\\PI_ScopeFoundry\\PIPython\\pipython\\pidevice\\gcsmessages.py", line 143, in read\n    self._checkerror()\n', '  File "c:\\data\\python programs\\camera humanitas\\hyperspectralmicroscope\\PI_ScopeFoundry\\PIPython\\pipython\\pidevice\\gcsmessages.py", line 302, in _checkerror\n    raise exc  # Raising NoneType while only classes or instances are allowed pylint: disable=E0702\n', 'PI_ScopeFoundry.PIPython.pipython.pidevice.gcserror.GCSError: Controller sent unexpected response (-1004)\n']
2025-02-25T16:44:12|ERROR|hyperMeasure|hyper Failed to update figure1: Controller sent unexpected response (-1004). ['Traceback (most recent call last):\n', '  File "C:\\ProgramData\\anaconda3\\envs\\scopefoundry\\lib\\site-packages\\ScopeFoundry\\measurement.py", line 362, in _on_display_update_timer\n    self.update_display()\n', '  File "c:\\data\\python programs\\camera humanitas\\hyperspectralmicroscope\\hyperspectral_measure.py", line 88, in update_display\n    self.stage.read_from_hardware()\n', '  File "C:\\ProgramData\\anaconda3\\envs\\scopefoundry\\lib\\site-packages\\ScopeFoundry\\hardware.py", line 188, in read_from_hardware\n    lq.read_from_hardware()\n', '  File "C:\\ProgramData\\anaconda3\\envs\\scopefoundry\\lib\\site-packages\\ScopeFoundry\\logged_quantity.py", line 203, in read_from_hardware\n    val = self.hardware_read_func()\n', '  File "c:\\data\\python programs\\camera humanitas\\hyperspectralmicroscope\\PI_ScopeFoundry\\PI_GCS_device.py", line 68, in get_position\n    position = self.pi_device.qPOS(self.axis)[self.axis]\n', '  File "c:\\data\\python programs\\camera humanitas\\hyperspectralmicroscope\\PI_ScopeFoundry\\PIPython\\pipython\\pidevice\\gcs2\\gcs2commands.py", line 667, in qPOS\n    answer = self._msgs.read(cmdstr)\n', '  File "c:\\data\\python programs\\camera humanitas\\hyperspectralmicroscope\\PI_ScopeFoundry\\PIPython\\pipython\\pidevice\\gcsmessages.py", line 143, in read\n    self._checkerror()\n', '  File "c:\\data\\python programs\\camera humanitas\\hyperspectralmicroscope\\PI_ScopeFoundry\\PIPython\\pipython\\pidevice\\gcsmessages.py", line 302, in _checkerror\n    raise exc  # Raising NoneType while only classes or instances are allowed pylint: disable=E0702\n', 'PI_ScopeFoundry.PIPython.pipython.pidevice.gcserror.GCSError: Controller sent unexpected response (-1004)\n']
2025-02-25T16:44:12|ERROR|hyperMeasure|hyper Failed to update figure1: Controller sent unexpected response (-1004). ['Traceback (most recent call last):\n', '  File "C:\\ProgramData\\anaconda3\\envs\\scopefoundry\\lib\\site-packages\\ScopeFoundry\\measurement.py", line 362, in _on_display_update_timer\n    self.update_display()\n', '  File "c:\\data\\python programs\\camera humanitas\\hyperspectralmicroscope\\hyperspectral_measure.py", line 88, in update_display\n    self.stage.read_from_hardware()\n', '  File "C:\\ProgramData\\anaconda3\\envs\\scopefoundry\\lib\\site-packages\\ScopeFoundry\\hardware.py", line 188, in read_from_hardware\n    lq.read_from_hardware()\n', '  File "C:\\ProgramData\\anaconda3\\envs\\scopefoundry\\lib\\site-packages\\ScopeFoundry\\logged_quantity.py", line 203, in read_from_hardware\n    val = self.hardware_read_func()\n', '  File "c:\\data\\python programs\\camera humanitas\\hyperspectralmicroscope\\PI_ScopeFoundry\\PI_GCS_device.py", line 68, in get_position\n    position = self.pi_device.qPOS(self.axis)[self.axis]\n', '  File "c:\\data\\python programs\\camera humanitas\\hyperspectralmicroscope\\PI_ScopeFoundry\\PIPython\\pipython\\pidevice\\gcs2\\gcs2commands.py", line 667, in qPOS\n    answer = self._msgs.read(cmdstr)\n', '  File "c:\\data\\python programs\\camera humanitas\\hyperspectralmicroscope\\PI_ScopeFoundry\\PIPython\\pipython\\pidevice\\gcsmessages.py", line 143, in read\n    self._checkerror()\n', '  File "c:\\data\\python programs\\camera humanitas\\hyperspectralmicroscope\\PI_ScopeFoundry\\PIPython\\pipython\\pidevice\\gcsmessages.py", line 302, in _checkerror\n    raise exc  # Raising NoneType while only classes or instances are allowed pylint: disable=E0702\n', 'PI_ScopeFoundry.PIPython.pipython.pidevice.gcserror.GCSError: Controller sent unexpected response (-1004)\n']
2025-02-25T16:44:12|ERROR|hyperMeasure|hyper Failed to update figure1: Controller sent unexpected response (-1004). ['Traceback (most recent call last):\n', '  File "C:\\ProgramData\\anaconda3\\envs\\scopefoundry\\lib\\site-packages\\ScopeFoundry\\measurement.py", line 362, in _on_display_update_timer\n    self.update_display()\n', '  File "c:\\data\\python programs\\camera humanitas\\hyperspectralmicroscope\\hyperspectral_measure.py", line 88, in update_display\n    self.stage.read_from_hardware()\n', '  File "C:\\ProgramData\\anaconda3\\envs\\scopefoundry\\lib\\site-packages\\ScopeFoundry\\hardware.py", line 188, in read_from_hardware\n    lq.read_from_hardware()\n', '  File "C:\\ProgramData\\anaconda3\\envs\\scopefoundry\\lib\\site-packages\\ScopeFoundry\\logged_quantity.py", line 203, in read_from_hardware\n    val = self.hardware_read_func()\n', '  File "c:\\data\\python programs\\camera humanitas\\hyperspectralmicroscope\\PI_ScopeFoundry\\PI_GCS_device.py", line 68, in get_position\n    position = self.pi_device.qPOS(self.axis)[self.axis]\n', '  File "c:\\data\\python programs\\camera humanitas\\hyperspectralmicroscope\\PI_ScopeFoundry\\PIPython\\pipython\\pidevice\\gcs2\\gcs2commands.py", line 667, in qPOS\n    answer = self._msgs.read(cmdstr)\n', '  File "c:\\data\\python programs\\camera humanitas\\hyperspectralmicroscope\\PI_ScopeFoundry\\PIPython\\pipython\\pidevice\\gcsmessages.py", line 143, in read\n    self._checkerror()\n', '  File "c:\\data\\python programs\\camera humanitas\\hyperspectralmicroscope\\PI_ScopeFoundry\\PIPython\\pipython\\pidevice\\gcsmessages.py", line 302, in _checkerror\n    raise exc  # Raising NoneType while only classes or instances are allowed pylint: disable=E0702\n', 'PI_ScopeFoundry.PIPython.pipython.pidevice.gcserror.GCSError: Controller sent unexpected response (-1004)\n']
2025-02-25T16:44:13|ERROR|hyperMeasure|hyper Failed to update figure1: Controller sent unexpected response (-1004). ['Traceback (most recent call last):\n', '  File "C:\\ProgramData\\anaconda3\\envs\\scopefoundry\\lib\\site-packages\\ScopeFoundry\\measurement.py", line 362, in _on_display_update_timer\n    self.update_display()\n', '  File "c:\\data\\python programs\\camera humanitas\\hyperspectralmicroscope\\hyperspectral_measure.py", line 88, in update_display\n    self.stage.read_from_hardware()\n', '  File "C:\\ProgramData\\anaconda3\\envs\\scopefoundry\\lib\\site-packages\\ScopeFoundry\\hardware.py", line 188, in read_from_hardware\n    lq.read_from_hardware()\n', '  File "C:\\ProgramData\\anaconda3\\envs\\scopefoundry\\lib\\site-packages\\ScopeFoundry\\logged_quantity.py", line 203, in read_from_hardware\n    val = self.hardware_read_func()\n', '  File "c:\\data\\python programs\\camera humanitas\\hyperspectralmicroscope\\PI_ScopeFoundry\\PI_GCS_device.py", line 68, in get_position\n    position = self.pi_device.qPOS(self.axis)[self.axis]\n', '  File "c:\\data\\python programs\\camera humanitas\\hyperspectralmicroscope\\PI_ScopeFoundry\\PIPython\\pipython\\pidevice\\gcs2\\gcs2commands.py", line 667, in qPOS\n    answer = self._msgs.read(cmdstr)\n', '  File "c:\\data\\python programs\\camera humanitas\\hyperspectralmicroscope\\PI_ScopeFoundry\\PIPython\\pipython\\pidevice\\gcsmessages.py", line 143, in read\n    self._checkerror()\n', '  File "c:\\data\\python programs\\camera humanitas\\hyperspectralmicroscope\\PI_ScopeFoundry\\PIPython\\pipython\\pidevice\\gcsmessages.py", line 302, in _checkerror\n    raise exc  # Raising NoneType while only classes or instances are allowed pylint: disable=E0702\n', 'PI_ScopeFoundry.PIPython.pipython.pidevice.gcserror.GCSError: Controller sent unexpected response (-1004)\n']
2025-02-25T16:44:13|ERROR|hyperMeasure|hyper Failed to update figure1: Controller sent unexpected response (-1004). ['Traceback (most recent call last):\n', '  File "C:\\ProgramData\\anaconda3\\envs\\scopefoundry\\lib\\site-packages\\ScopeFoundry\\measurement.py", line 362, in _on_display_update_timer\n    self.update_display()\n', '  File "c:\\data\\python programs\\camera humanitas\\hyperspectralmicroscope\\hyperspectral_measure.py", line 88, in update_display\n    self.stage.read_from_hardware()\n', '  File "C:\\ProgramData\\anaconda3\\envs\\scopefoundry\\lib\\site-packages\\ScopeFoundry\\hardware.py", line 188, in read_from_hardware\n    lq.read_from_hardware()\n', '  File "C:\\ProgramData\\anaconda3\\envs\\scopefoundry\\lib\\site-packages\\ScopeFoundry\\logged_quantity.py", line 203, in read_from_hardware\n    val = self.hardware_read_func()\n', '  File "c:\\data\\python programs\\camera humanitas\\hyperspectralmicroscope\\PI_ScopeFoundry\\PI_GCS_device.py", line 68, in get_position\n    position = self.pi_device.qPOS(self.axis)[self.axis]\n', '  File "c:\\data\\python programs\\camera humanitas\\hyperspectralmicroscope\\PI_ScopeFoundry\\PIPython\\pipython\\pidevice\\gcs2\\gcs2commands.py", line 667, in qPOS\n    answer = self._msgs.read(cmdstr)\n', '  File "c:\\data\\python programs\\camera humanitas\\hyperspectralmicroscope\\PI_ScopeFoundry\\PIPython\\pipython\\pidevice\\gcsmessages.py", line 143, in read\n    self._checkerror()\n', '  File "c:\\data\\python programs\\camera humanitas\\hyperspectralmicroscope\\PI_ScopeFoundry\\PIPython\\pipython\\pidevice\\gcsmessages.py", line 302, in _checkerror\n    raise exc  # Raising NoneType while only classes or instances are allowed pylint: disable=E0702\n', 'PI_ScopeFoundry.PIPython.pipython.pidevice.gcserror.GCSError: Controller sent unexpected response (-1004)\n']
2025-02-25T16:44:13|ERROR|hyperMeasure|hyper Failed to update figure1: Controller sent unexpected response (-1004). ['Traceback (most recent call last):\n', '  File "C:\\ProgramData\\anaconda3\\envs\\scopefoundry\\lib\\site-packages\\ScopeFoundry\\measurement.py", line 362, in _on_display_update_timer\n    self.update_display()\n', '  File "c:\\data\\python programs\\camera humanitas\\hyperspectralmicroscope\\hyperspectral_measure.py", line 88, in update_display\n    self.stage.read_from_hardware()\n', '  File "C:\\ProgramData\\anaconda3\\envs\\scopefoundry\\lib\\site-packages\\ScopeFoundry\\hardware.py", line 188, in read_from_hardware\n    lq.read_from_hardware()\n', '  File "C:\\ProgramData\\anaconda3\\envs\\scopefoundry\\lib\\site-packages\\ScopeFoundry\\logged_quantity.py", line 203, in read_from_hardware\n    val = self.hardware_read_func()\n', '  File "c:\\data\\python programs\\camera humanitas\\hyperspectralmicroscope\\PI_ScopeFoundry\\PI_GCS_device.py", line 68, in get_position\n    position = self.pi_device.qPOS(self.axis)[self.axis]\n', '  File "c:\\data\\python programs\\camera humanitas\\hyperspectralmicroscope\\PI_ScopeFoundry\\PIPython\\pipython\\pidevice\\gcs2\\gcs2commands.py", line 667, in qPOS\n    answer = self._msgs.read(cmdstr)\n', '  File "c:\\data\\python programs\\camera humanitas\\hyperspectralmicroscope\\PI_ScopeFoundry\\PIPython\\pipython\\pidevice\\gcsmessages.py", line 143, in read\n    self._checkerror()\n', '  File "c:\\data\\python programs\\camera humanitas\\hyperspectralmicroscope\\PI_ScopeFoundry\\PIPython\\pipython\\pidevice\\gcsmessages.py", line 302, in _checkerror\n    raise exc  # Raising NoneType while only classes or instances are allowed pylint: disable=E0702\n', 'PI_ScopeFoundry.PIPython.pipython.pidevice.gcserror.GCSError: Controller sent unexpected response (-1004)\n']
2025-02-25T16:44:15|CRITICAL|root|Unhandled exception:Traceback (most recent call last):
  File "C:\ProgramData\anaconda3\envs\scopefoundry\lib\site-packages\ScopeFoundry\measurement.py", line 27, in run
    self.measurement._thread_run()
  File "C:\ProgramData\anaconda3\envs\scopefoundry\lib\site-packages\ScopeFoundry\measurement.py", line 230, in _thread_run
    self.run()
  File "c:\data\python programs\camera humanitas\hyperspectralmicroscope\hyperspectral_measure.py", line 179, in run
    [frame, dims] = self.image_gen.hamamatsu.getLastFrame()
  File "c:\data\python programs\camera humanitas\hyperspectralmicroscope\Hamamatsu_ScopeFoundry\CameraDevice.py", line 1218, in getLastFrame
    hc_data.copyData(paramlock.buf)
  File "c:\data\python programs\camera humanitas\hyperspectralmicroscope\Hamamatsu_ScopeFoundry\CameraDevice.py", line 311, in copyData
    ctypes.memmove(self.np_array.ctypes.data, address, self.size) #copies self.size bytes from address into self.np_array.ctyps.data
OSError: exception: access violation reading 0x0000000000000000

