2025-02-19T17:41:54|ERROR|hyperMeasure|hyper Failed to update figure1: 'HamamatsuHardware' object has no attribute 'frame_num'. ['Traceback (most recent call last):\n', '  File "C:\\ProgramData\\anaconda3\\envs\\scopefoundry\\lib\\site-packages\\ScopeFoundry\\measurement.py", line 362, in _on_display_update_timer\n    self.update_display()\n', '  File "c:\\data\\python programs\\camera humanitas\\hyperspectralmicroscope\\hyperspectral_measure.py", line 93, in update_display\n    length = self.image_gen.frame_num.val\n', "AttributeError: 'HamamatsuHardware' object has no attribute 'frame_num'\n"]
2025-02-19T17:41:54|ERROR|hyperMeasure|hyper Failed to update figure1: 'HamamatsuHardware' object has no attribute 'frame_num'. ['Traceback (most recent call last):\n', '  File "C:\\ProgramData\\anaconda3\\envs\\scopefoundry\\lib\\site-packages\\ScopeFoundry\\measurement.py", line 362, in _on_display_update_timer\n    self.update_display()\n', '  File "c:\\data\\python programs\\camera humanitas\\hyperspectralmicroscope\\hyperspectral_measure.py", line 93, in update_display\n    length = self.image_gen.frame_num.val\n', "AttributeError: 'HamamatsuHardware' object has no attribute 'frame_num'\n"]
2025-02-19T17:41:54|ERROR|hyperMeasure|hyper Failed to update figure1: 'HamamatsuHardware' object has no attribute 'frame_num'. ['Traceback (most recent call last):\n', '  File "C:\\ProgramData\\anaconda3\\envs\\scopefoundry\\lib\\site-packages\\ScopeFoundry\\measurement.py", line 362, in _on_display_update_timer\n    self.update_display()\n', '  File "c:\\data\\python programs\\camera humanitas\\hyperspectralmicroscope\\hyperspectral_measure.py", line 93, in update_display\n    length = self.image_gen.frame_num.val\n', "AttributeError: 'HamamatsuHardware' object has no attribute 'frame_num'\n"]
2025-02-19T17:41:54|ERROR|hyperMeasure|hyper Failed to update figure1: 'HamamatsuHardware' object has no attribute 'frame_num'. ['Traceback (most recent call last):\n', '  File "C:\\ProgramData\\anaconda3\\envs\\scopefoundry\\lib\\site-packages\\ScopeFoundry\\measurement.py", line 362, in _on_display_update_timer\n    self.update_display()\n', '  File "c:\\data\\python programs\\camera humanitas\\hyperspectralmicroscope\\hyperspectral_measure.py", line 93, in update_display\n    length = self.image_gen.frame_num.val\n', "AttributeError: 'HamamatsuHardware' object has no attribute 'frame_num'\n"]
2025-02-19T17:41:54|ERROR|hyperMeasure|hyper Failed to update figure1: 'HamamatsuHardware' object has no attribute 'frame_num'. ['Traceback (most recent call last):\n', '  File "C:\\ProgramData\\anaconda3\\envs\\scopefoundry\\lib\\site-packages\\ScopeFoundry\\measurement.py", line 362, in _on_display_update_timer\n    self.update_display()\n', '  File "c:\\data\\python programs\\camera humanitas\\hyperspectralmicroscope\\hyperspectral_measure.py", line 93, in update_display\n    length = self.image_gen.frame_num.val\n', "AttributeError: 'HamamatsuHardware' object has no attribute 'frame_num'\n"]
2025-02-19T17:41:54|ERROR|hyperMeasure|hyper Failed to update figure1: 'HamamatsuHardware' object has no attribute 'frame_num'. ['Traceback (most recent call last):\n', '  File "C:\\ProgramData\\anaconda3\\envs\\scopefoundry\\lib\\site-packages\\ScopeFoundry\\measurement.py", line 362, in _on_display_update_timer\n    self.update_display()\n', '  File "c:\\data\\python programs\\camera humanitas\\hyperspectralmicroscope\\hyperspectral_measure.py", line 93, in update_display\n    length = self.image_gen.frame_num.val\n', "AttributeError: 'HamamatsuHardware' object has no attribute 'frame_num'\n"]
2025-02-19T17:41:54|ERROR|hyperMeasure|hyper Failed to update figure1: 'HamamatsuHardware' object has no attribute 'frame_num'. ['Traceback (most recent call last):\n', '  File "C:\\ProgramData\\anaconda3\\envs\\scopefoundry\\lib\\site-packages\\ScopeFoundry\\measurement.py", line 362, in _on_display_update_timer\n    self.update_display()\n', '  File "c:\\data\\python programs\\camera humanitas\\hyperspectralmicroscope\\hyperspectral_measure.py", line 93, in update_display\n    length = self.image_gen.frame_num.val\n', "AttributeError: 'HamamatsuHardware' object has no attribute 'frame_num'\n"]
2025-02-19T17:41:55|ERROR|hyperMeasure|hyper Failed to update figure1: 'HamamatsuHardware' object has no attribute 'frame_num'. ['Traceback (most recent call last):\n', '  File "C:\\ProgramData\\anaconda3\\envs\\scopefoundry\\lib\\site-packages\\ScopeFoundry\\measurement.py", line 362, in _on_display_update_timer\n    self.update_display()\n', '  File "c:\\data\\python programs\\camera humanitas\\hyperspectralmicroscope\\hyperspectral_measure.py", line 93, in update_display\n    length = self.image_gen.frame_num.val\n', "AttributeError: 'HamamatsuHardware' object has no attribute 'frame_num'\n"]
2025-02-19T17:41:55|ERROR|hyperMeasure|hyper Failed to update figure1: 'HamamatsuHardware' object has no attribute 'frame_num'. ['Traceback (most recent call last):\n', '  File "C:\\ProgramData\\anaconda3\\envs\\scopefoundry\\lib\\site-packages\\ScopeFoundry\\measurement.py", line 362, in _on_display_update_timer\n    self.update_display()\n', '  File "c:\\data\\python programs\\camera humanitas\\hyperspectralmicroscope\\hyperspectral_measure.py", line 93, in update_display\n    length = self.image_gen.frame_num.val\n', "AttributeError: 'HamamatsuHardware' object has no attribute 'frame_num'\n"]
2025-02-19T17:41:55|ERROR|hyperMeasure|hyper Failed to update figure1: 'HamamatsuHardware' object has no attribute 'frame_num'. ['Traceback (most recent call last):\n', '  File "C:\\ProgramData\\anaconda3\\envs\\scopefoundry\\lib\\site-packages\\ScopeFoundry\\measurement.py", line 362, in _on_display_update_timer\n    self.update_display()\n', '  File "c:\\data\\python programs\\camera humanitas\\hyperspectralmicroscope\\hyperspectral_measure.py", line 93, in update_display\n    length = self.image_gen.frame_num.val\n', "AttributeError: 'HamamatsuHardware' object has no attribute 'frame_num'\n"]
2025-02-19T17:41:55|ERROR|hyperMeasure|hyper Failed to update figure1: 'HamamatsuHardware' object has no attribute 'frame_num'. ['Traceback (most recent call last):\n', '  File "C:\\ProgramData\\anaconda3\\envs\\scopefoundry\\lib\\site-packages\\ScopeFoundry\\measurement.py", line 362, in _on_display_update_timer\n    self.update_display()\n', '  File "c:\\data\\python programs\\camera humanitas\\hyperspectralmicroscope\\hyperspectral_measure.py", line 93, in update_display\n    length = self.image_gen.frame_num.val\n', "AttributeError: 'HamamatsuHardware' object has no attribute 'frame_num'\n"]
2025-02-19T17:41:55|ERROR|hyperMeasure|hyper Failed to update figure1: 'HamamatsuHardware' object has no attribute 'frame_num'. ['Traceback (most recent call last):\n', '  File "C:\\ProgramData\\anaconda3\\envs\\scopefoundry\\lib\\site-packages\\ScopeFoundry\\measurement.py", line 362, in _on_display_update_timer\n    self.update_display()\n', '  File "c:\\data\\python programs\\camera humanitas\\hyperspectralmicroscope\\hyperspectral_measure.py", line 93, in update_display\n    length = self.image_gen.frame_num.val\n', "AttributeError: 'HamamatsuHardware' object has no attribute 'frame_num'\n"]
2025-02-19T17:41:55|ERROR|hyperMeasure|hyper Failed to update figure1: 'HamamatsuHardware' object has no attribute 'frame_num'. ['Traceback (most recent call last):\n', '  File "C:\\ProgramData\\anaconda3\\envs\\scopefoundry\\lib\\site-packages\\ScopeFoundry\\measurement.py", line 362, in _on_display_update_timer\n    self.update_display()\n', '  File "c:\\data\\python programs\\camera humanitas\\hyperspectralmicroscope\\hyperspectral_measure.py", line 93, in update_display\n    length = self.image_gen.frame_num.val\n', "AttributeError: 'HamamatsuHardware' object has no attribute 'frame_num'\n"]
2025-02-19T17:41:55|ERROR|hyperMeasure|hyper Failed to update figure1: 'HamamatsuHardware' object has no attribute 'frame_num'. ['Traceback (most recent call last):\n', '  File "C:\\ProgramData\\anaconda3\\envs\\scopefoundry\\lib\\site-packages\\ScopeFoundry\\measurement.py", line 362, in _on_display_update_timer\n    self.update_display()\n', '  File "c:\\data\\python programs\\camera humanitas\\hyperspectralmicroscope\\hyperspectral_measure.py", line 93, in update_display\n    length = self.image_gen.frame_num.val\n', "AttributeError: 'HamamatsuHardware' object has no attribute 'frame_num'\n"]
2025-02-19T17:41:55|ERROR|hyperMeasure|hyper Failed to update figure1: 'HamamatsuHardware' object has no attribute 'frame_num'. ['Traceback (most recent call last):\n', '  File "C:\\ProgramData\\anaconda3\\envs\\scopefoundry\\lib\\site-packages\\ScopeFoundry\\measurement.py", line 362, in _on_display_update_timer\n    self.update_display()\n', '  File "c:\\data\\python programs\\camera humanitas\\hyperspectralmicroscope\\hyperspectral_measure.py", line 93, in update_display\n    length = self.image_gen.frame_num.val\n', "AttributeError: 'HamamatsuHardware' object has no attribute 'frame_num'\n"]
2025-02-19T17:41:55|ERROR|hyperMeasure|hyper Failed to update figure1: 'HamamatsuHardware' object has no attribute 'frame_num'. ['Traceback (most recent call last):\n', '  File "C:\\ProgramData\\anaconda3\\envs\\scopefoundry\\lib\\site-packages\\ScopeFoundry\\measurement.py", line 362, in _on_display_update_timer\n    self.update_display()\n', '  File "c:\\data\\python programs\\camera humanitas\\hyperspectralmicroscope\\hyperspectral_measure.py", line 93, in update_display\n    length = self.image_gen.frame_num.val\n', "AttributeError: 'HamamatsuHardware' object has no attribute 'frame_num'\n"]
2025-02-19T17:41:56|ERROR|hyperMeasure|hyper Failed to update figure1: 'HamamatsuHardware' object has no attribute 'frame_num'. ['Traceback (most recent call last):\n', '  File "C:\\ProgramData\\anaconda3\\envs\\scopefoundry\\lib\\site-packages\\ScopeFoundry\\measurement.py", line 362, in _on_display_update_timer\n    self.update_display()\n', '  File "c:\\data\\python programs\\camera humanitas\\hyperspectralmicroscope\\hyperspectral_measure.py", line 93, in update_display\n    length = self.image_gen.frame_num.val\n', "AttributeError: 'HamamatsuHardware' object has no attribute 'frame_num'\n"]
2025-02-19T17:41:56|ERROR|hyperMeasure|hyper Failed to update figure1: 'HamamatsuHardware' object has no attribute 'frame_num'. ['Traceback (most recent call last):\n', '  File "C:\\ProgramData\\anaconda3\\envs\\scopefoundry\\lib\\site-packages\\ScopeFoundry\\measurement.py", line 362, in _on_display_update_timer\n    self.update_display()\n', '  File "c:\\data\\python programs\\camera humanitas\\hyperspectralmicroscope\\hyperspectral_measure.py", line 93, in update_display\n    length = self.image_gen.frame_num.val\n', "AttributeError: 'HamamatsuHardware' object has no attribute 'frame_num'\n"]
2025-02-19T17:41:56|ERROR|hyperMeasure|hyper Failed to update figure1: 'HamamatsuHardware' object has no attribute 'frame_num'. ['Traceback (most recent call last):\n', '  File "C:\\ProgramData\\anaconda3\\envs\\scopefoundry\\lib\\site-packages\\ScopeFoundry\\measurement.py", line 362, in _on_display_update_timer\n    self.update_display()\n', '  File "c:\\data\\python programs\\camera humanitas\\hyperspectralmicroscope\\hyperspectral_measure.py", line 93, in update_display\n    length = self.image_gen.frame_num.val\n', "AttributeError: 'HamamatsuHardware' object has no attribute 'frame_num'\n"]
2025-02-19T17:41:56|ERROR|hyperMeasure|hyper Failed to update figure1: 'HamamatsuHardware' object has no attribute 'frame_num'. ['Traceback (most recent call last):\n', '  File "C:\\ProgramData\\anaconda3\\envs\\scopefoundry\\lib\\site-packages\\ScopeFoundry\\measurement.py", line 362, in _on_display_update_timer\n    self.update_display()\n', '  File "c:\\data\\python programs\\camera humanitas\\hyperspectralmicroscope\\hyperspectral_measure.py", line 93, in update_display\n    length = self.image_gen.frame_num.val\n', "AttributeError: 'HamamatsuHardware' object has no attribute 'frame_num'\n"]
2025-02-19T17:41:56|ERROR|hyperMeasure|hyper Failed to update figure1: 'HamamatsuHardware' object has no attribute 'frame_num'. ['Traceback (most recent call last):\n', '  File "C:\\ProgramData\\anaconda3\\envs\\scopefoundry\\lib\\site-packages\\ScopeFoundry\\measurement.py", line 362, in _on_display_update_timer\n    self.update_display()\n', '  File "c:\\data\\python programs\\camera humanitas\\hyperspectralmicroscope\\hyperspectral_measure.py", line 93, in update_display\n    length = self.image_gen.frame_num.val\n', "AttributeError: 'HamamatsuHardware' object has no attribute 'frame_num'\n"]
2025-02-19T17:41:56|ERROR|hyperMeasure|hyper Failed to update figure1: 'HamamatsuHardware' object has no attribute 'frame_num'. ['Traceback (most recent call last):\n', '  File "C:\\ProgramData\\anaconda3\\envs\\scopefoundry\\lib\\site-packages\\ScopeFoundry\\measurement.py", line 362, in _on_display_update_timer\n    self.update_display()\n', '  File "c:\\data\\python programs\\camera humanitas\\hyperspectralmicroscope\\hyperspectral_measure.py", line 93, in update_display\n    length = self.image_gen.frame_num.val\n', "AttributeError: 'HamamatsuHardware' object has no attribute 'frame_num'\n"]
2025-02-19T17:41:56|ERROR|hyperMeasure|hyper Failed to update figure1: 'HamamatsuHardware' object has no attribute 'frame_num'. ['Traceback (most recent call last):\n', '  File "C:\\ProgramData\\anaconda3\\envs\\scopefoundry\\lib\\site-packages\\ScopeFoundry\\measurement.py", line 362, in _on_display_update_timer\n    self.update_display()\n', '  File "c:\\data\\python programs\\camera humanitas\\hyperspectralmicroscope\\hyperspectral_measure.py", line 93, in update_display\n    length = self.image_gen.frame_num.val\n', "AttributeError: 'HamamatsuHardware' object has no attribute 'frame_num'\n"]
2025-02-19T17:41:56|ERROR|hyperMeasure|hyper Failed to update figure1: 'HamamatsuHardware' object has no attribute 'frame_num'. ['Traceback (most recent call last):\n', '  File "C:\\ProgramData\\anaconda3\\envs\\scopefoundry\\lib\\site-packages\\ScopeFoundry\\measurement.py", line 362, in _on_display_update_timer\n    self.update_display()\n', '  File "c:\\data\\python programs\\camera humanitas\\hyperspectralmicroscope\\hyperspectral_measure.py", line 93, in update_display\n    length = self.image_gen.frame_num.val\n', "AttributeError: 'HamamatsuHardware' object has no attribute 'frame_num'\n"]
2025-02-19T17:41:56|ERROR|hyperMeasure|hyper Failed to update figure1: 'HamamatsuHardware' object has no attribute 'frame_num'. ['Traceback (most recent call last):\n', '  File "C:\\ProgramData\\anaconda3\\envs\\scopefoundry\\lib\\site-packages\\ScopeFoundry\\measurement.py", line 362, in _on_display_update_timer\n    self.update_display()\n', '  File "c:\\data\\python programs\\camera humanitas\\hyperspectralmicroscope\\hyperspectral_measure.py", line 93, in update_display\n    length = self.image_gen.frame_num.val\n', "AttributeError: 'HamamatsuHardware' object has no attribute 'frame_num'\n"]
2025-02-19T17:41:57|ERROR|hyperMeasure|hyper Failed to update figure1: 'HamamatsuHardware' object has no attribute 'frame_num'. ['Traceback (most recent call last):\n', '  File "C:\\ProgramData\\anaconda3\\envs\\scopefoundry\\lib\\site-packages\\ScopeFoundry\\measurement.py", line 362, in _on_display_update_timer\n    self.update_display()\n', '  File "c:\\data\\python programs\\camera humanitas\\hyperspectralmicroscope\\hyperspectral_measure.py", line 93, in update_display\n    length = self.image_gen.frame_num.val\n', "AttributeError: 'HamamatsuHardware' object has no attribute 'frame_num'\n"]
2025-02-19T17:41:57|ERROR|hyperMeasure|hyper Failed to update figure1: 'HamamatsuHardware' object has no attribute 'frame_num'. ['Traceback (most recent call last):\n', '  File "C:\\ProgramData\\anaconda3\\envs\\scopefoundry\\lib\\site-packages\\ScopeFoundry\\measurement.py", line 362, in _on_display_update_timer\n    self.update_display()\n', '  File "c:\\data\\python programs\\camera humanitas\\hyperspectralmicroscope\\hyperspectral_measure.py", line 93, in update_display\n    length = self.image_gen.frame_num.val\n', "AttributeError: 'HamamatsuHardware' object has no attribute 'frame_num'\n"]
2025-02-19T17:41:57|ERROR|hyperMeasure|hyper Failed to update figure1: 'HamamatsuHardware' object has no attribute 'frame_num'. ['Traceback (most recent call last):\n', '  File "C:\\ProgramData\\anaconda3\\envs\\scopefoundry\\lib\\site-packages\\ScopeFoundry\\measurement.py", line 362, in _on_display_update_timer\n    self.update_display()\n', '  File "c:\\data\\python programs\\camera humanitas\\hyperspectralmicroscope\\hyperspectral_measure.py", line 93, in update_display\n    length = self.image_gen.frame_num.val\n', "AttributeError: 'HamamatsuHardware' object has no attribute 'frame_num'\n"]
2025-02-19T17:41:57|ERROR|hyperMeasure|hyper Failed to update figure1: 'HamamatsuHardware' object has no attribute 'frame_num'. ['Traceback (most recent call last):\n', '  File "C:\\ProgramData\\anaconda3\\envs\\scopefoundry\\lib\\site-packages\\ScopeFoundry\\measurement.py", line 362, in _on_display_update_timer\n    self.update_display()\n', '  File "c:\\data\\python programs\\camera humanitas\\hyperspectralmicroscope\\hyperspectral_measure.py", line 93, in update_display\n    length = self.image_gen.frame_num.val\n', "AttributeError: 'HamamatsuHardware' object has no attribute 'frame_num'\n"]
2025-02-19T17:41:57|ERROR|hyperMeasure|hyper Failed to update figure1: 'HamamatsuHardware' object has no attribute 'frame_num'. ['Traceback (most recent call last):\n', '  File "C:\\ProgramData\\anaconda3\\envs\\scopefoundry\\lib\\site-packages\\ScopeFoundry\\measurement.py", line 362, in _on_display_update_timer\n    self.update_display()\n', '  File "c:\\data\\python programs\\camera humanitas\\hyperspectralmicroscope\\hyperspectral_measure.py", line 93, in update_display\n    length = self.image_gen.frame_num.val\n', "AttributeError: 'HamamatsuHardware' object has no attribute 'frame_num'\n"]
2025-02-19T17:41:57|ERROR|hyperMeasure|hyper Failed to update figure1: 'HamamatsuHardware' object has no attribute 'frame_num'. ['Traceback (most recent call last):\n', '  File "C:\\ProgramData\\anaconda3\\envs\\scopefoundry\\lib\\site-packages\\ScopeFoundry\\measurement.py", line 362, in _on_display_update_timer\n    self.update_display()\n', '  File "c:\\data\\python programs\\camera humanitas\\hyperspectralmicroscope\\hyperspectral_measure.py", line 93, in update_display\n    length = self.image_gen.frame_num.val\n', "AttributeError: 'HamamatsuHardware' object has no attribute 'frame_num'\n"]
2025-02-19T17:41:57|ERROR|hyperMeasure|hyper Failed to update figure1: 'HamamatsuHardware' object has no attribute 'frame_num'. ['Traceback (most recent call last):\n', '  File "C:\\ProgramData\\anaconda3\\envs\\scopefoundry\\lib\\site-packages\\ScopeFoundry\\measurement.py", line 362, in _on_display_update_timer\n    self.update_display()\n', '  File "c:\\data\\python programs\\camera humanitas\\hyperspectralmicroscope\\hyperspectral_measure.py", line 93, in update_display\n    length = self.image_gen.frame_num.val\n', "AttributeError: 'HamamatsuHardware' object has no attribute 'frame_num'\n"]
2025-02-19T17:41:57|ERROR|hyperMeasure|hyper Failed to update figure1: 'HamamatsuHardware' object has no attribute 'frame_num'. ['Traceback (most recent call last):\n', '  File "C:\\ProgramData\\anaconda3\\envs\\scopefoundry\\lib\\site-packages\\ScopeFoundry\\measurement.py", line 362, in _on_display_update_timer\n    self.update_display()\n', '  File "c:\\data\\python programs\\camera humanitas\\hyperspectralmicroscope\\hyperspectral_measure.py", line 93, in update_display\n    length = self.image_gen.frame_num.val\n', "AttributeError: 'HamamatsuHardware' object has no attribute 'frame_num'\n"]
2025-02-19T17:41:57|ERROR|hyperMeasure|hyper Failed to update figure1: 'HamamatsuHardware' object has no attribute 'frame_num'. ['Traceback (most recent call last):\n', '  File "C:\\ProgramData\\anaconda3\\envs\\scopefoundry\\lib\\site-packages\\ScopeFoundry\\measurement.py", line 362, in _on_display_update_timer\n    self.update_display()\n', '  File "c:\\data\\python programs\\camera humanitas\\hyperspectralmicroscope\\hyperspectral_measure.py", line 93, in update_display\n    length = self.image_gen.frame_num.val\n', "AttributeError: 'HamamatsuHardware' object has no attribute 'frame_num'\n"]
2025-02-19T17:41:58|ERROR|hyperMeasure|hyper Failed to update figure1: 'HamamatsuHardware' object has no attribute 'frame_num'. ['Traceback (most recent call last):\n', '  File "C:\\ProgramData\\anaconda3\\envs\\scopefoundry\\lib\\site-packages\\ScopeFoundry\\measurement.py", line 362, in _on_display_update_timer\n    self.update_display()\n', '  File "c:\\data\\python programs\\camera humanitas\\hyperspectralmicroscope\\hyperspectral_measure.py", line 93, in update_display\n    length = self.image_gen.frame_num.val\n', "AttributeError: 'HamamatsuHardware' object has no attribute 'frame_num'\n"]
2025-02-19T17:41:58|ERROR|hyperMeasure|hyper Failed to update figure1: 'HamamatsuHardware' object has no attribute 'frame_num'. ['Traceback (most recent call last):\n', '  File "C:\\ProgramData\\anaconda3\\envs\\scopefoundry\\lib\\site-packages\\ScopeFoundry\\measurement.py", line 362, in _on_display_update_timer\n    self.update_display()\n', '  File "c:\\data\\python programs\\camera humanitas\\hyperspectralmicroscope\\hyperspectral_measure.py", line 93, in update_display\n    length = self.image_gen.frame_num.val\n', "AttributeError: 'HamamatsuHardware' object has no attribute 'frame_num'\n"]
2025-02-19T17:41:58|ERROR|hyperMeasure|hyper Failed to update figure1: 'HamamatsuHardware' object has no attribute 'frame_num'. ['Traceback (most recent call last):\n', '  File "C:\\ProgramData\\anaconda3\\envs\\scopefoundry\\lib\\site-packages\\ScopeFoundry\\measurement.py", line 362, in _on_display_update_timer\n    self.update_display()\n', '  File "c:\\data\\python programs\\camera humanitas\\hyperspectralmicroscope\\hyperspectral_measure.py", line 93, in update_display\n    length = self.image_gen.frame_num.val\n', "AttributeError: 'HamamatsuHardware' object has no attribute 'frame_num'\n"]
2025-02-19T17:41:58|ERROR|hyperMeasure|hyper Failed to update figure1: 'HamamatsuHardware' object has no attribute 'frame_num'. ['Traceback (most recent call last):\n', '  File "C:\\ProgramData\\anaconda3\\envs\\scopefoundry\\lib\\site-packages\\ScopeFoundry\\measurement.py", line 362, in _on_display_update_timer\n    self.update_display()\n', '  File "c:\\data\\python programs\\camera humanitas\\hyperspectralmicroscope\\hyperspectral_measure.py", line 93, in update_display\n    length = self.image_gen.frame_num.val\n', "AttributeError: 'HamamatsuHardware' object has no attribute 'frame_num'\n"]
2025-02-19T17:41:58|ERROR|hyperMeasure|hyper Failed to update figure1: 'HamamatsuHardware' object has no attribute 'frame_num'. ['Traceback (most recent call last):\n', '  File "C:\\ProgramData\\anaconda3\\envs\\scopefoundry\\lib\\site-packages\\ScopeFoundry\\measurement.py", line 362, in _on_display_update_timer\n    self.update_display()\n', '  File "c:\\data\\python programs\\camera humanitas\\hyperspectralmicroscope\\hyperspectral_measure.py", line 93, in update_display\n    length = self.image_gen.frame_num.val\n', "AttributeError: 'HamamatsuHardware' object has no attribute 'frame_num'\n"]
2025-02-19T17:41:58|ERROR|hyperMeasure|hyper Failed to update figure1: 'HamamatsuHardware' object has no attribute 'frame_num'. ['Traceback (most recent call last):\n', '  File "C:\\ProgramData\\anaconda3\\envs\\scopefoundry\\lib\\site-packages\\ScopeFoundry\\measurement.py", line 362, in _on_display_update_timer\n    self.update_display()\n', '  File "c:\\data\\python programs\\camera humanitas\\hyperspectralmicroscope\\hyperspectral_measure.py", line 93, in update_display\n    length = self.image_gen.frame_num.val\n', "AttributeError: 'HamamatsuHardware' object has no attribute 'frame_num'\n"]
2025-02-19T17:41:58|ERROR|hyperMeasure|hyper Failed to update figure1: 'HamamatsuHardware' object has no attribute 'frame_num'. ['Traceback (most recent call last):\n', '  File "C:\\ProgramData\\anaconda3\\envs\\scopefoundry\\lib\\site-packages\\ScopeFoundry\\measurement.py", line 362, in _on_display_update_timer\n    self.update_display()\n', '  File "c:\\data\\python programs\\camera humanitas\\hyperspectralmicroscope\\hyperspectral_measure.py", line 93, in update_display\n    length = self.image_gen.frame_num.val\n', "AttributeError: 'HamamatsuHardware' object has no attribute 'frame_num'\n"]
2025-02-19T17:41:58|ERROR|hyperMeasure|hyper Failed to update figure1: 'HamamatsuHardware' object has no attribute 'frame_num'. ['Traceback (most recent call last):\n', '  File "C:\\ProgramData\\anaconda3\\envs\\scopefoundry\\lib\\site-packages\\ScopeFoundry\\measurement.py", line 362, in _on_display_update_timer\n    self.update_display()\n', '  File "c:\\data\\python programs\\camera humanitas\\hyperspectralmicroscope\\hyperspectral_measure.py", line 93, in update_display\n    length = self.image_gen.frame_num.val\n', "AttributeError: 'HamamatsuHardware' object has no attribute 'frame_num'\n"]
2025-02-19T17:41:58|ERROR|hyperMeasure|hyper Failed to update figure1: 'HamamatsuHardware' object has no attribute 'frame_num'. ['Traceback (most recent call last):\n', '  File "C:\\ProgramData\\anaconda3\\envs\\scopefoundry\\lib\\site-packages\\ScopeFoundry\\measurement.py", line 362, in _on_display_update_timer\n    self.update_display()\n', '  File "c:\\data\\python programs\\camera humanitas\\hyperspectralmicroscope\\hyperspectral_measure.py", line 93, in update_display\n    length = self.image_gen.frame_num.val\n', "AttributeError: 'HamamatsuHardware' object has no attribute 'frame_num'\n"]
2025-02-19T17:41:59|ERROR|hyperMeasure|hyper Failed to update figure1: 'HamamatsuHardware' object has no attribute 'frame_num'. ['Traceback (most recent call last):\n', '  File "C:\\ProgramData\\anaconda3\\envs\\scopefoundry\\lib\\site-packages\\ScopeFoundry\\measurement.py", line 362, in _on_display_update_timer\n    self.update_display()\n', '  File "c:\\data\\python programs\\camera humanitas\\hyperspectralmicroscope\\hyperspectral_measure.py", line 93, in update_display\n    length = self.image_gen.frame_num.val\n', "AttributeError: 'HamamatsuHardware' object has no attribute 'frame_num'\n"]
2025-02-19T17:41:59|ERROR|hyperMeasure|hyper Failed to update figure1: 'HamamatsuHardware' object has no attribute 'frame_num'. ['Traceback (most recent call last):\n', '  File "C:\\ProgramData\\anaconda3\\envs\\scopefoundry\\lib\\site-packages\\ScopeFoundry\\measurement.py", line 362, in _on_display_update_timer\n    self.update_display()\n', '  File "c:\\data\\python programs\\camera humanitas\\hyperspectralmicroscope\\hyperspectral_measure.py", line 93, in update_display\n    length = self.image_gen.frame_num.val\n', "AttributeError: 'HamamatsuHardware' object has no attribute 'frame_num'\n"]
2025-02-19T17:41:59|ERROR|hyperMeasure|hyper Failed to update figure1: 'HamamatsuHardware' object has no attribute 'frame_num'. ['Traceback (most recent call last):\n', '  File "C:\\ProgramData\\anaconda3\\envs\\scopefoundry\\lib\\site-packages\\ScopeFoundry\\measurement.py", line 362, in _on_display_update_timer\n    self.update_display()\n', '  File "c:\\data\\python programs\\camera humanitas\\hyperspectralmicroscope\\hyperspectral_measure.py", line 93, in update_display\n    length = self.image_gen.frame_num.val\n', "AttributeError: 'HamamatsuHardware' object has no attribute 'frame_num'\n"]
2025-02-19T17:41:59|ERROR|hyperMeasure|hyper Failed to update figure1: 'HamamatsuHardware' object has no attribute 'frame_num'. ['Traceback (most recent call last):\n', '  File "C:\\ProgramData\\anaconda3\\envs\\scopefoundry\\lib\\site-packages\\ScopeFoundry\\measurement.py", line 362, in _on_display_update_timer\n    self.update_display()\n', '  File "c:\\data\\python programs\\camera humanitas\\hyperspectralmicroscope\\hyperspectral_measure.py", line 93, in update_display\n    length = self.image_gen.frame_num.val\n', "AttributeError: 'HamamatsuHardware' object has no attribute 'frame_num'\n"]
2025-02-19T17:41:59|ERROR|hyperMeasure|hyper Failed to update figure1: 'HamamatsuHardware' object has no attribute 'frame_num'. ['Traceback (most recent call last):\n', '  File "C:\\ProgramData\\anaconda3\\envs\\scopefoundry\\lib\\site-packages\\ScopeFoundry\\measurement.py", line 362, in _on_display_update_timer\n    self.update_display()\n', '  File "c:\\data\\python programs\\camera humanitas\\hyperspectralmicroscope\\hyperspectral_measure.py", line 93, in update_display\n    length = self.image_gen.frame_num.val\n', "AttributeError: 'HamamatsuHardware' object has no attribute 'frame_num'\n"]
2025-02-19T17:41:59|ERROR|hyperMeasure|hyper Failed to update figure1: 'HamamatsuHardware' object has no attribute 'frame_num'. ['Traceback (most recent call last):\n', '  File "C:\\ProgramData\\anaconda3\\envs\\scopefoundry\\lib\\site-packages\\ScopeFoundry\\measurement.py", line 362, in _on_display_update_timer\n    self.update_display()\n', '  File "c:\\data\\python programs\\camera humanitas\\hyperspectralmicroscope\\hyperspectral_measure.py", line 93, in update_display\n    length = self.image_gen.frame_num.val\n', "AttributeError: 'HamamatsuHardware' object has no attribute 'frame_num'\n"]
2025-02-19T17:41:59|ERROR|hyperMeasure|hyper Failed to update figure1: 'HamamatsuHardware' object has no attribute 'frame_num'. ['Traceback (most recent call last):\n', '  File "C:\\ProgramData\\anaconda3\\envs\\scopefoundry\\lib\\site-packages\\ScopeFoundry\\measurement.py", line 362, in _on_display_update_timer\n    self.update_display()\n', '  File "c:\\data\\python programs\\camera humanitas\\hyperspectralmicroscope\\hyperspectral_measure.py", line 93, in update_display\n    length = self.image_gen.frame_num.val\n', "AttributeError: 'HamamatsuHardware' object has no attribute 'frame_num'\n"]
2025-02-19T17:41:59|ERROR|hyperMeasure|hyper Failed to update figure1: 'HamamatsuHardware' object has no attribute 'frame_num'. ['Traceback (most recent call last):\n', '  File "C:\\ProgramData\\anaconda3\\envs\\scopefoundry\\lib\\site-packages\\ScopeFoundry\\measurement.py", line 362, in _on_display_update_timer\n    self.update_display()\n', '  File "c:\\data\\python programs\\camera humanitas\\hyperspectralmicroscope\\hyperspectral_measure.py", line 93, in update_display\n    length = self.image_gen.frame_num.val\n', "AttributeError: 'HamamatsuHardware' object has no attribute 'frame_num'\n"]
2025-02-19T17:41:59|ERROR|hyperMeasure|hyper Failed to update figure1: 'HamamatsuHardware' object has no attribute 'frame_num'. ['Traceback (most recent call last):\n', '  File "C:\\ProgramData\\anaconda3\\envs\\scopefoundry\\lib\\site-packages\\ScopeFoundry\\measurement.py", line 362, in _on_display_update_timer\n    self.update_display()\n', '  File "c:\\data\\python programs\\camera humanitas\\hyperspectralmicroscope\\hyperspectral_measure.py", line 93, in update_display\n    length = self.image_gen.frame_num.val\n', "AttributeError: 'HamamatsuHardware' object has no attribute 'frame_num'\n"]
2025-02-19T17:42:00|ERROR|hyperMeasure|hyper Failed to update figure1: 'HamamatsuHardware' object has no attribute 'frame_num'. ['Traceback (most recent call last):\n', '  File "C:\\ProgramData\\anaconda3\\envs\\scopefoundry\\lib\\site-packages\\ScopeFoundry\\measurement.py", line 362, in _on_display_update_timer\n    self.update_display()\n', '  File "c:\\data\\python programs\\camera humanitas\\hyperspectralmicroscope\\hyperspectral_measure.py", line 93, in update_display\n    length = self.image_gen.frame_num.val\n', "AttributeError: 'HamamatsuHardware' object has no attribute 'frame_num'\n"]
2025-02-19T17:42:00|ERROR|hyperMeasure|hyper Failed to update figure1: 'HamamatsuHardware' object has no attribute 'frame_num'. ['Traceback (most recent call last):\n', '  File "C:\\ProgramData\\anaconda3\\envs\\scopefoundry\\lib\\site-packages\\ScopeFoundry\\measurement.py", line 362, in _on_display_update_timer\n    self.update_display()\n', '  File "c:\\data\\python programs\\camera humanitas\\hyperspectralmicroscope\\hyperspectral_measure.py", line 93, in update_display\n    length = self.image_gen.frame_num.val\n', "AttributeError: 'HamamatsuHardware' object has no attribute 'frame_num'\n"]
2025-02-19T17:42:00|ERROR|hyperMeasure|hyper Failed to update figure1: 'HamamatsuHardware' object has no attribute 'frame_num'. ['Traceback (most recent call last):\n', '  File "C:\\ProgramData\\anaconda3\\envs\\scopefoundry\\lib\\site-packages\\ScopeFoundry\\measurement.py", line 362, in _on_display_update_timer\n    self.update_display()\n', '  File "c:\\data\\python programs\\camera humanitas\\hyperspectralmicroscope\\hyperspectral_measure.py", line 93, in update_display\n    length = self.image_gen.frame_num.val\n', "AttributeError: 'HamamatsuHardware' object has no attribute 'frame_num'\n"]
2025-02-19T17:42:00|ERROR|hyperMeasure|hyper Failed to update figure1: 'HamamatsuHardware' object has no attribute 'frame_num'. ['Traceback (most recent call last):\n', '  File "C:\\ProgramData\\anaconda3\\envs\\scopefoundry\\lib\\site-packages\\ScopeFoundry\\measurement.py", line 362, in _on_display_update_timer\n    self.update_display()\n', '  File "c:\\data\\python programs\\camera humanitas\\hyperspectralmicroscope\\hyperspectral_measure.py", line 93, in update_display\n    length = self.image_gen.frame_num.val\n', "AttributeError: 'HamamatsuHardware' object has no attribute 'frame_num'\n"]
2025-02-19T17:42:00|ERROR|hyperMeasure|hyper Failed to update figure1: 'HamamatsuHardware' object has no attribute 'frame_num'. ['Traceback (most recent call last):\n', '  File "C:\\ProgramData\\anaconda3\\envs\\scopefoundry\\lib\\site-packages\\ScopeFoundry\\measurement.py", line 362, in _on_display_update_timer\n    self.update_display()\n', '  File "c:\\data\\python programs\\camera humanitas\\hyperspectralmicroscope\\hyperspectral_measure.py", line 93, in update_display\n    length = self.image_gen.frame_num.val\n', "AttributeError: 'HamamatsuHardware' object has no attribute 'frame_num'\n"]
2025-02-19T17:42:00|ERROR|hyperMeasure|hyper Failed to update figure1: 'HamamatsuHardware' object has no attribute 'frame_num'. ['Traceback (most recent call last):\n', '  File "C:\\ProgramData\\anaconda3\\envs\\scopefoundry\\lib\\site-packages\\ScopeFoundry\\measurement.py", line 362, in _on_display_update_timer\n    self.update_display()\n', '  File "c:\\data\\python programs\\camera humanitas\\hyperspectralmicroscope\\hyperspectral_measure.py", line 93, in update_display\n    length = self.image_gen.frame_num.val\n', "AttributeError: 'HamamatsuHardware' object has no attribute 'frame_num'\n"]
2025-02-19T17:42:00|ERROR|hyperMeasure|hyper Failed to update figure1: 'HamamatsuHardware' object has no attribute 'frame_num'. ['Traceback (most recent call last):\n', '  File "C:\\ProgramData\\anaconda3\\envs\\scopefoundry\\lib\\site-packages\\ScopeFoundry\\measurement.py", line 362, in _on_display_update_timer\n    self.update_display()\n', '  File "c:\\data\\python programs\\camera humanitas\\hyperspectralmicroscope\\hyperspectral_measure.py", line 93, in update_display\n    length = self.image_gen.frame_num.val\n', "AttributeError: 'HamamatsuHardware' object has no attribute 'frame_num'\n"]
2025-02-19T17:42:00|ERROR|hyperMeasure|hyper Failed to update figure1: 'HamamatsuHardware' object has no attribute 'frame_num'. ['Traceback (most recent call last):\n', '  File "C:\\ProgramData\\anaconda3\\envs\\scopefoundry\\lib\\site-packages\\ScopeFoundry\\measurement.py", line 362, in _on_display_update_timer\n    self.update_display()\n', '  File "c:\\data\\python programs\\camera humanitas\\hyperspectralmicroscope\\hyperspectral_measure.py", line 93, in update_display\n    length = self.image_gen.frame_num.val\n', "AttributeError: 'HamamatsuHardware' object has no attribute 'frame_num'\n"]
2025-02-19T17:42:00|ERROR|hyperMeasure|hyper Failed to update figure1: 'HamamatsuHardware' object has no attribute 'frame_num'. ['Traceback (most recent call last):\n', '  File "C:\\ProgramData\\anaconda3\\envs\\scopefoundry\\lib\\site-packages\\ScopeFoundry\\measurement.py", line 362, in _on_display_update_timer\n    self.update_display()\n', '  File "c:\\data\\python programs\\camera humanitas\\hyperspectralmicroscope\\hyperspectral_measure.py", line 93, in update_display\n    length = self.image_gen.frame_num.val\n', "AttributeError: 'HamamatsuHardware' object has no attribute 'frame_num'\n"]
2025-02-19T17:42:01|ERROR|hyperMeasure|hyper Failed to update figure1: 'HamamatsuHardware' object has no attribute 'frame_num'. ['Traceback (most recent call last):\n', '  File "C:\\ProgramData\\anaconda3\\envs\\scopefoundry\\lib\\site-packages\\ScopeFoundry\\measurement.py", line 362, in _on_display_update_timer\n    self.update_display()\n', '  File "c:\\data\\python programs\\camera humanitas\\hyperspectralmicroscope\\hyperspectral_measure.py", line 93, in update_display\n    length = self.image_gen.frame_num.val\n', "AttributeError: 'HamamatsuHardware' object has no attribute 'frame_num'\n"]
2025-02-19T17:42:01|ERROR|hyperMeasure|hyper Failed to update figure1: 'HamamatsuHardware' object has no attribute 'frame_num'. ['Traceback (most recent call last):\n', '  File "C:\\ProgramData\\anaconda3\\envs\\scopefoundry\\lib\\site-packages\\ScopeFoundry\\measurement.py", line 362, in _on_display_update_timer\n    self.update_display()\n', '  File "c:\\data\\python programs\\camera humanitas\\hyperspectralmicroscope\\hyperspectral_measure.py", line 93, in update_display\n    length = self.image_gen.frame_num.val\n', "AttributeError: 'HamamatsuHardware' object has no attribute 'frame_num'\n"]
2025-02-19T17:42:01|ERROR|hyperMeasure|hyper Failed to update figure1: 'HamamatsuHardware' object has no attribute 'frame_num'. ['Traceback (most recent call last):\n', '  File "C:\\ProgramData\\anaconda3\\envs\\scopefoundry\\lib\\site-packages\\ScopeFoundry\\measurement.py", line 362, in _on_display_update_timer\n    self.update_display()\n', '  File "c:\\data\\python programs\\camera humanitas\\hyperspectralmicroscope\\hyperspectral_measure.py", line 93, in update_display\n    length = self.image_gen.frame_num.val\n', "AttributeError: 'HamamatsuHardware' object has no attribute 'frame_num'\n"]
2025-02-19T17:42:01|ERROR|hyperMeasure|hyper Failed to update figure1: 'HamamatsuHardware' object has no attribute 'frame_num'. ['Traceback (most recent call last):\n', '  File "C:\\ProgramData\\anaconda3\\envs\\scopefoundry\\lib\\site-packages\\ScopeFoundry\\measurement.py", line 362, in _on_display_update_timer\n    self.update_display()\n', '  File "c:\\data\\python programs\\camera humanitas\\hyperspectralmicroscope\\hyperspectral_measure.py", line 93, in update_display\n    length = self.image_gen.frame_num.val\n', "AttributeError: 'HamamatsuHardware' object has no attribute 'frame_num'\n"]
2025-02-19T17:42:01|ERROR|hyperMeasure|hyper Failed to update figure1: 'HamamatsuHardware' object has no attribute 'frame_num'. ['Traceback (most recent call last):\n', '  File "C:\\ProgramData\\anaconda3\\envs\\scopefoundry\\lib\\site-packages\\ScopeFoundry\\measurement.py", line 362, in _on_display_update_timer\n    self.update_display()\n', '  File "c:\\data\\python programs\\camera humanitas\\hyperspectralmicroscope\\hyperspectral_measure.py", line 93, in update_display\n    length = self.image_gen.frame_num.val\n', "AttributeError: 'HamamatsuHardware' object has no attribute 'frame_num'\n"]
2025-02-19T17:42:01|ERROR|hyperMeasure|hyper Failed to update figure1: 'HamamatsuHardware' object has no attribute 'frame_num'. ['Traceback (most recent call last):\n', '  File "C:\\ProgramData\\anaconda3\\envs\\scopefoundry\\lib\\site-packages\\ScopeFoundry\\measurement.py", line 362, in _on_display_update_timer\n    self.update_display()\n', '  File "c:\\data\\python programs\\camera humanitas\\hyperspectralmicroscope\\hyperspectral_measure.py", line 93, in update_display\n    length = self.image_gen.frame_num.val\n', "AttributeError: 'HamamatsuHardware' object has no attribute 'frame_num'\n"]
2025-02-19T17:42:01|ERROR|hyperMeasure|hyper Failed to update figure1: 'HamamatsuHardware' object has no attribute 'frame_num'. ['Traceback (most recent call last):\n', '  File "C:\\ProgramData\\anaconda3\\envs\\scopefoundry\\lib\\site-packages\\ScopeFoundry\\measurement.py", line 362, in _on_display_update_timer\n    self.update_display()\n', '  File "c:\\data\\python programs\\camera humanitas\\hyperspectralmicroscope\\hyperspectral_measure.py", line 93, in update_display\n    length = self.image_gen.frame_num.val\n', "AttributeError: 'HamamatsuHardware' object has no attribute 'frame_num'\n"]
2025-02-19T17:42:01|ERROR|hyperMeasure|hyper Failed to update figure1: 'HamamatsuHardware' object has no attribute 'frame_num'. ['Traceback (most recent call last):\n', '  File "C:\\ProgramData\\anaconda3\\envs\\scopefoundry\\lib\\site-packages\\ScopeFoundry\\measurement.py", line 362, in _on_display_update_timer\n    self.update_display()\n', '  File "c:\\data\\python programs\\camera humanitas\\hyperspectralmicroscope\\hyperspectral_measure.py", line 93, in update_display\n    length = self.image_gen.frame_num.val\n', "AttributeError: 'HamamatsuHardware' object has no attribute 'frame_num'\n"]
2025-02-19T17:42:01|ERROR|hyperMeasure|hyper Failed to update figure1: 'HamamatsuHardware' object has no attribute 'frame_num'. ['Traceback (most recent call last):\n', '  File "C:\\ProgramData\\anaconda3\\envs\\scopefoundry\\lib\\site-packages\\ScopeFoundry\\measurement.py", line 362, in _on_display_update_timer\n    self.update_display()\n', '  File "c:\\data\\python programs\\camera humanitas\\hyperspectralmicroscope\\hyperspectral_measure.py", line 93, in update_display\n    length = self.image_gen.frame_num.val\n', "AttributeError: 'HamamatsuHardware' object has no attribute 'frame_num'\n"]
2025-02-19T17:42:02|ERROR|hyperMeasure|hyper Failed to update figure1: 'HamamatsuHardware' object has no attribute 'frame_num'. ['Traceback (most recent call last):\n', '  File "C:\\ProgramData\\anaconda3\\envs\\scopefoundry\\lib\\site-packages\\ScopeFoundry\\measurement.py", line 362, in _on_display_update_timer\n    self.update_display()\n', '  File "c:\\data\\python programs\\camera humanitas\\hyperspectralmicroscope\\hyperspectral_measure.py", line 93, in update_display\n    length = self.image_gen.frame_num.val\n', "AttributeError: 'HamamatsuHardware' object has no attribute 'frame_num'\n"]
2025-02-19T17:42:02|ERROR|hyperMeasure|hyper Failed to update figure1: 'HamamatsuHardware' object has no attribute 'frame_num'. ['Traceback (most recent call last):\n', '  File "C:\\ProgramData\\anaconda3\\envs\\scopefoundry\\lib\\site-packages\\ScopeFoundry\\measurement.py", line 362, in _on_display_update_timer\n    self.update_display()\n', '  File "c:\\data\\python programs\\camera humanitas\\hyperspectralmicroscope\\hyperspectral_measure.py", line 93, in update_display\n    length = self.image_gen.frame_num.val\n', "AttributeError: 'HamamatsuHardware' object has no attribute 'frame_num'\n"]
2025-02-19T17:42:02|ERROR|hyperMeasure|hyper Failed to update figure1: 'HamamatsuHardware' object has no attribute 'frame_num'. ['Traceback (most recent call last):\n', '  File "C:\\ProgramData\\anaconda3\\envs\\scopefoundry\\lib\\site-packages\\ScopeFoundry\\measurement.py", line 362, in _on_display_update_timer\n    self.update_display()\n', '  File "c:\\data\\python programs\\camera humanitas\\hyperspectralmicroscope\\hyperspectral_measure.py", line 93, in update_display\n    length = self.image_gen.frame_num.val\n', "AttributeError: 'HamamatsuHardware' object has no attribute 'frame_num'\n"]
2025-02-19T17:42:02|ERROR|hyperMeasure|hyper Failed to update figure1: 'HamamatsuHardware' object has no attribute 'frame_num'. ['Traceback (most recent call last):\n', '  File "C:\\ProgramData\\anaconda3\\envs\\scopefoundry\\lib\\site-packages\\ScopeFoundry\\measurement.py", line 362, in _on_display_update_timer\n    self.update_display()\n', '  File "c:\\data\\python programs\\camera humanitas\\hyperspectralmicroscope\\hyperspectral_measure.py", line 93, in update_display\n    length = self.image_gen.frame_num.val\n', "AttributeError: 'HamamatsuHardware' object has no attribute 'frame_num'\n"]
2025-02-19T17:42:02|ERROR|hyperMeasure|hyper Failed to update figure1: 'HamamatsuHardware' object has no attribute 'frame_num'. ['Traceback (most recent call last):\n', '  File "C:\\ProgramData\\anaconda3\\envs\\scopefoundry\\lib\\site-packages\\ScopeFoundry\\measurement.py", line 362, in _on_display_update_timer\n    self.update_display()\n', '  File "c:\\data\\python programs\\camera humanitas\\hyperspectralmicroscope\\hyperspectral_measure.py", line 93, in update_display\n    length = self.image_gen.frame_num.val\n', "AttributeError: 'HamamatsuHardware' object has no attribute 'frame_num'\n"]
2025-02-19T17:42:02|ERROR|hyperMeasure|hyper Failed to update figure1: 'HamamatsuHardware' object has no attribute 'frame_num'. ['Traceback (most recent call last):\n', '  File "C:\\ProgramData\\anaconda3\\envs\\scopefoundry\\lib\\site-packages\\ScopeFoundry\\measurement.py", line 362, in _on_display_update_timer\n    self.update_display()\n', '  File "c:\\data\\python programs\\camera humanitas\\hyperspectralmicroscope\\hyperspectral_measure.py", line 93, in update_display\n    length = self.image_gen.frame_num.val\n', "AttributeError: 'HamamatsuHardware' object has no attribute 'frame_num'\n"]
2025-02-19T17:42:02|ERROR|hyperMeasure|hyper Failed to update figure1: 'HamamatsuHardware' object has no attribute 'frame_num'. ['Traceback (most recent call last):\n', '  File "C:\\ProgramData\\anaconda3\\envs\\scopefoundry\\lib\\site-packages\\ScopeFoundry\\measurement.py", line 362, in _on_display_update_timer\n    self.update_display()\n', '  File "c:\\data\\python programs\\camera humanitas\\hyperspectralmicroscope\\hyperspectral_measure.py", line 93, in update_display\n    length = self.image_gen.frame_num.val\n', "AttributeError: 'HamamatsuHardware' object has no attribute 'frame_num'\n"]
2025-02-19T17:42:02|ERROR|hyperMeasure|hyper Failed to update figure1: 'HamamatsuHardware' object has no attribute 'frame_num'. ['Traceback (most recent call last):\n', '  File "C:\\ProgramData\\anaconda3\\envs\\scopefoundry\\lib\\site-packages\\ScopeFoundry\\measurement.py", line 362, in _on_display_update_timer\n    self.update_display()\n', '  File "c:\\data\\python programs\\camera humanitas\\hyperspectralmicroscope\\hyperspectral_measure.py", line 93, in update_display\n    length = self.image_gen.frame_num.val\n', "AttributeError: 'HamamatsuHardware' object has no attribute 'frame_num'\n"]
2025-02-19T17:42:02|ERROR|hyperMeasure|hyper Failed to update figure1: 'HamamatsuHardware' object has no attribute 'frame_num'. ['Traceback (most recent call last):\n', '  File "C:\\ProgramData\\anaconda3\\envs\\scopefoundry\\lib\\site-packages\\ScopeFoundry\\measurement.py", line 362, in _on_display_update_timer\n    self.update_display()\n', '  File "c:\\data\\python programs\\camera humanitas\\hyperspectralmicroscope\\hyperspectral_measure.py", line 93, in update_display\n    length = self.image_gen.frame_num.val\n', "AttributeError: 'HamamatsuHardware' object has no attribute 'frame_num'\n"]
2025-02-19T17:42:02|ERROR|hyperMeasure|hyper Failed to update figure1: 'HamamatsuHardware' object has no attribute 'frame_num'. ['Traceback (most recent call last):\n', '  File "C:\\ProgramData\\anaconda3\\envs\\scopefoundry\\lib\\site-packages\\ScopeFoundry\\measurement.py", line 362, in _on_display_update_timer\n    self.update_display()\n', '  File "c:\\data\\python programs\\camera humanitas\\hyperspectralmicroscope\\hyperspectral_measure.py", line 93, in update_display\n    length = self.image_gen.frame_num.val\n', "AttributeError: 'HamamatsuHardware' object has no attribute 'frame_num'\n"]
2025-02-19T17:42:03|ERROR|hyperMeasure|hyper Failed to update figure1: 'HamamatsuHardware' object has no attribute 'frame_num'. ['Traceback (most recent call last):\n', '  File "C:\\ProgramData\\anaconda3\\envs\\scopefoundry\\lib\\site-packages\\ScopeFoundry\\measurement.py", line 362, in _on_display_update_timer\n    self.update_display()\n', '  File "c:\\data\\python programs\\camera humanitas\\hyperspectralmicroscope\\hyperspectral_measure.py", line 93, in update_display\n    length = self.image_gen.frame_num.val\n', "AttributeError: 'HamamatsuHardware' object has no attribute 'frame_num'\n"]
2025-02-19T17:42:03|ERROR|hyperMeasure|hyper Failed to update figure1: 'HamamatsuHardware' object has no attribute 'frame_num'. ['Traceback (most recent call last):\n', '  File "C:\\ProgramData\\anaconda3\\envs\\scopefoundry\\lib\\site-packages\\ScopeFoundry\\measurement.py", line 362, in _on_display_update_timer\n    self.update_display()\n', '  File "c:\\data\\python programs\\camera humanitas\\hyperspectralmicroscope\\hyperspectral_measure.py", line 93, in update_display\n    length = self.image_gen.frame_num.val\n', "AttributeError: 'HamamatsuHardware' object has no attribute 'frame_num'\n"]
2025-02-19T17:42:03|ERROR|hyperMeasure|hyper Failed to update figure1: 'HamamatsuHardware' object has no attribute 'frame_num'. ['Traceback (most recent call last):\n', '  File "C:\\ProgramData\\anaconda3\\envs\\scopefoundry\\lib\\site-packages\\ScopeFoundry\\measurement.py", line 362, in _on_display_update_timer\n    self.update_display()\n', '  File "c:\\data\\python programs\\camera humanitas\\hyperspectralmicroscope\\hyperspectral_measure.py", line 93, in update_display\n    length = self.image_gen.frame_num.val\n', "AttributeError: 'HamamatsuHardware' object has no attribute 'frame_num'\n"]
2025-02-19T17:42:03|ERROR|hyperMeasure|hyper Failed to update figure1: 'HamamatsuHardware' object has no attribute 'frame_num'. ['Traceback (most recent call last):\n', '  File "C:\\ProgramData\\anaconda3\\envs\\scopefoundry\\lib\\site-packages\\ScopeFoundry\\measurement.py", line 362, in _on_display_update_timer\n    self.update_display()\n', '  File "c:\\data\\python programs\\camera humanitas\\hyperspectralmicroscope\\hyperspectral_measure.py", line 93, in update_display\n    length = self.image_gen.frame_num.val\n', "AttributeError: 'HamamatsuHardware' object has no attribute 'frame_num'\n"]
2025-02-19T17:42:03|ERROR|hyperMeasure|hyper Failed to update figure1: 'HamamatsuHardware' object has no attribute 'frame_num'. ['Traceback (most recent call last):\n', '  File "C:\\ProgramData\\anaconda3\\envs\\scopefoundry\\lib\\site-packages\\ScopeFoundry\\measurement.py", line 362, in _on_display_update_timer\n    self.update_display()\n', '  File "c:\\data\\python programs\\camera humanitas\\hyperspectralmicroscope\\hyperspectral_measure.py", line 93, in update_display\n    length = self.image_gen.frame_num.val\n', "AttributeError: 'HamamatsuHardware' object has no attribute 'frame_num'\n"]
2025-02-19T17:42:03|ERROR|hyperMeasure|hyper Failed to update figure1: 'HamamatsuHardware' object has no attribute 'frame_num'. ['Traceback (most recent call last):\n', '  File "C:\\ProgramData\\anaconda3\\envs\\scopefoundry\\lib\\site-packages\\ScopeFoundry\\measurement.py", line 362, in _on_display_update_timer\n    self.update_display()\n', '  File "c:\\data\\python programs\\camera humanitas\\hyperspectralmicroscope\\hyperspectral_measure.py", line 93, in update_display\n    length = self.image_gen.frame_num.val\n', "AttributeError: 'HamamatsuHardware' object has no attribute 'frame_num'\n"]
2025-02-19T17:42:03|ERROR|hyperMeasure|hyper Failed to update figure1: 'HamamatsuHardware' object has no attribute 'frame_num'. ['Traceback (most recent call last):\n', '  File "C:\\ProgramData\\anaconda3\\envs\\scopefoundry\\lib\\site-packages\\ScopeFoundry\\measurement.py", line 362, in _on_display_update_timer\n    self.update_display()\n', '  File "c:\\data\\python programs\\camera humanitas\\hyperspectralmicroscope\\hyperspectral_measure.py", line 93, in update_display\n    length = self.image_gen.frame_num.val\n', "AttributeError: 'HamamatsuHardware' object has no attribute 'frame_num'\n"]
2025-02-19T17:42:03|ERROR|hyperMeasure|hyper Failed to update figure1: 'HamamatsuHardware' object has no attribute 'frame_num'. ['Traceback (most recent call last):\n', '  File "C:\\ProgramData\\anaconda3\\envs\\scopefoundry\\lib\\site-packages\\ScopeFoundry\\measurement.py", line 362, in _on_display_update_timer\n    self.update_display()\n', '  File "c:\\data\\python programs\\camera humanitas\\hyperspectralmicroscope\\hyperspectral_measure.py", line 93, in update_display\n    length = self.image_gen.frame_num.val\n', "AttributeError: 'HamamatsuHardware' object has no attribute 'frame_num'\n"]
2025-02-19T17:42:04|ERROR|hyperMeasure|hyper Failed to update figure1: 'HamamatsuHardware' object has no attribute 'frame_num'. ['Traceback (most recent call last):\n', '  File "C:\\ProgramData\\anaconda3\\envs\\scopefoundry\\lib\\site-packages\\ScopeFoundry\\measurement.py", line 362, in _on_display_update_timer\n    self.update_display()\n', '  File "c:\\data\\python programs\\camera humanitas\\hyperspectralmicroscope\\hyperspectral_measure.py", line 93, in update_display\n    length = self.image_gen.frame_num.val\n', "AttributeError: 'HamamatsuHardware' object has no attribute 'frame_num'\n"]
2025-02-19T17:42:04|ERROR|hyperMeasure|hyper Failed to update figure1: 'HamamatsuHardware' object has no attribute 'frame_num'. ['Traceback (most recent call last):\n', '  File "C:\\ProgramData\\anaconda3\\envs\\scopefoundry\\lib\\site-packages\\ScopeFoundry\\measurement.py", line 362, in _on_display_update_timer\n    self.update_display()\n', '  File "c:\\data\\python programs\\camera humanitas\\hyperspectralmicroscope\\hyperspectral_measure.py", line 93, in update_display\n    length = self.image_gen.frame_num.val\n', "AttributeError: 'HamamatsuHardware' object has no attribute 'frame_num'\n"]
2025-02-19T17:42:04|ERROR|hyperMeasure|hyper Failed to update figure1: 'HamamatsuHardware' object has no attribute 'frame_num'. ['Traceback (most recent call last):\n', '  File "C:\\ProgramData\\anaconda3\\envs\\scopefoundry\\lib\\site-packages\\ScopeFoundry\\measurement.py", line 362, in _on_display_update_timer\n    self.update_display()\n', '  File "c:\\data\\python programs\\camera humanitas\\hyperspectralmicroscope\\hyperspectral_measure.py", line 93, in update_display\n    length = self.image_gen.frame_num.val\n', "AttributeError: 'HamamatsuHardware' object has no attribute 'frame_num'\n"]
2025-02-19T17:42:04|ERROR|hyperMeasure|hyper Failed to update figure1: 'HamamatsuHardware' object has no attribute 'frame_num'. ['Traceback (most recent call last):\n', '  File "C:\\ProgramData\\anaconda3\\envs\\scopefoundry\\lib\\site-packages\\ScopeFoundry\\measurement.py", line 362, in _on_display_update_timer\n    self.update_display()\n', '  File "c:\\data\\python programs\\camera humanitas\\hyperspectralmicroscope\\hyperspectral_measure.py", line 93, in update_display\n    length = self.image_gen.frame_num.val\n', "AttributeError: 'HamamatsuHardware' object has no attribute 'frame_num'\n"]
2025-02-19T17:42:04|ERROR|hyperMeasure|hyper Failed to update figure1: 'HamamatsuHardware' object has no attribute 'frame_num'. ['Traceback (most recent call last):\n', '  File "C:\\ProgramData\\anaconda3\\envs\\scopefoundry\\lib\\site-packages\\ScopeFoundry\\measurement.py", line 362, in _on_display_update_timer\n    self.update_display()\n', '  File "c:\\data\\python programs\\camera humanitas\\hyperspectralmicroscope\\hyperspectral_measure.py", line 93, in update_display\n    length = self.image_gen.frame_num.val\n', "AttributeError: 'HamamatsuHardware' object has no attribute 'frame_num'\n"]
2025-02-19T17:42:04|ERROR|hyperMeasure|hyper Failed to update figure1: 'HamamatsuHardware' object has no attribute 'frame_num'. ['Traceback (most recent call last):\n', '  File "C:\\ProgramData\\anaconda3\\envs\\scopefoundry\\lib\\site-packages\\ScopeFoundry\\measurement.py", line 362, in _on_display_update_timer\n    self.update_display()\n', '  File "c:\\data\\python programs\\camera humanitas\\hyperspectralmicroscope\\hyperspectral_measure.py", line 93, in update_display\n    length = self.image_gen.frame_num.val\n', "AttributeError: 'HamamatsuHardware' object has no attribute 'frame_num'\n"]
2025-02-19T17:42:04|ERROR|hyperMeasure|hyper Failed to update figure1: 'HamamatsuHardware' object has no attribute 'frame_num'. ['Traceback (most recent call last):\n', '  File "C:\\ProgramData\\anaconda3\\envs\\scopefoundry\\lib\\site-packages\\ScopeFoundry\\measurement.py", line 362, in _on_display_update_timer\n    self.update_display()\n', '  File "c:\\data\\python programs\\camera humanitas\\hyperspectralmicroscope\\hyperspectral_measure.py", line 93, in update_display\n    length = self.image_gen.frame_num.val\n', "AttributeError: 'HamamatsuHardware' object has no attribute 'frame_num'\n"]
2025-02-19T17:42:04|ERROR|hyperMeasure|hyper Failed to update figure1: 'HamamatsuHardware' object has no attribute 'frame_num'. ['Traceback (most recent call last):\n', '  File "C:\\ProgramData\\anaconda3\\envs\\scopefoundry\\lib\\site-packages\\ScopeFoundry\\measurement.py", line 362, in _on_display_update_timer\n    self.update_display()\n', '  File "c:\\data\\python programs\\camera humanitas\\hyperspectralmicroscope\\hyperspectral_measure.py", line 93, in update_display\n    length = self.image_gen.frame_num.val\n', "AttributeError: 'HamamatsuHardware' object has no attribute 'frame_num'\n"]
2025-02-19T17:42:04|ERROR|hyperMeasure|hyper Failed to update figure1: 'HamamatsuHardware' object has no attribute 'frame_num'. ['Traceback (most recent call last):\n', '  File "C:\\ProgramData\\anaconda3\\envs\\scopefoundry\\lib\\site-packages\\ScopeFoundry\\measurement.py", line 362, in _on_display_update_timer\n    self.update_display()\n', '  File "c:\\data\\python programs\\camera humanitas\\hyperspectralmicroscope\\hyperspectral_measure.py", line 93, in update_display\n    length = self.image_gen.frame_num.val\n', "AttributeError: 'HamamatsuHardware' object has no attribute 'frame_num'\n"]
2025-02-19T17:42:04|ERROR|hyperMeasure|hyper Failed to update figure1: 'HamamatsuHardware' object has no attribute 'frame_num'. ['Traceback (most recent call last):\n', '  File "C:\\ProgramData\\anaconda3\\envs\\scopefoundry\\lib\\site-packages\\ScopeFoundry\\measurement.py", line 362, in _on_display_update_timer\n    self.update_display()\n', '  File "c:\\data\\python programs\\camera humanitas\\hyperspectralmicroscope\\hyperspectral_measure.py", line 93, in update_display\n    length = self.image_gen.frame_num.val\n', "AttributeError: 'HamamatsuHardware' object has no attribute 'frame_num'\n"]
2025-02-19T17:42:05|ERROR|hyperMeasure|hyper Failed to update figure1: 'HamamatsuHardware' object has no attribute 'frame_num'. ['Traceback (most recent call last):\n', '  File "C:\\ProgramData\\anaconda3\\envs\\scopefoundry\\lib\\site-packages\\ScopeFoundry\\measurement.py", line 362, in _on_display_update_timer\n    self.update_display()\n', '  File "c:\\data\\python programs\\camera humanitas\\hyperspectralmicroscope\\hyperspectral_measure.py", line 93, in update_display\n    length = self.image_gen.frame_num.val\n', "AttributeError: 'HamamatsuHardware' object has no attribute 'frame_num'\n"]
2025-02-19T17:42:05|ERROR|hyperMeasure|hyper Failed to update figure1: 'HamamatsuHardware' object has no attribute 'frame_num'. ['Traceback (most recent call last):\n', '  File "C:\\ProgramData\\anaconda3\\envs\\scopefoundry\\lib\\site-packages\\ScopeFoundry\\measurement.py", line 362, in _on_display_update_timer\n    self.update_display()\n', '  File "c:\\data\\python programs\\camera humanitas\\hyperspectralmicroscope\\hyperspectral_measure.py", line 93, in update_display\n    length = self.image_gen.frame_num.val\n', "AttributeError: 'HamamatsuHardware' object has no attribute 'frame_num'\n"]
2025-02-19T17:42:05|ERROR|hyperMeasure|hyper Failed to update figure1: 'HamamatsuHardware' object has no attribute 'frame_num'. ['Traceback (most recent call last):\n', '  File "C:\\ProgramData\\anaconda3\\envs\\scopefoundry\\lib\\site-packages\\ScopeFoundry\\measurement.py", line 362, in _on_display_update_timer\n    self.update_display()\n', '  File "c:\\data\\python programs\\camera humanitas\\hyperspectralmicroscope\\hyperspectral_measure.py", line 93, in update_display\n    length = self.image_gen.frame_num.val\n', "AttributeError: 'HamamatsuHardware' object has no attribute 'frame_num'\n"]
2025-02-19T17:42:05|ERROR|hyperMeasure|hyper Failed to update figure1: 'HamamatsuHardware' object has no attribute 'frame_num'. ['Traceback (most recent call last):\n', '  File "C:\\ProgramData\\anaconda3\\envs\\scopefoundry\\lib\\site-packages\\ScopeFoundry\\measurement.py", line 362, in _on_display_update_timer\n    self.update_display()\n', '  File "c:\\data\\python programs\\camera humanitas\\hyperspectralmicroscope\\hyperspectral_measure.py", line 93, in update_display\n    length = self.image_gen.frame_num.val\n', "AttributeError: 'HamamatsuHardware' object has no attribute 'frame_num'\n"]
2025-02-19T17:42:05|ERROR|hyperMeasure|hyper Failed to update figure1: 'HamamatsuHardware' object has no attribute 'frame_num'. ['Traceback (most recent call last):\n', '  File "C:\\ProgramData\\anaconda3\\envs\\scopefoundry\\lib\\site-packages\\ScopeFoundry\\measurement.py", line 362, in _on_display_update_timer\n    self.update_display()\n', '  File "c:\\data\\python programs\\camera humanitas\\hyperspectralmicroscope\\hyperspectral_measure.py", line 93, in update_display\n    length = self.image_gen.frame_num.val\n', "AttributeError: 'HamamatsuHardware' object has no attribute 'frame_num'\n"]
2025-02-19T17:42:05|ERROR|hyperMeasure|hyper Failed to update figure1: 'HamamatsuHardware' object has no attribute 'frame_num'. ['Traceback (most recent call last):\n', '  File "C:\\ProgramData\\anaconda3\\envs\\scopefoundry\\lib\\site-packages\\ScopeFoundry\\measurement.py", line 362, in _on_display_update_timer\n    self.update_display()\n', '  File "c:\\data\\python programs\\camera humanitas\\hyperspectralmicroscope\\hyperspectral_measure.py", line 93, in update_display\n    length = self.image_gen.frame_num.val\n', "AttributeError: 'HamamatsuHardware' object has no attribute 'frame_num'\n"]
2025-02-19T17:42:05|ERROR|hyperMeasure|hyper Failed to update figure1: 'HamamatsuHardware' object has no attribute 'frame_num'. ['Traceback (most recent call last):\n', '  File "C:\\ProgramData\\anaconda3\\envs\\scopefoundry\\lib\\site-packages\\ScopeFoundry\\measurement.py", line 362, in _on_display_update_timer\n    self.update_display()\n', '  File "c:\\data\\python programs\\camera humanitas\\hyperspectralmicroscope\\hyperspectral_measure.py", line 93, in update_display\n    length = self.image_gen.frame_num.val\n', "AttributeError: 'HamamatsuHardware' object has no attribute 'frame_num'\n"]
2025-02-19T17:42:05|CRITICAL|root|Unhandled exception:Traceback (most recent call last):
  File "c:\data\python programs\camera humanitas\hyperspectralmicroscope\hyperspectral_measure.py", line 173, in run
    self.image_gen.camera.acq_start()
AttributeError: 'LoggedQuantity' object has no attribute 'acq_start'

During handling of the above exception, another exception occurred:

Traceback (most recent call last):
  File "C:\ProgramData\anaconda3\envs\scopefoundry\lib\site-packages\ScopeFoundry\measurement.py", line 27, in run
    self.measurement._thread_run()
  File "C:\ProgramData\anaconda3\envs\scopefoundry\lib\site-packages\ScopeFoundry\measurement.py", line 230, in _thread_run
    self.run()
  File "c:\data\python programs\camera humanitas\hyperspectralmicroscope\hyperspectral_measure.py", line 193, in run
    self.image_gen.camera.acq_stop()
AttributeError: 'LoggedQuantity' object has no attribute 'acq_stop'

2025-02-19T17:42:05|ERROR|hyperMeasure|hyper Failed to update figure1: 'HamamatsuHardware' object has no attribute 'frame_num'. ['Traceback (most recent call last):\n', '  File "C:\\ProgramData\\anaconda3\\envs\\scopefoundry\\lib\\site-packages\\ScopeFoundry\\measurement.py", line 362, in _on_display_update_timer\n    self.update_display()\n', '  File "c:\\data\\python programs\\camera humanitas\\hyperspectralmicroscope\\hyperspectral_measure.py", line 93, in update_display\n    length = self.image_gen.frame_num.val\n', "AttributeError: 'HamamatsuHardware' object has no attribute 'frame_num'\n"]
2025-02-19T17:42:09|ERROR|hyperMeasure|hyper Failed to update figure1: 'HamamatsuHardware' object has no attribute 'frame_num'. ['Traceback (most recent call last):\n', '  File "C:\\ProgramData\\anaconda3\\envs\\scopefoundry\\lib\\site-packages\\ScopeFoundry\\measurement.py", line 362, in _on_display_update_timer\n    self.update_display()\n', '  File "c:\\data\\python programs\\camera humanitas\\hyperspectralmicroscope\\hyperspectral_measure.py", line 93, in update_display\n    length = self.image_gen.frame_num.val\n', "AttributeError: 'HamamatsuHardware' object has no attribute 'frame_num'\n"]
2025-02-19T17:42:09|ERROR|hyperMeasure|hyper Failed to update figure1: 'HamamatsuHardware' object has no attribute 'frame_num'. ['Traceback (most recent call last):\n', '  File "C:\\ProgramData\\anaconda3\\envs\\scopefoundry\\lib\\site-packages\\ScopeFoundry\\measurement.py", line 362, in _on_display_update_timer\n    self.update_display()\n', '  File "c:\\data\\python programs\\camera humanitas\\hyperspectralmicroscope\\hyperspectral_measure.py", line 93, in update_display\n    length = self.image_gen.frame_num.val\n', "AttributeError: 'HamamatsuHardware' object has no attribute 'frame_num'\n"]
2025-02-19T17:42:09|ERROR|hyperMeasure|hyper Failed to update figure1: 'HamamatsuHardware' object has no attribute 'frame_num'. ['Traceback (most recent call last):\n', '  File "C:\\ProgramData\\anaconda3\\envs\\scopefoundry\\lib\\site-packages\\ScopeFoundry\\measurement.py", line 362, in _on_display_update_timer\n    self.update_display()\n', '  File "c:\\data\\python programs\\camera humanitas\\hyperspectralmicroscope\\hyperspectral_measure.py", line 93, in update_display\n    length = self.image_gen.frame_num.val\n', "AttributeError: 'HamamatsuHardware' object has no attribute 'frame_num'\n"]
2025-02-19T17:42:10|ERROR|hyperMeasure|hyper Failed to update figure1: 'HamamatsuHardware' object has no attribute 'frame_num'. ['Traceback (most recent call last):\n', '  File "C:\\ProgramData\\anaconda3\\envs\\scopefoundry\\lib\\site-packages\\ScopeFoundry\\measurement.py", line 362, in _on_display_update_timer\n    self.update_display()\n', '  File "c:\\data\\python programs\\camera humanitas\\hyperspectralmicroscope\\hyperspectral_measure.py", line 93, in update_display\n    length = self.image_gen.frame_num.val\n', "AttributeError: 'HamamatsuHardware' object has no attribute 'frame_num'\n"]
2025-02-19T17:42:10|ERROR|hyperMeasure|hyper Failed to update figure1: 'HamamatsuHardware' object has no attribute 'frame_num'. ['Traceback (most recent call last):\n', '  File "C:\\ProgramData\\anaconda3\\envs\\scopefoundry\\lib\\site-packages\\ScopeFoundry\\measurement.py", line 362, in _on_display_update_timer\n    self.update_display()\n', '  File "c:\\data\\python programs\\camera humanitas\\hyperspectralmicroscope\\hyperspectral_measure.py", line 93, in update_display\n    length = self.image_gen.frame_num.val\n', "AttributeError: 'HamamatsuHardware' object has no attribute 'frame_num'\n"]
2025-02-19T17:42:10|ERROR|hyperMeasure|hyper Failed to update figure1: 'HamamatsuHardware' object has no attribute 'frame_num'. ['Traceback (most recent call last):\n', '  File "C:\\ProgramData\\anaconda3\\envs\\scopefoundry\\lib\\site-packages\\ScopeFoundry\\measurement.py", line 362, in _on_display_update_timer\n    self.update_display()\n', '  File "c:\\data\\python programs\\camera humanitas\\hyperspectralmicroscope\\hyperspectral_measure.py", line 93, in update_display\n    length = self.image_gen.frame_num.val\n', "AttributeError: 'HamamatsuHardware' object has no attribute 'frame_num'\n"]
2025-02-19T17:42:10|ERROR|hyperMeasure|hyper Failed to update figure1: 'HamamatsuHardware' object has no attribute 'frame_num'. ['Traceback (most recent call last):\n', '  File "C:\\ProgramData\\anaconda3\\envs\\scopefoundry\\lib\\site-packages\\ScopeFoundry\\measurement.py", line 362, in _on_display_update_timer\n    self.update_display()\n', '  File "c:\\data\\python programs\\camera humanitas\\hyperspectralmicroscope\\hyperspectral_measure.py", line 93, in update_display\n    length = self.image_gen.frame_num.val\n', "AttributeError: 'HamamatsuHardware' object has no attribute 'frame_num'\n"]
2025-02-19T17:42:10|ERROR|hyperMeasure|hyper Failed to update figure1: 'HamamatsuHardware' object has no attribute 'frame_num'. ['Traceback (most recent call last):\n', '  File "C:\\ProgramData\\anaconda3\\envs\\scopefoundry\\lib\\site-packages\\ScopeFoundry\\measurement.py", line 362, in _on_display_update_timer\n    self.update_display()\n', '  File "c:\\data\\python programs\\camera humanitas\\hyperspectralmicroscope\\hyperspectral_measure.py", line 93, in update_display\n    length = self.image_gen.frame_num.val\n', "AttributeError: 'HamamatsuHardware' object has no attribute 'frame_num'\n"]
2025-02-19T17:42:10|ERROR|hyperMeasure|hyper Failed to update figure1: 'HamamatsuHardware' object has no attribute 'frame_num'. ['Traceback (most recent call last):\n', '  File "C:\\ProgramData\\anaconda3\\envs\\scopefoundry\\lib\\site-packages\\ScopeFoundry\\measurement.py", line 362, in _on_display_update_timer\n    self.update_display()\n', '  File "c:\\data\\python programs\\camera humanitas\\hyperspectralmicroscope\\hyperspectral_measure.py", line 93, in update_display\n    length = self.image_gen.frame_num.val\n', "AttributeError: 'HamamatsuHardware' object has no attribute 'frame_num'\n"]
2025-02-19T17:42:10|ERROR|hyperMeasure|hyper Failed to update figure1: 'HamamatsuHardware' object has no attribute 'frame_num'. ['Traceback (most recent call last):\n', '  File "C:\\ProgramData\\anaconda3\\envs\\scopefoundry\\lib\\site-packages\\ScopeFoundry\\measurement.py", line 362, in _on_display_update_timer\n    self.update_display()\n', '  File "c:\\data\\python programs\\camera humanitas\\hyperspectralmicroscope\\hyperspectral_measure.py", line 93, in update_display\n    length = self.image_gen.frame_num.val\n', "AttributeError: 'HamamatsuHardware' object has no attribute 'frame_num'\n"]
2025-02-19T17:42:10|ERROR|hyperMeasure|hyper Failed to update figure1: 'HamamatsuHardware' object has no attribute 'frame_num'. ['Traceback (most recent call last):\n', '  File "C:\\ProgramData\\anaconda3\\envs\\scopefoundry\\lib\\site-packages\\ScopeFoundry\\measurement.py", line 362, in _on_display_update_timer\n    self.update_display()\n', '  File "c:\\data\\python programs\\camera humanitas\\hyperspectralmicroscope\\hyperspectral_measure.py", line 93, in update_display\n    length = self.image_gen.frame_num.val\n', "AttributeError: 'HamamatsuHardware' object has no attribute 'frame_num'\n"]
2025-02-19T17:42:11|ERROR|hyperMeasure|hyper Failed to update figure1: 'HamamatsuHardware' object has no attribute 'frame_num'. ['Traceback (most recent call last):\n', '  File "C:\\ProgramData\\anaconda3\\envs\\scopefoundry\\lib\\site-packages\\ScopeFoundry\\measurement.py", line 362, in _on_display_update_timer\n    self.update_display()\n', '  File "c:\\data\\python programs\\camera humanitas\\hyperspectralmicroscope\\hyperspectral_measure.py", line 93, in update_display\n    length = self.image_gen.frame_num.val\n', "AttributeError: 'HamamatsuHardware' object has no attribute 'frame_num'\n"]
2025-02-19T17:42:11|ERROR|hyperMeasure|hyper Failed to update figure1: 'HamamatsuHardware' object has no attribute 'frame_num'. ['Traceback (most recent call last):\n', '  File "C:\\ProgramData\\anaconda3\\envs\\scopefoundry\\lib\\site-packages\\ScopeFoundry\\measurement.py", line 362, in _on_display_update_timer\n    self.update_display()\n', '  File "c:\\data\\python programs\\camera humanitas\\hyperspectralmicroscope\\hyperspectral_measure.py", line 93, in update_display\n    length = self.image_gen.frame_num.val\n', "AttributeError: 'HamamatsuHardware' object has no attribute 'frame_num'\n"]
2025-02-19T17:42:11|ERROR|hyperMeasure|hyper Failed to update figure1: 'HamamatsuHardware' object has no attribute 'frame_num'. ['Traceback (most recent call last):\n', '  File "C:\\ProgramData\\anaconda3\\envs\\scopefoundry\\lib\\site-packages\\ScopeFoundry\\measurement.py", line 362, in _on_display_update_timer\n    self.update_display()\n', '  File "c:\\data\\python programs\\camera humanitas\\hyperspectralmicroscope\\hyperspectral_measure.py", line 93, in update_display\n    length = self.image_gen.frame_num.val\n', "AttributeError: 'HamamatsuHardware' object has no attribute 'frame_num'\n"]
2025-02-19T17:42:11|ERROR|hyperMeasure|hyper Failed to update figure1: 'HamamatsuHardware' object has no attribute 'frame_num'. ['Traceback (most recent call last):\n', '  File "C:\\ProgramData\\anaconda3\\envs\\scopefoundry\\lib\\site-packages\\ScopeFoundry\\measurement.py", line 362, in _on_display_update_timer\n    self.update_display()\n', '  File "c:\\data\\python programs\\camera humanitas\\hyperspectralmicroscope\\hyperspectral_measure.py", line 93, in update_display\n    length = self.image_gen.frame_num.val\n', "AttributeError: 'HamamatsuHardware' object has no attribute 'frame_num'\n"]
2025-02-19T17:42:11|ERROR|hyperMeasure|hyper Failed to update figure1: 'HamamatsuHardware' object has no attribute 'frame_num'. ['Traceback (most recent call last):\n', '  File "C:\\ProgramData\\anaconda3\\envs\\scopefoundry\\lib\\site-packages\\ScopeFoundry\\measurement.py", line 362, in _on_display_update_timer\n    self.update_display()\n', '  File "c:\\data\\python programs\\camera humanitas\\hyperspectralmicroscope\\hyperspectral_measure.py", line 93, in update_display\n    length = self.image_gen.frame_num.val\n', "AttributeError: 'HamamatsuHardware' object has no attribute 'frame_num'\n"]
2025-02-19T17:42:11|ERROR|hyperMeasure|hyper Failed to update figure1: 'HamamatsuHardware' object has no attribute 'frame_num'. ['Traceback (most recent call last):\n', '  File "C:\\ProgramData\\anaconda3\\envs\\scopefoundry\\lib\\site-packages\\ScopeFoundry\\measurement.py", line 362, in _on_display_update_timer\n    self.update_display()\n', '  File "c:\\data\\python programs\\camera humanitas\\hyperspectralmicroscope\\hyperspectral_measure.py", line 93, in update_display\n    length = self.image_gen.frame_num.val\n', "AttributeError: 'HamamatsuHardware' object has no attribute 'frame_num'\n"]
2025-02-19T17:42:11|ERROR|hyperMeasure|hyper Failed to update figure1: 'HamamatsuHardware' object has no attribute 'frame_num'. ['Traceback (most recent call last):\n', '  File "C:\\ProgramData\\anaconda3\\envs\\scopefoundry\\lib\\site-packages\\ScopeFoundry\\measurement.py", line 362, in _on_display_update_timer\n    self.update_display()\n', '  File "c:\\data\\python programs\\camera humanitas\\hyperspectralmicroscope\\hyperspectral_measure.py", line 93, in update_display\n    length = self.image_gen.frame_num.val\n', "AttributeError: 'HamamatsuHardware' object has no attribute 'frame_num'\n"]
2025-02-19T17:42:11|ERROR|hyperMeasure|hyper Failed to update figure1: 'HamamatsuHardware' object has no attribute 'frame_num'. ['Traceback (most recent call last):\n', '  File "C:\\ProgramData\\anaconda3\\envs\\scopefoundry\\lib\\site-packages\\ScopeFoundry\\measurement.py", line 362, in _on_display_update_timer\n    self.update_display()\n', '  File "c:\\data\\python programs\\camera humanitas\\hyperspectralmicroscope\\hyperspectral_measure.py", line 93, in update_display\n    length = self.image_gen.frame_num.val\n', "AttributeError: 'HamamatsuHardware' object has no attribute 'frame_num'\n"]
2025-02-19T17:42:12|ERROR|hyperMeasure|hyper Failed to update figure1: 'HamamatsuHardware' object has no attribute 'frame_num'. ['Traceback (most recent call last):\n', '  File "C:\\ProgramData\\anaconda3\\envs\\scopefoundry\\lib\\site-packages\\ScopeFoundry\\measurement.py", line 362, in _on_display_update_timer\n    self.update_display()\n', '  File "c:\\data\\python programs\\camera humanitas\\hyperspectralmicroscope\\hyperspectral_measure.py", line 93, in update_display\n    length = self.image_gen.frame_num.val\n', "AttributeError: 'HamamatsuHardware' object has no attribute 'frame_num'\n"]
2025-02-19T17:42:12|ERROR|hyperMeasure|hyper Failed to update figure1: 'HamamatsuHardware' object has no attribute 'frame_num'. ['Traceback (most recent call last):\n', '  File "C:\\ProgramData\\anaconda3\\envs\\scopefoundry\\lib\\site-packages\\ScopeFoundry\\measurement.py", line 362, in _on_display_update_timer\n    self.update_display()\n', '  File "c:\\data\\python programs\\camera humanitas\\hyperspectralmicroscope\\hyperspectral_measure.py", line 93, in update_display\n    length = self.image_gen.frame_num.val\n', "AttributeError: 'HamamatsuHardware' object has no attribute 'frame_num'\n"]
2025-02-19T17:42:12|ERROR|hyperMeasure|hyper Failed to update figure1: 'HamamatsuHardware' object has no attribute 'frame_num'. ['Traceback (most recent call last):\n', '  File "C:\\ProgramData\\anaconda3\\envs\\scopefoundry\\lib\\site-packages\\ScopeFoundry\\measurement.py", line 362, in _on_display_update_timer\n    self.update_display()\n', '  File "c:\\data\\python programs\\camera humanitas\\hyperspectralmicroscope\\hyperspectral_measure.py", line 93, in update_display\n    length = self.image_gen.frame_num.val\n', "AttributeError: 'HamamatsuHardware' object has no attribute 'frame_num'\n"]
2025-02-19T17:42:12|ERROR|hyperMeasure|hyper Failed to update figure1: 'HamamatsuHardware' object has no attribute 'frame_num'. ['Traceback (most recent call last):\n', '  File "C:\\ProgramData\\anaconda3\\envs\\scopefoundry\\lib\\site-packages\\ScopeFoundry\\measurement.py", line 362, in _on_display_update_timer\n    self.update_display()\n', '  File "c:\\data\\python programs\\camera humanitas\\hyperspectralmicroscope\\hyperspectral_measure.py", line 93, in update_display\n    length = self.image_gen.frame_num.val\n', "AttributeError: 'HamamatsuHardware' object has no attribute 'frame_num'\n"]
2025-02-19T17:42:12|ERROR|hyperMeasure|hyper Failed to update figure1: 'HamamatsuHardware' object has no attribute 'frame_num'. ['Traceback (most recent call last):\n', '  File "C:\\ProgramData\\anaconda3\\envs\\scopefoundry\\lib\\site-packages\\ScopeFoundry\\measurement.py", line 362, in _on_display_update_timer\n    self.update_display()\n', '  File "c:\\data\\python programs\\camera humanitas\\hyperspectralmicroscope\\hyperspectral_measure.py", line 93, in update_display\n    length = self.image_gen.frame_num.val\n', "AttributeError: 'HamamatsuHardware' object has no attribute 'frame_num'\n"]
2025-02-19T17:42:12|ERROR|hyperMeasure|hyper Failed to update figure1: 'HamamatsuHardware' object has no attribute 'frame_num'. ['Traceback (most recent call last):\n', '  File "C:\\ProgramData\\anaconda3\\envs\\scopefoundry\\lib\\site-packages\\ScopeFoundry\\measurement.py", line 362, in _on_display_update_timer\n    self.update_display()\n', '  File "c:\\data\\python programs\\camera humanitas\\hyperspectralmicroscope\\hyperspectral_measure.py", line 93, in update_display\n    length = self.image_gen.frame_num.val\n', "AttributeError: 'HamamatsuHardware' object has no attribute 'frame_num'\n"]
2025-02-19T17:42:12|ERROR|hyperMeasure|hyper Failed to update figure1: 'HamamatsuHardware' object has no attribute 'frame_num'. ['Traceback (most recent call last):\n', '  File "C:\\ProgramData\\anaconda3\\envs\\scopefoundry\\lib\\site-packages\\ScopeFoundry\\measurement.py", line 362, in _on_display_update_timer\n    self.update_display()\n', '  File "c:\\data\\python programs\\camera humanitas\\hyperspectralmicroscope\\hyperspectral_measure.py", line 93, in update_display\n    length = self.image_gen.frame_num.val\n', "AttributeError: 'HamamatsuHardware' object has no attribute 'frame_num'\n"]
2025-02-19T17:42:12|ERROR|hyperMeasure|hyper Failed to update figure1: 'HamamatsuHardware' object has no attribute 'frame_num'. ['Traceback (most recent call last):\n', '  File "C:\\ProgramData\\anaconda3\\envs\\scopefoundry\\lib\\site-packages\\ScopeFoundry\\measurement.py", line 362, in _on_display_update_timer\n    self.update_display()\n', '  File "c:\\data\\python programs\\camera humanitas\\hyperspectralmicroscope\\hyperspectral_measure.py", line 93, in update_display\n    length = self.image_gen.frame_num.val\n', "AttributeError: 'HamamatsuHardware' object has no attribute 'frame_num'\n"]
2025-02-19T17:42:13|ERROR|hyperMeasure|hyper Failed to update figure1: 'HamamatsuHardware' object has no attribute 'frame_num'. ['Traceback (most recent call last):\n', '  File "C:\\ProgramData\\anaconda3\\envs\\scopefoundry\\lib\\site-packages\\ScopeFoundry\\measurement.py", line 362, in _on_display_update_timer\n    self.update_display()\n', '  File "c:\\data\\python programs\\camera humanitas\\hyperspectralmicroscope\\hyperspectral_measure.py", line 93, in update_display\n    length = self.image_gen.frame_num.val\n', "AttributeError: 'HamamatsuHardware' object has no attribute 'frame_num'\n"]
2025-02-19T17:42:13|ERROR|hyperMeasure|hyper Failed to update figure1: 'HamamatsuHardware' object has no attribute 'frame_num'. ['Traceback (most recent call last):\n', '  File "C:\\ProgramData\\anaconda3\\envs\\scopefoundry\\lib\\site-packages\\ScopeFoundry\\measurement.py", line 362, in _on_display_update_timer\n    self.update_display()\n', '  File "c:\\data\\python programs\\camera humanitas\\hyperspectralmicroscope\\hyperspectral_measure.py", line 93, in update_display\n    length = self.image_gen.frame_num.val\n', "AttributeError: 'HamamatsuHardware' object has no attribute 'frame_num'\n"]
2025-02-19T17:42:13|ERROR|hyperMeasure|hyper Failed to update figure1: 'HamamatsuHardware' object has no attribute 'frame_num'. ['Traceback (most recent call last):\n', '  File "C:\\ProgramData\\anaconda3\\envs\\scopefoundry\\lib\\site-packages\\ScopeFoundry\\measurement.py", line 362, in _on_display_update_timer\n    self.update_display()\n', '  File "c:\\data\\python programs\\camera humanitas\\hyperspectralmicroscope\\hyperspectral_measure.py", line 93, in update_display\n    length = self.image_gen.frame_num.val\n', "AttributeError: 'HamamatsuHardware' object has no attribute 'frame_num'\n"]
2025-02-19T17:42:13|CRITICAL|root|Unhandled exception:Traceback (most recent call last):
  File "c:\data\python programs\camera humanitas\hyperspectralmicroscope\hyperspectral_measure.py", line 173, in run
    self.image_gen.camera.acq_start()
AttributeError: 'LoggedQuantity' object has no attribute 'acq_start'

During handling of the above exception, another exception occurred:

Traceback (most recent call last):
  File "C:\ProgramData\anaconda3\envs\scopefoundry\lib\site-packages\ScopeFoundry\measurement.py", line 27, in run
    self.measurement._thread_run()
  File "C:\ProgramData\anaconda3\envs\scopefoundry\lib\site-packages\ScopeFoundry\measurement.py", line 230, in _thread_run
    self.run()
  File "c:\data\python programs\camera humanitas\hyperspectralmicroscope\hyperspectral_measure.py", line 193, in run
    self.image_gen.camera.acq_stop()
AttributeError: 'LoggedQuantity' object has no attribute 'acq_stop'

2025-02-19T17:42:13|ERROR|hyperMeasure|hyper Failed to update figure1: 'HamamatsuHardware' object has no attribute 'frame_num'. ['Traceback (most recent call last):\n', '  File "C:\\ProgramData\\anaconda3\\envs\\scopefoundry\\lib\\site-packages\\ScopeFoundry\\measurement.py", line 362, in _on_display_update_timer\n    self.update_display()\n', '  File "c:\\data\\python programs\\camera humanitas\\hyperspectralmicroscope\\hyperspectral_measure.py", line 93, in update_display\n    length = self.image_gen.frame_num.val\n', "AttributeError: 'HamamatsuHardware' object has no attribute 'frame_num'\n"]
2025-02-19T17:42:56|ERROR|hyperMeasure|hyper Failed to update figure1: 'HamamatsuHardware' object has no attribute 'frame_num'. ['Traceback (most recent call last):\n', '  File "C:\\ProgramData\\anaconda3\\envs\\scopefoundry\\lib\\site-packages\\ScopeFoundry\\measurement.py", line 362, in _on_display_update_timer\n    self.update_display()\n', '  File "c:\\data\\python programs\\camera humanitas\\hyperspectralmicroscope\\hyperspectral_measure.py", line 93, in update_display\n    length = self.image_gen.frame_num.val\n', "AttributeError: 'HamamatsuHardware' object has no attribute 'frame_num'\n"]
2025-02-19T17:42:56|ERROR|hyperMeasure|hyper Failed to update figure1: 'HamamatsuHardware' object has no attribute 'frame_num'. ['Traceback (most recent call last):\n', '  File "C:\\ProgramData\\anaconda3\\envs\\scopefoundry\\lib\\site-packages\\ScopeFoundry\\measurement.py", line 362, in _on_display_update_timer\n    self.update_display()\n', '  File "c:\\data\\python programs\\camera humanitas\\hyperspectralmicroscope\\hyperspectral_measure.py", line 93, in update_display\n    length = self.image_gen.frame_num.val\n', "AttributeError: 'HamamatsuHardware' object has no attribute 'frame_num'\n"]
2025-02-19T17:42:56|ERROR|hyperMeasure|hyper Failed to update figure1: 'HamamatsuHardware' object has no attribute 'frame_num'. ['Traceback (most recent call last):\n', '  File "C:\\ProgramData\\anaconda3\\envs\\scopefoundry\\lib\\site-packages\\ScopeFoundry\\measurement.py", line 362, in _on_display_update_timer\n    self.update_display()\n', '  File "c:\\data\\python programs\\camera humanitas\\hyperspectralmicroscope\\hyperspectral_measure.py", line 93, in update_display\n    length = self.image_gen.frame_num.val\n', "AttributeError: 'HamamatsuHardware' object has no attribute 'frame_num'\n"]
2025-02-19T17:42:56|ERROR|hyperMeasure|hyper Failed to update figure1: 'HamamatsuHardware' object has no attribute 'frame_num'. ['Traceback (most recent call last):\n', '  File "C:\\ProgramData\\anaconda3\\envs\\scopefoundry\\lib\\site-packages\\ScopeFoundry\\measurement.py", line 362, in _on_display_update_timer\n    self.update_display()\n', '  File "c:\\data\\python programs\\camera humanitas\\hyperspectralmicroscope\\hyperspectral_measure.py", line 93, in update_display\n    length = self.image_gen.frame_num.val\n', "AttributeError: 'HamamatsuHardware' object has no attribute 'frame_num'\n"]
2025-02-19T17:42:57|ERROR|hyperMeasure|hyper Failed to update figure1: 'HamamatsuHardware' object has no attribute 'frame_num'. ['Traceback (most recent call last):\n', '  File "C:\\ProgramData\\anaconda3\\envs\\scopefoundry\\lib\\site-packages\\ScopeFoundry\\measurement.py", line 362, in _on_display_update_timer\n    self.update_display()\n', '  File "c:\\data\\python programs\\camera humanitas\\hyperspectralmicroscope\\hyperspectral_measure.py", line 93, in update_display\n    length = self.image_gen.frame_num.val\n', "AttributeError: 'HamamatsuHardware' object has no attribute 'frame_num'\n"]
2025-02-19T17:42:57|ERROR|hyperMeasure|hyper Failed to update figure1: 'HamamatsuHardware' object has no attribute 'frame_num'. ['Traceback (most recent call last):\n', '  File "C:\\ProgramData\\anaconda3\\envs\\scopefoundry\\lib\\site-packages\\ScopeFoundry\\measurement.py", line 362, in _on_display_update_timer\n    self.update_display()\n', '  File "c:\\data\\python programs\\camera humanitas\\hyperspectralmicroscope\\hyperspectral_measure.py", line 93, in update_display\n    length = self.image_gen.frame_num.val\n', "AttributeError: 'HamamatsuHardware' object has no attribute 'frame_num'\n"]
2025-02-19T17:42:57|ERROR|hyperMeasure|hyper Failed to update figure1: 'HamamatsuHardware' object has no attribute 'frame_num'. ['Traceback (most recent call last):\n', '  File "C:\\ProgramData\\anaconda3\\envs\\scopefoundry\\lib\\site-packages\\ScopeFoundry\\measurement.py", line 362, in _on_display_update_timer\n    self.update_display()\n', '  File "c:\\data\\python programs\\camera humanitas\\hyperspectralmicroscope\\hyperspectral_measure.py", line 93, in update_display\n    length = self.image_gen.frame_num.val\n', "AttributeError: 'HamamatsuHardware' object has no attribute 'frame_num'\n"]
2025-02-19T17:42:57|ERROR|hyperMeasure|hyper Failed to update figure1: 'HamamatsuHardware' object has no attribute 'frame_num'. ['Traceback (most recent call last):\n', '  File "C:\\ProgramData\\anaconda3\\envs\\scopefoundry\\lib\\site-packages\\ScopeFoundry\\measurement.py", line 362, in _on_display_update_timer\n    self.update_display()\n', '  File "c:\\data\\python programs\\camera humanitas\\hyperspectralmicroscope\\hyperspectral_measure.py", line 93, in update_display\n    length = self.image_gen.frame_num.val\n', "AttributeError: 'HamamatsuHardware' object has no attribute 'frame_num'\n"]
2025-02-19T17:42:58|ERROR|hyperMeasure|hyper Failed to update figure1: 'HamamatsuHardware' object has no attribute 'frame_num'. ['Traceback (most recent call last):\n', '  File "C:\\ProgramData\\anaconda3\\envs\\scopefoundry\\lib\\site-packages\\ScopeFoundry\\measurement.py", line 362, in _on_display_update_timer\n    self.update_display()\n', '  File "c:\\data\\python programs\\camera humanitas\\hyperspectralmicroscope\\hyperspectral_measure.py", line 93, in update_display\n    length = self.image_gen.frame_num.val\n', "AttributeError: 'HamamatsuHardware' object has no attribute 'frame_num'\n"]
2025-02-19T17:42:58|ERROR|hyperMeasure|hyper Failed to update figure1: 'HamamatsuHardware' object has no attribute 'frame_num'. ['Traceback (most recent call last):\n', '  File "C:\\ProgramData\\anaconda3\\envs\\scopefoundry\\lib\\site-packages\\ScopeFoundry\\measurement.py", line 362, in _on_display_update_timer\n    self.update_display()\n', '  File "c:\\data\\python programs\\camera humanitas\\hyperspectralmicroscope\\hyperspectral_measure.py", line 93, in update_display\n    length = self.image_gen.frame_num.val\n', "AttributeError: 'HamamatsuHardware' object has no attribute 'frame_num'\n"]
2025-02-19T17:42:58|ERROR|hyperMeasure|hyper Failed to update figure1: 'HamamatsuHardware' object has no attribute 'frame_num'. ['Traceback (most recent call last):\n', '  File "C:\\ProgramData\\anaconda3\\envs\\scopefoundry\\lib\\site-packages\\ScopeFoundry\\measurement.py", line 362, in _on_display_update_timer\n    self.update_display()\n', '  File "c:\\data\\python programs\\camera humanitas\\hyperspectralmicroscope\\hyperspectral_measure.py", line 93, in update_display\n    length = self.image_gen.frame_num.val\n', "AttributeError: 'HamamatsuHardware' object has no attribute 'frame_num'\n"]
2025-02-19T17:42:58|ERROR|hyperMeasure|hyper Failed to update figure1: 'HamamatsuHardware' object has no attribute 'frame_num'. ['Traceback (most recent call last):\n', '  File "C:\\ProgramData\\anaconda3\\envs\\scopefoundry\\lib\\site-packages\\ScopeFoundry\\measurement.py", line 362, in _on_display_update_timer\n    self.update_display()\n', '  File "c:\\data\\python programs\\camera humanitas\\hyperspectralmicroscope\\hyperspectral_measure.py", line 93, in update_display\n    length = self.image_gen.frame_num.val\n', "AttributeError: 'HamamatsuHardware' object has no attribute 'frame_num'\n"]
2025-02-19T17:42:59|ERROR|hyperMeasure|hyper Failed to update figure1: 'HamamatsuHardware' object has no attribute 'frame_num'. ['Traceback (most recent call last):\n', '  File "C:\\ProgramData\\anaconda3\\envs\\scopefoundry\\lib\\site-packages\\ScopeFoundry\\measurement.py", line 362, in _on_display_update_timer\n    self.update_display()\n', '  File "c:\\data\\python programs\\camera humanitas\\hyperspectralmicroscope\\hyperspectral_measure.py", line 93, in update_display\n    length = self.image_gen.frame_num.val\n', "AttributeError: 'HamamatsuHardware' object has no attribute 'frame_num'\n"]
2025-02-19T17:42:59|ERROR|hyperMeasure|hyper Failed to update figure1: 'HamamatsuHardware' object has no attribute 'frame_num'. ['Traceback (most recent call last):\n', '  File "C:\\ProgramData\\anaconda3\\envs\\scopefoundry\\lib\\site-packages\\ScopeFoundry\\measurement.py", line 362, in _on_display_update_timer\n    self.update_display()\n', '  File "c:\\data\\python programs\\camera humanitas\\hyperspectralmicroscope\\hyperspectral_measure.py", line 93, in update_display\n    length = self.image_gen.frame_num.val\n', "AttributeError: 'HamamatsuHardware' object has no attribute 'frame_num'\n"]
2025-02-19T17:42:59|ERROR|hyperMeasure|hyper Failed to update figure1: 'HamamatsuHardware' object has no attribute 'frame_num'. ['Traceback (most recent call last):\n', '  File "C:\\ProgramData\\anaconda3\\envs\\scopefoundry\\lib\\site-packages\\ScopeFoundry\\measurement.py", line 362, in _on_display_update_timer\n    self.update_display()\n', '  File "c:\\data\\python programs\\camera humanitas\\hyperspectralmicroscope\\hyperspectral_measure.py", line 93, in update_display\n    length = self.image_gen.frame_num.val\n', "AttributeError: 'HamamatsuHardware' object has no attribute 'frame_num'\n"]
2025-02-19T17:42:59|ERROR|hyperMeasure|hyper Failed to update figure1: 'HamamatsuHardware' object has no attribute 'frame_num'. ['Traceback (most recent call last):\n', '  File "C:\\ProgramData\\anaconda3\\envs\\scopefoundry\\lib\\site-packages\\ScopeFoundry\\measurement.py", line 362, in _on_display_update_timer\n    self.update_display()\n', '  File "c:\\data\\python programs\\camera humanitas\\hyperspectralmicroscope\\hyperspectral_measure.py", line 93, in update_display\n    length = self.image_gen.frame_num.val\n', "AttributeError: 'HamamatsuHardware' object has no attribute 'frame_num'\n"]
2025-02-19T17:43:00|ERROR|hyperMeasure|hyper Failed to update figure1: 'HamamatsuHardware' object has no attribute 'frame_num'. ['Traceback (most recent call last):\n', '  File "C:\\ProgramData\\anaconda3\\envs\\scopefoundry\\lib\\site-packages\\ScopeFoundry\\measurement.py", line 362, in _on_display_update_timer\n    self.update_display()\n', '  File "c:\\data\\python programs\\camera humanitas\\hyperspectralmicroscope\\hyperspectral_measure.py", line 93, in update_display\n    length = self.image_gen.frame_num.val\n', "AttributeError: 'HamamatsuHardware' object has no attribute 'frame_num'\n"]
2025-02-19T17:43:00|ERROR|hyperMeasure|hyper Failed to update figure1: 'HamamatsuHardware' object has no attribute 'frame_num'. ['Traceback (most recent call last):\n', '  File "C:\\ProgramData\\anaconda3\\envs\\scopefoundry\\lib\\site-packages\\ScopeFoundry\\measurement.py", line 362, in _on_display_update_timer\n    self.update_display()\n', '  File "c:\\data\\python programs\\camera humanitas\\hyperspectralmicroscope\\hyperspectral_measure.py", line 93, in update_display\n    length = self.image_gen.frame_num.val\n', "AttributeError: 'HamamatsuHardware' object has no attribute 'frame_num'\n"]
2025-02-19T17:43:00|ERROR|hyperMeasure|hyper Failed to update figure1: 'HamamatsuHardware' object has no attribute 'frame_num'. ['Traceback (most recent call last):\n', '  File "C:\\ProgramData\\anaconda3\\envs\\scopefoundry\\lib\\site-packages\\ScopeFoundry\\measurement.py", line 362, in _on_display_update_timer\n    self.update_display()\n', '  File "c:\\data\\python programs\\camera humanitas\\hyperspectralmicroscope\\hyperspectral_measure.py", line 93, in update_display\n    length = self.image_gen.frame_num.val\n', "AttributeError: 'HamamatsuHardware' object has no attribute 'frame_num'\n"]
2025-02-19T17:43:00|ERROR|hyperMeasure|hyper Failed to update figure1: 'HamamatsuHardware' object has no attribute 'frame_num'. ['Traceback (most recent call last):\n', '  File "C:\\ProgramData\\anaconda3\\envs\\scopefoundry\\lib\\site-packages\\ScopeFoundry\\measurement.py", line 362, in _on_display_update_timer\n    self.update_display()\n', '  File "c:\\data\\python programs\\camera humanitas\\hyperspectralmicroscope\\hyperspectral_measure.py", line 93, in update_display\n    length = self.image_gen.frame_num.val\n', "AttributeError: 'HamamatsuHardware' object has no attribute 'frame_num'\n"]
2025-02-19T17:43:01|ERROR|hyperMeasure|hyper Failed to update figure1: 'HamamatsuHardware' object has no attribute 'frame_num'. ['Traceback (most recent call last):\n', '  File "C:\\ProgramData\\anaconda3\\envs\\scopefoundry\\lib\\site-packages\\ScopeFoundry\\measurement.py", line 362, in _on_display_update_timer\n    self.update_display()\n', '  File "c:\\data\\python programs\\camera humanitas\\hyperspectralmicroscope\\hyperspectral_measure.py", line 93, in update_display\n    length = self.image_gen.frame_num.val\n', "AttributeError: 'HamamatsuHardware' object has no attribute 'frame_num'\n"]
2025-02-19T17:43:01|ERROR|hyperMeasure|hyper Failed to update figure1: 'HamamatsuHardware' object has no attribute 'frame_num'. ['Traceback (most recent call last):\n', '  File "C:\\ProgramData\\anaconda3\\envs\\scopefoundry\\lib\\site-packages\\ScopeFoundry\\measurement.py", line 362, in _on_display_update_timer\n    self.update_display()\n', '  File "c:\\data\\python programs\\camera humanitas\\hyperspectralmicroscope\\hyperspectral_measure.py", line 93, in update_display\n    length = self.image_gen.frame_num.val\n', "AttributeError: 'HamamatsuHardware' object has no attribute 'frame_num'\n"]
2025-02-19T17:43:01|ERROR|hyperMeasure|hyper Failed to update figure1: 'HamamatsuHardware' object has no attribute 'frame_num'. ['Traceback (most recent call last):\n', '  File "C:\\ProgramData\\anaconda3\\envs\\scopefoundry\\lib\\site-packages\\ScopeFoundry\\measurement.py", line 362, in _on_display_update_timer\n    self.update_display()\n', '  File "c:\\data\\python programs\\camera humanitas\\hyperspectralmicroscope\\hyperspectral_measure.py", line 93, in update_display\n    length = self.image_gen.frame_num.val\n', "AttributeError: 'HamamatsuHardware' object has no attribute 'frame_num'\n"]
2025-02-19T17:43:01|ERROR|hyperMeasure|hyper Failed to update figure1: 'HamamatsuHardware' object has no attribute 'frame_num'. ['Traceback (most recent call last):\n', '  File "C:\\ProgramData\\anaconda3\\envs\\scopefoundry\\lib\\site-packages\\ScopeFoundry\\measurement.py", line 362, in _on_display_update_timer\n    self.update_display()\n', '  File "c:\\data\\python programs\\camera humanitas\\hyperspectralmicroscope\\hyperspectral_measure.py", line 93, in update_display\n    length = self.image_gen.frame_num.val\n', "AttributeError: 'HamamatsuHardware' object has no attribute 'frame_num'\n"]
2025-02-19T17:43:02|ERROR|hyperMeasure|hyper Failed to update figure1: 'HamamatsuHardware' object has no attribute 'frame_num'. ['Traceback (most recent call last):\n', '  File "C:\\ProgramData\\anaconda3\\envs\\scopefoundry\\lib\\site-packages\\ScopeFoundry\\measurement.py", line 362, in _on_display_update_timer\n    self.update_display()\n', '  File "c:\\data\\python programs\\camera humanitas\\hyperspectralmicroscope\\hyperspectral_measure.py", line 93, in update_display\n    length = self.image_gen.frame_num.val\n', "AttributeError: 'HamamatsuHardware' object has no attribute 'frame_num'\n"]
2025-02-19T17:43:02|ERROR|hyperMeasure|hyper Failed to update figure1: 'HamamatsuHardware' object has no attribute 'frame_num'. ['Traceback (most recent call last):\n', '  File "C:\\ProgramData\\anaconda3\\envs\\scopefoundry\\lib\\site-packages\\ScopeFoundry\\measurement.py", line 362, in _on_display_update_timer\n    self.update_display()\n', '  File "c:\\data\\python programs\\camera humanitas\\hyperspectralmicroscope\\hyperspectral_measure.py", line 93, in update_display\n    length = self.image_gen.frame_num.val\n', "AttributeError: 'HamamatsuHardware' object has no attribute 'frame_num'\n"]
2025-02-19T17:43:02|ERROR|hyperMeasure|hyper Failed to update figure1: 'HamamatsuHardware' object has no attribute 'frame_num'. ['Traceback (most recent call last):\n', '  File "C:\\ProgramData\\anaconda3\\envs\\scopefoundry\\lib\\site-packages\\ScopeFoundry\\measurement.py", line 362, in _on_display_update_timer\n    self.update_display()\n', '  File "c:\\data\\python programs\\camera humanitas\\hyperspectralmicroscope\\hyperspectral_measure.py", line 93, in update_display\n    length = self.image_gen.frame_num.val\n', "AttributeError: 'HamamatsuHardware' object has no attribute 'frame_num'\n"]
2025-02-19T17:43:02|ERROR|hyperMeasure|hyper Failed to update figure1: 'HamamatsuHardware' object has no attribute 'frame_num'. ['Traceback (most recent call last):\n', '  File "C:\\ProgramData\\anaconda3\\envs\\scopefoundry\\lib\\site-packages\\ScopeFoundry\\measurement.py", line 362, in _on_display_update_timer\n    self.update_display()\n', '  File "c:\\data\\python programs\\camera humanitas\\hyperspectralmicroscope\\hyperspectral_measure.py", line 93, in update_display\n    length = self.image_gen.frame_num.val\n', "AttributeError: 'HamamatsuHardware' object has no attribute 'frame_num'\n"]
2025-02-19T17:43:03|ERROR|hyperMeasure|hyper Failed to update figure1: 'HamamatsuHardware' object has no attribute 'frame_num'. ['Traceback (most recent call last):\n', '  File "C:\\ProgramData\\anaconda3\\envs\\scopefoundry\\lib\\site-packages\\ScopeFoundry\\measurement.py", line 362, in _on_display_update_timer\n    self.update_display()\n', '  File "c:\\data\\python programs\\camera humanitas\\hyperspectralmicroscope\\hyperspectral_measure.py", line 93, in update_display\n    length = self.image_gen.frame_num.val\n', "AttributeError: 'HamamatsuHardware' object has no attribute 'frame_num'\n"]
2025-02-19T17:43:03|ERROR|hyperMeasure|hyper Failed to update figure1: 'HamamatsuHardware' object has no attribute 'frame_num'. ['Traceback (most recent call last):\n', '  File "C:\\ProgramData\\anaconda3\\envs\\scopefoundry\\lib\\site-packages\\ScopeFoundry\\measurement.py", line 362, in _on_display_update_timer\n    self.update_display()\n', '  File "c:\\data\\python programs\\camera humanitas\\hyperspectralmicroscope\\hyperspectral_measure.py", line 93, in update_display\n    length = self.image_gen.frame_num.val\n', "AttributeError: 'HamamatsuHardware' object has no attribute 'frame_num'\n"]
2025-02-19T17:43:03|ERROR|hyperMeasure|hyper Failed to update figure1: 'HamamatsuHardware' object has no attribute 'frame_num'. ['Traceback (most recent call last):\n', '  File "C:\\ProgramData\\anaconda3\\envs\\scopefoundry\\lib\\site-packages\\ScopeFoundry\\measurement.py", line 362, in _on_display_update_timer\n    self.update_display()\n', '  File "c:\\data\\python programs\\camera humanitas\\hyperspectralmicroscope\\hyperspectral_measure.py", line 93, in update_display\n    length = self.image_gen.frame_num.val\n', "AttributeError: 'HamamatsuHardware' object has no attribute 'frame_num'\n"]
2025-02-19T17:43:03|ERROR|hyperMeasure|hyper Failed to update figure1: 'HamamatsuHardware' object has no attribute 'frame_num'. ['Traceback (most recent call last):\n', '  File "C:\\ProgramData\\anaconda3\\envs\\scopefoundry\\lib\\site-packages\\ScopeFoundry\\measurement.py", line 362, in _on_display_update_timer\n    self.update_display()\n', '  File "c:\\data\\python programs\\camera humanitas\\hyperspectralmicroscope\\hyperspectral_measure.py", line 93, in update_display\n    length = self.image_gen.frame_num.val\n', "AttributeError: 'HamamatsuHardware' object has no attribute 'frame_num'\n"]
2025-02-19T17:43:04|ERROR|hyperMeasure|hyper Failed to update figure1: 'HamamatsuHardware' object has no attribute 'frame_num'. ['Traceback (most recent call last):\n', '  File "C:\\ProgramData\\anaconda3\\envs\\scopefoundry\\lib\\site-packages\\ScopeFoundry\\measurement.py", line 362, in _on_display_update_timer\n    self.update_display()\n', '  File "c:\\data\\python programs\\camera humanitas\\hyperspectralmicroscope\\hyperspectral_measure.py", line 93, in update_display\n    length = self.image_gen.frame_num.val\n', "AttributeError: 'HamamatsuHardware' object has no attribute 'frame_num'\n"]
2025-02-19T17:43:04|ERROR|hyperMeasure|hyper Failed to update figure1: 'HamamatsuHardware' object has no attribute 'frame_num'. ['Traceback (most recent call last):\n', '  File "C:\\ProgramData\\anaconda3\\envs\\scopefoundry\\lib\\site-packages\\ScopeFoundry\\measurement.py", line 362, in _on_display_update_timer\n    self.update_display()\n', '  File "c:\\data\\python programs\\camera humanitas\\hyperspectralmicroscope\\hyperspectral_measure.py", line 93, in update_display\n    length = self.image_gen.frame_num.val\n', "AttributeError: 'HamamatsuHardware' object has no attribute 'frame_num'\n"]
2025-02-19T17:43:04|ERROR|hyperMeasure|hyper Failed to update figure1: 'HamamatsuHardware' object has no attribute 'frame_num'. ['Traceback (most recent call last):\n', '  File "C:\\ProgramData\\anaconda3\\envs\\scopefoundry\\lib\\site-packages\\ScopeFoundry\\measurement.py", line 362, in _on_display_update_timer\n    self.update_display()\n', '  File "c:\\data\\python programs\\camera humanitas\\hyperspectralmicroscope\\hyperspectral_measure.py", line 93, in update_display\n    length = self.image_gen.frame_num.val\n', "AttributeError: 'HamamatsuHardware' object has no attribute 'frame_num'\n"]
2025-02-19T17:43:04|ERROR|hyperMeasure|hyper Failed to update figure1: 'HamamatsuHardware' object has no attribute 'frame_num'. ['Traceback (most recent call last):\n', '  File "C:\\ProgramData\\anaconda3\\envs\\scopefoundry\\lib\\site-packages\\ScopeFoundry\\measurement.py", line 362, in _on_display_update_timer\n    self.update_display()\n', '  File "c:\\data\\python programs\\camera humanitas\\hyperspectralmicroscope\\hyperspectral_measure.py", line 93, in update_display\n    length = self.image_gen.frame_num.val\n', "AttributeError: 'HamamatsuHardware' object has no attribute 'frame_num'\n"]
2025-02-19T17:43:05|ERROR|hyperMeasure|hyper Failed to update figure1: 'HamamatsuHardware' object has no attribute 'frame_num'. ['Traceback (most recent call last):\n', '  File "C:\\ProgramData\\anaconda3\\envs\\scopefoundry\\lib\\site-packages\\ScopeFoundry\\measurement.py", line 362, in _on_display_update_timer\n    self.update_display()\n', '  File "c:\\data\\python programs\\camera humanitas\\hyperspectralmicroscope\\hyperspectral_measure.py", line 93, in update_display\n    length = self.image_gen.frame_num.val\n', "AttributeError: 'HamamatsuHardware' object has no attribute 'frame_num'\n"]
2025-02-19T17:43:05|ERROR|hyperMeasure|hyper Failed to update figure1: 'HamamatsuHardware' object has no attribute 'frame_num'. ['Traceback (most recent call last):\n', '  File "C:\\ProgramData\\anaconda3\\envs\\scopefoundry\\lib\\site-packages\\ScopeFoundry\\measurement.py", line 362, in _on_display_update_timer\n    self.update_display()\n', '  File "c:\\data\\python programs\\camera humanitas\\hyperspectralmicroscope\\hyperspectral_measure.py", line 93, in update_display\n    length = self.image_gen.frame_num.val\n', "AttributeError: 'HamamatsuHardware' object has no attribute 'frame_num'\n"]
2025-02-19T17:43:05|ERROR|hyperMeasure|hyper Failed to update figure1: 'HamamatsuHardware' object has no attribute 'frame_num'. ['Traceback (most recent call last):\n', '  File "C:\\ProgramData\\anaconda3\\envs\\scopefoundry\\lib\\site-packages\\ScopeFoundry\\measurement.py", line 362, in _on_display_update_timer\n    self.update_display()\n', '  File "c:\\data\\python programs\\camera humanitas\\hyperspectralmicroscope\\hyperspectral_measure.py", line 93, in update_display\n    length = self.image_gen.frame_num.val\n', "AttributeError: 'HamamatsuHardware' object has no attribute 'frame_num'\n"]
2025-02-19T17:43:05|ERROR|hyperMeasure|hyper Failed to update figure1: 'HamamatsuHardware' object has no attribute 'frame_num'. ['Traceback (most recent call last):\n', '  File "C:\\ProgramData\\anaconda3\\envs\\scopefoundry\\lib\\site-packages\\ScopeFoundry\\measurement.py", line 362, in _on_display_update_timer\n    self.update_display()\n', '  File "c:\\data\\python programs\\camera humanitas\\hyperspectralmicroscope\\hyperspectral_measure.py", line 93, in update_display\n    length = self.image_gen.frame_num.val\n', "AttributeError: 'HamamatsuHardware' object has no attribute 'frame_num'\n"]
2025-02-19T17:43:06|ERROR|hyperMeasure|hyper Failed to update figure1: 'HamamatsuHardware' object has no attribute 'frame_num'. ['Traceback (most recent call last):\n', '  File "C:\\ProgramData\\anaconda3\\envs\\scopefoundry\\lib\\site-packages\\ScopeFoundry\\measurement.py", line 362, in _on_display_update_timer\n    self.update_display()\n', '  File "c:\\data\\python programs\\camera humanitas\\hyperspectralmicroscope\\hyperspectral_measure.py", line 93, in update_display\n    length = self.image_gen.frame_num.val\n', "AttributeError: 'HamamatsuHardware' object has no attribute 'frame_num'\n"]
2025-02-19T17:43:06|ERROR|hyperMeasure|hyper Failed to update figure1: 'HamamatsuHardware' object has no attribute 'frame_num'. ['Traceback (most recent call last):\n', '  File "C:\\ProgramData\\anaconda3\\envs\\scopefoundry\\lib\\site-packages\\ScopeFoundry\\measurement.py", line 362, in _on_display_update_timer\n    self.update_display()\n', '  File "c:\\data\\python programs\\camera humanitas\\hyperspectralmicroscope\\hyperspectral_measure.py", line 93, in update_display\n    length = self.image_gen.frame_num.val\n', "AttributeError: 'HamamatsuHardware' object has no attribute 'frame_num'\n"]
2025-02-19T17:43:06|ERROR|hyperMeasure|hyper Failed to update figure1: 'HamamatsuHardware' object has no attribute 'frame_num'. ['Traceback (most recent call last):\n', '  File "C:\\ProgramData\\anaconda3\\envs\\scopefoundry\\lib\\site-packages\\ScopeFoundry\\measurement.py", line 362, in _on_display_update_timer\n    self.update_display()\n', '  File "c:\\data\\python programs\\camera humanitas\\hyperspectralmicroscope\\hyperspectral_measure.py", line 93, in update_display\n    length = self.image_gen.frame_num.val\n', "AttributeError: 'HamamatsuHardware' object has no attribute 'frame_num'\n"]
2025-02-19T17:43:06|ERROR|hyperMeasure|hyper Failed to update figure1: 'HamamatsuHardware' object has no attribute 'frame_num'. ['Traceback (most recent call last):\n', '  File "C:\\ProgramData\\anaconda3\\envs\\scopefoundry\\lib\\site-packages\\ScopeFoundry\\measurement.py", line 362, in _on_display_update_timer\n    self.update_display()\n', '  File "c:\\data\\python programs\\camera humanitas\\hyperspectralmicroscope\\hyperspectral_measure.py", line 93, in update_display\n    length = self.image_gen.frame_num.val\n', "AttributeError: 'HamamatsuHardware' object has no attribute 'frame_num'\n"]
2025-02-19T17:43:07|ERROR|hyperMeasure|hyper Failed to update figure1: 'HamamatsuHardware' object has no attribute 'frame_num'. ['Traceback (most recent call last):\n', '  File "C:\\ProgramData\\anaconda3\\envs\\scopefoundry\\lib\\site-packages\\ScopeFoundry\\measurement.py", line 362, in _on_display_update_timer\n    self.update_display()\n', '  File "c:\\data\\python programs\\camera humanitas\\hyperspectralmicroscope\\hyperspectral_measure.py", line 93, in update_display\n    length = self.image_gen.frame_num.val\n', "AttributeError: 'HamamatsuHardware' object has no attribute 'frame_num'\n"]
2025-02-19T17:43:07|ERROR|hyperMeasure|hyper Failed to update figure1: 'HamamatsuHardware' object has no attribute 'frame_num'. ['Traceback (most recent call last):\n', '  File "C:\\ProgramData\\anaconda3\\envs\\scopefoundry\\lib\\site-packages\\ScopeFoundry\\measurement.py", line 362, in _on_display_update_timer\n    self.update_display()\n', '  File "c:\\data\\python programs\\camera humanitas\\hyperspectralmicroscope\\hyperspectral_measure.py", line 93, in update_display\n    length = self.image_gen.frame_num.val\n', "AttributeError: 'HamamatsuHardware' object has no attribute 'frame_num'\n"]
2025-02-19T17:43:07|ERROR|hyperMeasure|hyper Failed to update figure1: 'HamamatsuHardware' object has no attribute 'frame_num'. ['Traceback (most recent call last):\n', '  File "C:\\ProgramData\\anaconda3\\envs\\scopefoundry\\lib\\site-packages\\ScopeFoundry\\measurement.py", line 362, in _on_display_update_timer\n    self.update_display()\n', '  File "c:\\data\\python programs\\camera humanitas\\hyperspectralmicroscope\\hyperspectral_measure.py", line 93, in update_display\n    length = self.image_gen.frame_num.val\n', "AttributeError: 'HamamatsuHardware' object has no attribute 'frame_num'\n"]
2025-02-19T17:43:07|ERROR|hyperMeasure|hyper Failed to update figure1: 'HamamatsuHardware' object has no attribute 'frame_num'. ['Traceback (most recent call last):\n', '  File "C:\\ProgramData\\anaconda3\\envs\\scopefoundry\\lib\\site-packages\\ScopeFoundry\\measurement.py", line 362, in _on_display_update_timer\n    self.update_display()\n', '  File "c:\\data\\python programs\\camera humanitas\\hyperspectralmicroscope\\hyperspectral_measure.py", line 93, in update_display\n    length = self.image_gen.frame_num.val\n', "AttributeError: 'HamamatsuHardware' object has no attribute 'frame_num'\n"]
2025-02-19T17:43:08|ERROR|hyperMeasure|hyper Failed to update figure1: 'HamamatsuHardware' object has no attribute 'frame_num'. ['Traceback (most recent call last):\n', '  File "C:\\ProgramData\\anaconda3\\envs\\scopefoundry\\lib\\site-packages\\ScopeFoundry\\measurement.py", line 362, in _on_display_update_timer\n    self.update_display()\n', '  File "c:\\data\\python programs\\camera humanitas\\hyperspectralmicroscope\\hyperspectral_measure.py", line 93, in update_display\n    length = self.image_gen.frame_num.val\n', "AttributeError: 'HamamatsuHardware' object has no attribute 'frame_num'\n"]
2025-02-19T17:43:08|ERROR|hyperMeasure|hyper Failed to update figure1: 'HamamatsuHardware' object has no attribute 'frame_num'. ['Traceback (most recent call last):\n', '  File "C:\\ProgramData\\anaconda3\\envs\\scopefoundry\\lib\\site-packages\\ScopeFoundry\\measurement.py", line 362, in _on_display_update_timer\n    self.update_display()\n', '  File "c:\\data\\python programs\\camera humanitas\\hyperspectralmicroscope\\hyperspectral_measure.py", line 93, in update_display\n    length = self.image_gen.frame_num.val\n', "AttributeError: 'HamamatsuHardware' object has no attribute 'frame_num'\n"]
2025-02-19T17:43:08|ERROR|hyperMeasure|hyper Failed to update figure1: 'HamamatsuHardware' object has no attribute 'frame_num'. ['Traceback (most recent call last):\n', '  File "C:\\ProgramData\\anaconda3\\envs\\scopefoundry\\lib\\site-packages\\ScopeFoundry\\measurement.py", line 362, in _on_display_update_timer\n    self.update_display()\n', '  File "c:\\data\\python programs\\camera humanitas\\hyperspectralmicroscope\\hyperspectral_measure.py", line 93, in update_display\n    length = self.image_gen.frame_num.val\n', "AttributeError: 'HamamatsuHardware' object has no attribute 'frame_num'\n"]
2025-02-19T17:43:08|ERROR|hyperMeasure|hyper Failed to update figure1: 'HamamatsuHardware' object has no attribute 'frame_num'. ['Traceback (most recent call last):\n', '  File "C:\\ProgramData\\anaconda3\\envs\\scopefoundry\\lib\\site-packages\\ScopeFoundry\\measurement.py", line 362, in _on_display_update_timer\n    self.update_display()\n', '  File "c:\\data\\python programs\\camera humanitas\\hyperspectralmicroscope\\hyperspectral_measure.py", line 93, in update_display\n    length = self.image_gen.frame_num.val\n', "AttributeError: 'HamamatsuHardware' object has no attribute 'frame_num'\n"]
2025-02-19T17:43:09|CRITICAL|root|Unhandled exception:Traceback (most recent call last):
  File "c:\data\python programs\camera humanitas\hyperspectralmicroscope\hyperspectral_measure.py", line 173, in run
    self.image_gen.camera.acq_start()
AttributeError: 'LoggedQuantity' object has no attribute 'acq_start'

During handling of the above exception, another exception occurred:

Traceback (most recent call last):
  File "C:\ProgramData\anaconda3\envs\scopefoundry\lib\site-packages\ScopeFoundry\measurement.py", line 27, in run
    self.measurement._thread_run()
  File "C:\ProgramData\anaconda3\envs\scopefoundry\lib\site-packages\ScopeFoundry\measurement.py", line 230, in _thread_run
    self.run()
  File "c:\data\python programs\camera humanitas\hyperspectralmicroscope\hyperspectral_measure.py", line 193, in run
    self.image_gen.camera.acq_stop()
AttributeError: 'LoggedQuantity' object has no attribute 'acq_stop'

2025-02-19T17:43:09|ERROR|hyperMeasure|hyper Failed to update figure1: 'HamamatsuHardware' object has no attribute 'frame_num'. ['Traceback (most recent call last):\n', '  File "C:\\ProgramData\\anaconda3\\envs\\scopefoundry\\lib\\site-packages\\ScopeFoundry\\measurement.py", line 362, in _on_display_update_timer\n    self.update_display()\n', '  File "c:\\data\\python programs\\camera humanitas\\hyperspectralmicroscope\\hyperspectral_measure.py", line 93, in update_display\n    length = self.image_gen.frame_num.val\n', "AttributeError: 'HamamatsuHardware' object has no attribute 'frame_num'\n"]
2025-02-19T17:43:09|ERROR|hyperMeasure|hyper Failed to update figure1: 'HamamatsuHardware' object has no attribute 'frame_num'. ['Traceback (most recent call last):\n', '  File "C:\\ProgramData\\anaconda3\\envs\\scopefoundry\\lib\\site-packages\\ScopeFoundry\\measurement.py", line 362, in _on_display_update_timer\n    self.update_display()\n', '  File "c:\\data\\python programs\\camera humanitas\\hyperspectralmicroscope\\hyperspectral_measure.py", line 93, in update_display\n    length = self.image_gen.frame_num.val\n', "AttributeError: 'HamamatsuHardware' object has no attribute 'frame_num'\n"]
2025-02-19T17:43:58|ERROR|hyperMeasure|hyper Failed to update figure1: 'HamamatsuHardware' object has no attribute 'frame_num'. ['Traceback (most recent call last):\n', '  File "C:\\ProgramData\\anaconda3\\envs\\scopefoundry\\lib\\site-packages\\ScopeFoundry\\measurement.py", line 362, in _on_display_update_timer\n    self.update_display()\n', '  File "c:\\data\\python programs\\camera humanitas\\hyperspectralmicroscope\\hyperspectral_measure.py", line 93, in update_display\n    length = self.image_gen.frame_num.val\n', "AttributeError: 'HamamatsuHardware' object has no attribute 'frame_num'\n"]
2025-02-19T17:43:59|ERROR|hyperMeasure|hyper Failed to update figure1: 'HamamatsuHardware' object has no attribute 'frame_num'. ['Traceback (most recent call last):\n', '  File "C:\\ProgramData\\anaconda3\\envs\\scopefoundry\\lib\\site-packages\\ScopeFoundry\\measurement.py", line 362, in _on_display_update_timer\n    self.update_display()\n', '  File "c:\\data\\python programs\\camera humanitas\\hyperspectralmicroscope\\hyperspectral_measure.py", line 93, in update_display\n    length = self.image_gen.frame_num.val\n', "AttributeError: 'HamamatsuHardware' object has no attribute 'frame_num'\n"]
2025-02-19T17:44:07|ERROR|hyperMeasure|hyper Failed to update figure1: 'HamamatsuHardware' object has no attribute 'frame_num'. ['Traceback (most recent call last):\n', '  File "C:\\ProgramData\\anaconda3\\envs\\scopefoundry\\lib\\site-packages\\ScopeFoundry\\measurement.py", line 362, in _on_display_update_timer\n    self.update_display()\n', '  File "c:\\data\\python programs\\camera humanitas\\hyperspectralmicroscope\\hyperspectral_measure.py", line 93, in update_display\n    length = self.image_gen.frame_num.val\n', "AttributeError: 'HamamatsuHardware' object has no attribute 'frame_num'\n"]
2025-02-19T17:44:07|ERROR|hyperMeasure|hyper Failed to update figure1: 'HamamatsuHardware' object has no attribute 'frame_num'. ['Traceback (most recent call last):\n', '  File "C:\\ProgramData\\anaconda3\\envs\\scopefoundry\\lib\\site-packages\\ScopeFoundry\\measurement.py", line 362, in _on_display_update_timer\n    self.update_display()\n', '  File "c:\\data\\python programs\\camera humanitas\\hyperspectralmicroscope\\hyperspectral_measure.py", line 93, in update_display\n    length = self.image_gen.frame_num.val\n', "AttributeError: 'HamamatsuHardware' object has no attribute 'frame_num'\n"]
2025-02-19T17:44:07|ERROR|hyperMeasure|hyper Failed to update figure1: 'HamamatsuHardware' object has no attribute 'frame_num'. ['Traceback (most recent call last):\n', '  File "C:\\ProgramData\\anaconda3\\envs\\scopefoundry\\lib\\site-packages\\ScopeFoundry\\measurement.py", line 362, in _on_display_update_timer\n    self.update_display()\n', '  File "c:\\data\\python programs\\camera humanitas\\hyperspectralmicroscope\\hyperspectral_measure.py", line 93, in update_display\n    length = self.image_gen.frame_num.val\n', "AttributeError: 'HamamatsuHardware' object has no attribute 'frame_num'\n"]
2025-02-19T17:50:43|ERROR|hyperMeasure|hyper Failed to update figure1: 'HamamatsuHardware' object has no attribute 'frame_num'. ['Traceback (most recent call last):\n', '  File "C:\\ProgramData\\anaconda3\\envs\\scopefoundry\\lib\\site-packages\\ScopeFoundry\\measurement.py", line 362, in _on_display_update_timer\n    self.update_display()\n', '  File "c:\\data\\python programs\\camera humanitas\\hyperspectralmicroscope\\hyperspectral_measure.py", line 93, in update_display\n    #length = self.image_gen.frame_num.val\n', "AttributeError: 'HamamatsuHardware' object has no attribute 'frame_num'\n"]
2025-02-19T17:50:43|ERROR|hyperMeasure|hyper Failed to update figure1: 'HamamatsuHardware' object has no attribute 'frame_num'. ['Traceback (most recent call last):\n', '  File "C:\\ProgramData\\anaconda3\\envs\\scopefoundry\\lib\\site-packages\\ScopeFoundry\\measurement.py", line 362, in _on_display_update_timer\n    self.update_display()\n', '  File "c:\\data\\python programs\\camera humanitas\\hyperspectralmicroscope\\hyperspectral_measure.py", line 93, in update_display\n    #length = self.image_gen.frame_num.val\n', "AttributeError: 'HamamatsuHardware' object has no attribute 'frame_num'\n"]
2025-02-19T17:50:44|ERROR|hyperMeasure|hyper Failed to update figure1: 'HamamatsuHardware' object has no attribute 'frame_num'. ['Traceback (most recent call last):\n', '  File "C:\\ProgramData\\anaconda3\\envs\\scopefoundry\\lib\\site-packages\\ScopeFoundry\\measurement.py", line 362, in _on_display_update_timer\n    self.update_display()\n', '  File "c:\\data\\python programs\\camera humanitas\\hyperspectralmicroscope\\hyperspectral_measure.py", line 93, in update_display\n    #length = self.image_gen.frame_num.val\n', "AttributeError: 'HamamatsuHardware' object has no attribute 'frame_num'\n"]
2025-02-19T17:54:51|ERROR|hyperMeasure|hyper Failed to update figure1: 'HamamatsuHardware' object has no attribute 'frame_num'. ['Traceback (most recent call last):\n', '  File "C:\\ProgramData\\anaconda3\\envs\\scopefoundry\\lib\\site-packages\\ScopeFoundry\\measurement.py", line 362, in _on_display_update_timer\n    self.update_display()\n', '  File "c:\\data\\python programs\\camera humanitas\\hyperspectralmicroscope\\hyperspectral_measure.py", line 93, in update_display\n    #length = self.image_gen.frame_num.val\n', "AttributeError: 'HamamatsuHardware' object has no attribute 'frame_num'\n"]
2025-02-19T17:57:52|ERROR|hyperMeasure|hyper Failed to update figure1: 'HamamatsuHardware' object has no attribute 'frame_num'. ['Traceback (most recent call last):\n', '  File "C:\\ProgramData\\anaconda3\\envs\\scopefoundry\\lib\\site-packages\\ScopeFoundry\\measurement.py", line 362, in _on_display_update_timer\n    self.update_display()\n', '  File "c:\\data\\python programs\\camera humanitas\\hyperspectralmicroscope\\hyperspectral_measure.py", line 93, in update_display\n    #length = self.image_gen.frame_num.val\n', "AttributeError: 'HamamatsuHardware' object has no attribute 'frame_num'\n"]
2025-02-19T17:58:13|ERROR|hyperMeasure|hyper Failed to update figure1: 'HamamatsuHardware' object has no attribute 'frame_num'. ['Traceback (most recent call last):\n', '  File "C:\\ProgramData\\anaconda3\\envs\\scopefoundry\\lib\\site-packages\\ScopeFoundry\\measurement.py", line 362, in _on_display_update_timer\n    self.update_display()\n', '  File "c:\\data\\python programs\\camera humanitas\\hyperspectralmicroscope\\hyperspectral_measure.py", line 93, in update_display\n    #length = self.image_gen.frame_num.val\n', "AttributeError: 'HamamatsuHardware' object has no attribute 'frame_num'\n"]
2025-02-19T17:58:23|ERROR|hyperMeasure|hyper Failed to update figure1: 'HamamatsuHardware' object has no attribute 'frame_num'. ['Traceback (most recent call last):\n', '  File "C:\\ProgramData\\anaconda3\\envs\\scopefoundry\\lib\\site-packages\\ScopeFoundry\\measurement.py", line 362, in _on_display_update_timer\n    self.update_display()\n', '  File "c:\\data\\python programs\\camera humanitas\\hyperspectralmicroscope\\hyperspectral_measure.py", line 93, in update_display\n    #length = self.image_gen.frame_num.val\n', "AttributeError: 'HamamatsuHardware' object has no attribute 'frame_num'\n"]
