2022-11-30T11:00:41|CRITICAL|root|Unhandled exception:Traceback (most recent call last):
  File "C:\Users\FastFMT-micro\anaconda3\lib\site-packages\ScopeFoundry\hardware.py", line 208, in enable_connection
    raise err
  File "C:\Users\FastFMT-micro\anaconda3\lib\site-packages\ScopeFoundry\hardware.py", line 204, in enable_connection
    self.connect()
  File "C:\LabPrograms\Python\PI_ScopeFoundry\PI_GCS_hardware.py", line 40, in connect
    self.motor = PI_GCS_Device(serial = SERIAL, axis = '1')
  File "C:\LabPrograms\Python\PI_ScopeFoundry\PI_GCS_device.py", line 26, in __init__
    self.pi_device.ConnectUSB (serial)
  File "C:\LabPrograms\Python\PI_ScopeFoundry\PIPython\pipython\pidevice\gcs2\gcs2device.py", line 133, in ConnectUSB
    self.dll.ConnectUSB(serialnum)
  File "C:\LabPrograms\Python\PI_ScopeFoundry\PIPython\pipython\pidevice\interfaces\gcsdll.py", line 437, in ConnectUSB
    raise GCSError(self._error)
PI_ScopeFoundry.PIPython.pipython.pidevice.gcserror.GCSError: There is no interface or DLL handle with the given ID (-9)

2022-11-30T11:01:21|CRITICAL|root|Unhandled exception:Traceback (most recent call last):
  File "C:\Users\FastFMT-micro\anaconda3\lib\site-packages\ScopeFoundry\hardware.py", line 160, in <lambda>
    op_button.clicked.connect(lambda checked, f=op_func: f())
  File "C:\LabPrograms\Python\PI_ScopeFoundry\PI_GCS_hardware.py", line 81, in gotoRefSwitch
    self.motor.gotoRefSwitch()
AttributeError: 'PI_GCS_HW' object has no attribute 'motor'

2022-11-30T11:01:47|CRITICAL|root|Unhandled exception:Traceback (most recent call last):
  File "C:\Users\FastFMT-micro\anaconda3\lib\site-packages\ScopeFoundry\hardware.py", line 208, in enable_connection
    raise err
  File "C:\Users\FastFMT-micro\anaconda3\lib\site-packages\ScopeFoundry\hardware.py", line 204, in enable_connection
    self.connect()
  File "C:\LabPrograms\Python\PI_ScopeFoundry\PI_GCS_hardware.py", line 40, in connect
    self.motor = PI_GCS_Device(serial = SERIAL, axis = '1')
  File "C:\LabPrograms\Python\PI_ScopeFoundry\PI_GCS_device.py", line 26, in __init__
    self.pi_device.ConnectUSB (serial)
  File "C:\LabPrograms\Python\PI_ScopeFoundry\PIPython\pipython\pidevice\gcs2\gcs2device.py", line 133, in ConnectUSB
    self.dll.ConnectUSB(serialnum)
  File "C:\LabPrograms\Python\PI_ScopeFoundry\PIPython\pipython\pidevice\interfaces\gcsdll.py", line 437, in ConnectUSB
    raise GCSError(self._error)
PI_ScopeFoundry.PIPython.pipython.pidevice.gcserror.GCSError: There is no interface or DLL handle with the given ID (-9)

