2022-11-30T16:41:49|CRITICAL|root|Unhandled exception:Traceback (most recent call last):
  File "C:\Users\FastFMT-micro\anaconda3\lib\site-packages\ScopeFoundry\logged_quantity.py", line 241, in update_value
    self.hardware_set_func(self.val)
  File "C:\LabPrograms\Python\PI_ScopeFoundry\PI_GCS_device.py", line 58, in move_absolute
    self.pi_device.MOV(self.axis, pos)
  File "C:\LabPrograms\Python\PI_ScopeFoundry\PIPython\pipython\pidevice\gcs2\gcs2commands.py", line 2798, in MOV
    self._msgs.send(cmdstr)
  File "C:\LabPrograms\Python\PI_ScopeFoundry\PIPython\pipython\pidevice\gcsmessages.py", line 107, in send
    self._checkerror(senderr=not self.embederr)
  File "C:\LabPrograms\Python\PI_ScopeFoundry\PIPython\pipython\pidevice\gcsmessages.py", line 302, in _checkerror
    raise exc  # Raising NoneType while only classes or instances are allowed pylint: disable=E0702
PI_ScopeFoundry.PIPython.pipython.pidevice.gcserror.GCSError: Unallowable move attempted on unreferenced axis, or move attempted with servo off (5)

