2021-06-29T13:17:34|CRITICAL|root|Unhandled exception:Traceback (most recent call last):
  File "C:\Users\FastFMT-micro\anaconda3\lib\site-packages\ScopeFoundry\hardware.py", line 208, in enable_connection
    raise err
  File "C:\Users\FastFMT-micro\anaconda3\lib\site-packages\ScopeFoundry\hardware.py", line 204, in enable_connection
    self.connect()
  File "C:\LabPrograms\Python\PI_ScopeFoundry\PI_CG_hardware.py", line 55, in connect
    self.read_from_hardware()
  File "C:\Users\FastFMT-micro\anaconda3\lib\site-packages\ScopeFoundry\hardware.py", line 181, in read_from_hardware
    lq.read_from_hardware()
  File "C:\Users\FastFMT-micro\anaconda3\lib\site-packages\ScopeFoundry\logged_quantity.py", line 161, in read_from_hardware
    val = self.hardware_read_func()
  File "C:\LabPrograms\Python\PI_ScopeFoundry\PI_CG_device.py", line 59, in get_home
    home = self.pi_device.qDFH(self.axis)[self.axis]
  File "C:\LabPrograms\Python\PI_ScopeFoundry\PIPython\pipython\pidevice\gcs2\gcs2commands.py", line 2181, in qDFH
    answer = self._msgs.read(cmdstr)
  File "C:\LabPrograms\Python\PI_ScopeFoundry\PIPython\pipython\pidevice\gcsmessages.py", line 125, in read
    answer = self._read(stopon)
  File "C:\LabPrograms\Python\PI_ScopeFoundry\PIPython\pipython\pidevice\gcsmessages.py", line 180, in _read
    raise GCSError(gcserror.E_7_COM_TIMEOUT, '@ GCSMessages._read')
PI_ScopeFoundry.PIPython.pipython.pidevice.gcserror.GCSError: Timeout error (-7): '@ GCSMessages._read'

